Workbook

Sheet RC Customers by plan
A1: RC Customers by plan
A2: RC Customers & revenue · Main Scenario
A4: Variable / dimension | B4: 2026-11 | C4: 2026-12 | D4: 2027-01 | E4: 2027-02 | F4: 2027-03 | G4: 2027-04 | H4: 2027-05 | I4: 2027-06 | J4: 2027-07 | K4: 2027-08 | L4: 2027-09 | M4: 2027-10 | N4: 2027-11 | O4: 2027-12 | P4: 2028-01 | Q4: 2028-02 | R4: 2028-03 | S4: 2028-04
A5: Model month | B5: =(YEAR(DATE(2026,11,1))-2026)*12+MONTH(DATE(2026,11,1))-11 -> 0 | C5: =(YEAR(DATE(2026,12,1))-2026)*12+MONTH(DATE(2026,12,1))-11 -> 1 | D5: =(YEAR(DATE(2027,1,1))-2026)*12+MONTH(DATE(2027,1,1))-11 -> 2 | E5: =(YEAR(DATE(2027,2,1))-2026)*12+MONTH(DATE(2027,2,1))-11 -> 3 | F5: =(YEAR(DATE(2027,3,1))-2026)*12+MONTH(DATE(2027,3,1))-11 -> 4 | G5: =(YEAR(DATE(2027,4,1))-2026)*12+MONTH(DATE(2027,4,1))-11 -> 5 | H5: =(YEAR(DATE(2027,5,1))-2026)*12+MONTH(DATE(2027,5,1))-11 -> 6 | I5: =(YEAR(DATE(2027,6,1))-2026)*12+MONTH(DATE(2027,6,1))-11 -> 7 | J5: =(YEAR(DATE(2027,7,1))-2026)*12+MONTH(DATE(2027,7,1))-11 -> 8 | K5: =(YEAR(DATE(2027,8,1))-2026)*12+MONTH(DATE(2027,8,1))-11 -> 9 | L5: =(YEAR(DATE(2027,9,1))-2026)*12+MONTH(DATE(2027,9,1))-11 -> 10 | M5: =(YEAR(DATE(2027,10,1))-2026)*12+MONTH(DATE(2027,10,1))-11 -> 11 | N5: =(YEAR(DATE(2027,11,1))-2026)*12+MONTH(DATE(2027,11,1))-11 -> 12 | O5: =(YEAR(DATE(2027,12,1))-2026)*12+MONTH(DATE(2027,12,1))-11 -> 13 | P5: =(YEAR(DATE(2028,1,1))-2026)*12+MONTH(DATE(2028,1,1))-11 -> 14 | Q5: =(YEAR(DATE(2028,2,1))-2026)*12+MONTH(DATE(2028,2,1))-11 -> 15 | R5: =(YEAR(DATE(2028,3,1))-2026)*12+MONTH(DATE(2028,3,1))-11 -> 16 | S5: =(YEAR(DATE(2028,4,1))-2026)*12+MONTH(DATE(2028,4,1))-11 -> 17
A6: Opening customers | B6: =SUM('RC Customers by plan'!B7,'RC Customers by plan'!B8,'RC Customers by plan'!B9) -> 47 | C6: =SUM('RC Customers by plan'!C7,'RC Customers by plan'!C8,'RC Customers by plan'!C9) -> 47 | D6: =SUM('RC Customers by plan'!D7,'RC Customers by plan'!D8,'RC Customers by plan'!D9) -> 84.905 | E6: =SUM('RC Customers by plan'!E7,'RC Customers by plan'!E8,'RC Customers by plan'!E9) -> 110.9505 | F6: =SUM('RC Customers by plan'!F7,'RC Customers by plan'!F8,'RC Customers by plan'!F9) -> 138.05103 | G6: =SUM('RC Customers by plan'!G7,'RC Customers by plan'!G8,'RC Customers by plan'!G9) -> 166.36012 | H6: =SUM('RC Customers by plan'!H7,'RC Customers by plan'!H8,'RC Customers by plan'!H9) -> 196.04007 | I6: =SUM('RC Customers by plan'!I7,'RC Customers by plan'!I8,'RC Customers by plan'!I9) -> 227.26287 | ... S6: =SUM('RC Customers by plan'!S7,'RC Customers by plan'!S8,'RC Customers by plan'!S9) -> 582.97988
A7: Indie | B7: =IF(IF(IF(ISERROR('RC Customers by plan'!B5=0),'RC Customers by plan'!B5=0,IF('RC Customers by plan'!B5="","",'RC Customers by plan'!B5=0))="",FALSE,IF(ISERROR('RC Customers by plan'!B5=0),'RC Customers by plan'!B5=0,IF('RC Customers by plan'!B5="","",'RC Customers by plan'!B5=0))),IF('Model inputs'!AG86="","",'Model inputs'!AG86),IF('Model inputs'!N38="","",'Model inputs'!N38)) -> 40 | C7: =IF(IF(IF(ISERROR('RC Customers by plan'!C5=0),'RC Customers by plan'!C5=0,IF('RC Customers by plan'!C5="","",'RC Customers by plan'!C5=0))="",FALSE,IF(ISERROR('RC Customers by plan'!C5=0),'RC Customers by plan'!C5=0,IF('RC Customers by plan'!C5="","",'RC Customers by plan'!C5=0))),IF('Model inputs'!AG86="","",'Model inputs'!AG86),IF('RC Customers by plan'!B31="","",'RC Customers by plan'!B31)) -> 40 | D7: =IF(IF(IF(ISERROR('RC Customers by plan'!D5=0),'RC Customers by plan'!D5=0,IF('RC Customers by plan'!D5="","",'RC Customers by plan'!D5=0))="",FALSE,IF(ISERROR('RC Customers by plan'!D5=0),'RC Customers by plan'!D5=0,IF('RC Customers by plan'!D5="","",'RC Customers by plan'!D5=0))),IF('Model inputs'!AG86="","",'Model inputs'!AG86),IF('RC Customers by plan'!C31="","",'RC Customers by plan'!C31)) -> 74.333333 | E7: =IF(IF(IF(ISERROR('RC Customers by plan'!E5=0),'RC Customers by plan'!E5=0,IF('RC Customers by plan'!E5="","",'RC Customers by plan'!E5=0))="",FALSE,IF(ISERROR('RC Customers by plan'!E5=0),'RC Customers by plan'!E5=0,IF('RC Customers by plan'!E5="","",'RC Customers by plan'!E5=0))),IF('Model inputs'!AG86="","",'Model inputs'!AG86),IF('RC Customers by plan'!D31="","",'RC Customers by plan'!D31)) -> 96.377778 | F7: =IF(IF(IF(ISERROR('RC Customers by plan'!F5=0),'RC Customers by plan'!F5=0,IF('RC Customers by plan'!F5="","",'RC Customers by plan'!F5=0))="",FALSE,IF(ISERROR('RC Customers by plan'!F5=0),'RC Customers by plan'!F5=0,IF('RC Customers by plan'!F5="","",'RC Customers by plan'!F5=0))),IF('Model inputs'!AG86="","",'Model inputs'!AG86),IF('RC Customers by plan'!E31="","",'RC Customers by plan'!E31)) -> 119.11259 | G7: =IF(IF(IF(ISERROR('RC Customers by plan'!G5=0),'RC Customers by plan'!G5=0,IF('RC Customers by plan'!G5="","",'RC Customers by plan'!G5=0))="",FALSE,IF(ISERROR('RC Customers by plan'!G5=0),'RC Customers by plan'!G5=0,IF('RC Customers by plan'!G5="","",'RC Customers by plan'!G5=0))),IF('Model inputs'!AG86="","",'Model inputs'!AG86),IF('RC Customers by plan'!F31="","",'RC Customers by plan'!F31)) -> 142.66455 | H7: =IF(IF(IF(ISERROR('RC Customers by plan'!H5=0),'RC Customers by plan'!H5=0,IF('RC Customers by plan'!H5="","",'RC Customers by plan'!H5=0))="",FALSE,IF(ISERROR('RC Customers by plan'!H5=0),'RC Customers by plan'!H5=0,IF('RC Customers by plan'!H5="","",'RC Customers by plan'!H5=0))),IF('Model inputs'!AG86="","",'Model inputs'!AG86),IF('RC Customers by plan'!G31="","",'RC Customers by plan'!G31)) -> 167.16581 | I7: =IF(IF(IF(ISERROR('RC Customers by plan'!I5=0),'RC Customers by plan'!I5=0,IF('RC Customers by plan'!I5="","",'RC Customers by plan'!I5=0))="",FALSE,IF(ISERROR('RC Customers by plan'!I5=0),'RC Customers by plan'!I5=0,IF('RC Customers by plan'!I5="","",'RC Customers by plan'!I5=0))),IF('Model inputs'!AG86="","",'Model inputs'!AG86),IF('RC Customers by plan'!H31="","",'RC Customers by plan'!H31)) -> 192.75462 | J7: =IF(IF(IF(ISERROR('RC Customers by plan'!J5=0),'RC Customers by plan'!J5=0,IF('RC Customers by plan'!J5="","",'RC Customers by plan'!J5=0))="",FALSE,IF(ISERROR('RC Customers by plan'!J5=0),'RC Customers by plan'!J5=0,IF('RC Customers by plan'!J5="","",'RC Customers by plan'!J5=0))),IF('Model inputs'!AG86="","",'Model inputs'!AG86),IF('RC Customers by plan'!I31="","",'RC Customers by plan'!I31)) -> 219.57617 | K7: =IF(IF(IF(ISERROR('RC Customers by plan'!K5=0),'RC Customers by plan'!K5=0,IF('RC Customers by plan'!K5="","",'RC Customers by plan'!K5=0))="",FALSE,IF(ISERROR('RC Customers by plan'!K5=0),'RC Customers by plan'!K5=0,IF('RC Customers by plan'!K5="","",'RC Customers by plan'!K5=0))),IF('Model inputs'!AG86="","",'Model inputs'!AG86),IF('RC Customers by plan'!J31="","",'RC Customers by plan'!J31)) -> 247.78337 | L7: =IF(IF(IF(ISERROR('RC Customers by plan'!L5=0),'RC Customers by plan'!L5=0,IF('RC Customers by plan'!L5="","",'RC Customers by plan'!L5=0))="",FALSE,IF(ISERROR('RC Customers by plan'!L5=0),'RC Customers by plan'!L5=0,IF('RC Customers by plan'!L5="","",'RC Customers by plan'!L5=0))),IF('Model inputs'!AG86="","",'Model inputs'!AG86),IF('RC Customers by plan'!K31="","",'RC Customers by plan'!K31)) -> 275.82391 | M7: =IF(IF(IF(ISERROR('RC Customers by plan'!M5=0),'RC Customers by plan'!M5=0,IF('RC Customers by plan'!M5="","",'RC Customers by plan'!M5=0))="",FALSE,IF(ISERROR('RC Customers by plan'!M5=0),'RC Customers by plan'!M5=0,IF('RC Customers by plan'!M5="","",'RC Customers by plan'!M5=0))),IF('Model inputs'!AG86="","",'Model inputs'!AG86),IF('RC Customers by plan'!L31="","",'RC Customers by plan'!L31)) -> 303.77745 | N7: =IF(IF(IF(ISERROR('RC Customers by plan'!N5=0),'RC Customers by plan'!N5=0,IF('RC Customers by plan'!N5="","",'RC Customers by plan'!N5=0))="",FALSE,IF(ISERROR('RC Customers by plan'!N5=0),'RC Customers by plan'!N5=0,IF('RC Customers by plan'!N5="","",'RC Customers by plan'!N5=0))),IF('Model inputs'!AG86="","",'Model inputs'!AG86),IF('RC Customers by plan'!M31="","",'RC Customers by plan'!M31)) -> 331.7211 | O7: =IF(IF(IF(ISERROR('RC Customers by plan'!O5=0),'RC Customers by plan'!O5=0,IF('RC Customers by plan'!O5="","",'RC Customers by plan'!O5=0))="",FALSE,IF(ISERROR('RC Customers by plan'!O5=0),'RC Customers by plan'!O5=0,IF('RC Customers by plan'!O5="","",'RC Customers by plan'!O5=0))),IF('Model inputs'!AG86="","",'Model inputs'!AG86),IF('RC Customers by plan'!N31="","",'RC Customers by plan'!N31)) -> 359.72966 | P7: =IF(IF(IF(ISERROR('RC Customers by plan'!P5=0),'RC Customers by plan'!P5=0,IF('RC Customers by plan'!P5="","",'RC Customers by plan'!P5=0))="",FALSE,IF(ISERROR('RC Customers by plan'!P5=0),'RC Customers by plan'!P5=0,IF('RC Customers by plan'!P5="","",'RC Customers by plan'!P5=0))),IF('Model inputs'!AG86="","",'Model inputs'!AG86),IF('RC Customers by plan'!O31="","",'RC Customers by plan'!O31)) -> 387.87592 | Q7: =IF(IF(IF(ISERROR('RC Customers by plan'!Q5=0),'RC Customers by plan'!Q5=0,IF('RC Customers by plan'!Q5="","",'RC Customers by plan'!Q5=0))="",FALSE,IF(ISERROR('RC Customers by plan'!Q5=0),'RC Customers by plan'!Q5=0,IF('RC Customers by plan'!Q5="","",'RC Customers by plan'!Q5=0))),IF('Model inputs'!AG86="","",'Model inputs'!AG86),IF('RC Customers by plan'!P31="","",'RC Customers by plan'!P31)) -> 416.23088 | R7: =IF(IF(IF(ISERROR('RC Customers by plan'!R5=0),'RC Customers by plan'!R5=0,IF('RC Customers by plan'!R5="","",'RC Customers by plan'!R5=0))="",FALSE,IF(ISERROR('RC Customers by plan'!R5=0),'RC Customers by plan'!R5=0,IF('RC Customers by plan'!R5="","",'RC Customers by plan'!R5=0))),IF('Model inputs'!AG86="","",'Model inputs'!AG86),IF('RC Customers by plan'!Q31="","",'RC Customers by plan'!Q31)) -> 444.86405 | S7: =IF(IF(IF(ISERROR('RC Customers by plan'!S5=0),'RC Customers by plan'!S5=0,IF('RC Customers by plan'!S5="","",'RC Customers by plan'!S5=0))="",FALSE,IF(ISERROR('RC Customers by plan'!S5=0),'RC Customers by plan'!S5=0,IF('RC Customers by plan'!S5="","",'RC Customers by plan'!S5=0))),IF('Model inputs'!AG86="","",'Model inputs'!AG86),IF('RC Customers by plan'!R31="","",'RC Customers by plan'!R31)) -> 473.84362
A8: Launch | B8: =IF(IF(IF(ISERROR('RC Customers by plan'!B5=0),'RC Customers by plan'!B5=0,IF('RC Customers by plan'!B5="","",'RC Customers by plan'!B5=0))="",FALSE,IF(ISERROR('RC Customers by plan'!B5=0),'RC Customers by plan'!B5=0,IF('RC Customers by plan'!B5="","",'RC Customers by plan'!B5=0))),IF('Model inputs'!AG87="","",'Model inputs'!AG87),IF('Model inputs'!N39="","",'Model inputs'!N39)) -> 1 | C8: =IF(IF(IF(ISERROR('RC Customers by plan'!C5=0),'RC Customers by plan'!C5=0,IF('RC Customers by plan'!C5="","",'RC Customers by plan'!C5=0))="",FALSE,IF(ISERROR('RC Customers by plan'!C5=0),'RC Customers by plan'!C5=0,IF('RC Customers by plan'!C5="","",'RC Customers by plan'!C5=0))),IF('Model inputs'!AG87="","",'Model inputs'!AG87),IF('RC Customers by plan'!B32="","",'RC Customers by plan'!B32)) -> 1 | D8: =IF(IF(IF(ISERROR('RC Customers by plan'!D5=0),'RC Customers by plan'!D5=0,IF('RC Customers by plan'!D5="","",'RC Customers by plan'!D5=0))="",FALSE,IF(ISERROR('RC Customers by plan'!D5=0),'RC Customers by plan'!D5=0,IF('RC Customers by plan'!D5="","",'RC Customers by plan'!D5=0))),IF('Model inputs'!AG87="","",'Model inputs'!AG87),IF('RC Customers by plan'!C32="","",'RC Customers by plan'!C32)) -> 1.51 | E8: =IF(IF(IF(ISERROR('RC Customers by plan'!E5=0),'RC Customers by plan'!E5=0,IF('RC Customers by plan'!E5="","",'RC Customers by plan'!E5=0))="",FALSE,IF(ISERROR('RC Customers by plan'!E5=0),'RC Customers by plan'!E5=0,IF('RC Customers by plan'!E5="","",'RC Customers by plan'!E5=0))),IF('Model inputs'!AG87="","",'Model inputs'!AG87),IF('RC Customers by plan'!D32="","",'RC Customers by plan'!D32)) -> 2.0251069 | F8: =IF(IF(IF(ISERROR('RC Customers by plan'!F5=0),'RC Customers by plan'!F5=0,IF('RC Customers by plan'!F5="","",'RC Customers by plan'!F5=0))="",FALSE,IF(ISERROR('RC Customers by plan'!F5=0),'RC Customers by plan'!F5=0,IF('RC Customers by plan'!F5="","",'RC Customers by plan'!F5=0))),IF('Model inputs'!AG87="","",'Model inputs'!AG87),IF('RC Customers by plan'!E32="","",'RC Customers by plan'!E32)) -> 2.5470121 | G8: =IF(IF(IF(ISERROR('RC Customers by plan'!G5=0),'RC Customers by plan'!G5=0,IF('RC Customers by plan'!G5="","",'RC Customers by plan'!G5=0))="",FALSE,IF(ISERROR('RC Customers by plan'!G5=0),'RC Customers by plan'!G5=0,IF('RC Customers by plan'!G5="","",'RC Customers by plan'!G5=0))),IF('Model inputs'!AG87="","",'Model inputs'!AG87),IF('RC Customers by plan'!F32="","",'RC Customers by plan'!F32)) -> 3.0771045 | H8: =IF(IF(IF(ISERROR('RC Customers by plan'!H5=0),'RC Customers by plan'!H5=0,IF('RC Customers by plan'!H5="","",'RC Customers by plan'!H5=0))="",FALSE,IF(ISERROR('RC Customers by plan'!H5=0),'RC Customers by plan'!H5=0,IF('RC Customers by plan'!H5="","",'RC Customers by plan'!H5=0))),IF('Model inputs'!AG87="","",'Model inputs'!AG87),IF('RC Customers by plan'!G32="","",'RC Customers by plan'!G32)) -> 3.6168582 | I8: =IF(IF(IF(ISERROR('RC Customers by plan'!I5=0),'RC Customers by plan'!I5=0,IF('RC Customers by plan'!I5="","",'RC Customers by plan'!I5=0))="",FALSE,IF(ISERROR('RC Customers by plan'!I5=0),'RC Customers by plan'!I5=0,IF('RC Customers by plan'!I5="","",'RC Customers by plan'!I5=0))),IF('Model inputs'!AG87="","",'Model inputs'!AG87),IF('RC Customers by plan'!H32="","",'RC Customers by plan'!H32)) -> 4.1678445 | J8: =IF(IF(IF(ISERROR('RC Customers by plan'!J5=0),'RC Customers by plan'!J5=0,IF('RC Customers by plan'!J5="","",'RC Customers by plan'!J5=0))="",FALSE,IF(ISERROR('RC Customers by plan'!J5=0),'RC Customers by plan'!J5=0,IF('RC Customers by plan'!J5="","",'RC Customers by plan'!J5=0))),IF('Model inputs'!AG87="","",'Model inputs'!AG87),IF('RC Customers by plan'!I32="","",'RC Customers by plan'!I32)) -> 4.7317452 | K8: =IF(IF(IF(ISERROR('RC Customers by plan'!K5=0),'RC Customers by plan'!K5=0,IF('RC Customers by plan'!K5="","",'RC Customers by plan'!K5=0))="",FALSE,IF(ISERROR('RC Customers by plan'!K5=0),'RC Customers by plan'!K5=0,IF('RC Customers by plan'!K5="","",'RC Customers by plan'!K5=0))),IF('Model inputs'!AG87="","",'Model inputs'!AG87),IF('RC Customers by plan'!J32="","",'RC Customers by plan'!J32)) -> 5.3103669 | L8: =IF(IF(IF(ISERROR('RC Customers by plan'!L5=0),'RC Customers by plan'!L5=0,IF('RC Customers by plan'!L5="","",'RC Customers by plan'!L5=0))="",FALSE,IF(ISERROR('RC Customers by plan'!L5=0),'RC Customers by plan'!L5=0,IF('RC Customers by plan'!L5="","",'RC Customers by plan'!L5=0))),IF('Model inputs'!AG87="","",'Model inputs'!AG87),IF('RC Customers by plan'!K32="","",'RC Customers by plan'!K32)) -> 5.9056563 | M8: =IF(IF(IF(ISERROR('RC Customers by plan'!M5=0),'RC Customers by plan'!M5=0,IF('RC Customers by plan'!M5="","",'RC Customers by plan'!M5=0))="",FALSE,IF(ISERROR('RC Customers by plan'!M5=0),'RC Customers by plan'!M5=0,IF('RC Customers by plan'!M5="","",'RC Customers by plan'!M5=0))),IF('Model inputs'!AG87="","",'Model inputs'!AG87),IF('RC Customers by plan'!L32="","",'RC Customers by plan'!L32)) -> 6.5182553 | N8: =IF(IF(IF(ISERROR('RC Customers by plan'!N5=0),'RC Customers by plan'!N5=0,IF('RC Customers by plan'!N5="","",'RC Customers by plan'!N5=0))="",FALSE,IF(ISERROR('RC Customers by plan'!N5=0),'RC Customers by plan'!N5=0,IF('RC Customers by plan'!N5="","",'RC Customers by plan'!N5=0))),IF('Model inputs'!AG87="","",'Model inputs'!AG87),IF('RC Customers by plan'!M32="","",'RC Customers by plan'!M32)) -> 7.1487999 | O8: =IF(IF(IF(ISERROR('RC Customers by plan'!O5=0),'RC Customers by plan'!O5=0,IF('RC Customers by plan'!O5="","",'RC Customers by plan'!O5=0))="",FALSE,IF(ISERROR('RC Customers by plan'!O5=0),'RC Customers by plan'!O5=0,IF('RC Customers by plan'!O5="","",'RC Customers by plan'!O5=0))),IF('Model inputs'!AG87="","",'Model inputs'!AG87),IF('RC Customers by plan'!N32="","",'RC Customers by plan'!N32)) -> 7.7979243 | P8: =IF(IF(IF(ISERROR('RC Customers by plan'!P5=0),'RC Customers by plan'!P5=0,IF('RC Customers by plan'!P5="","",'RC Customers by plan'!P5=0))="",FALSE,IF(ISERROR('RC Customers by plan'!P5=0),'RC Customers by plan'!P5=0,IF('RC Customers by plan'!P5="","",'RC Customers by plan'!P5=0))),IF('Model inputs'!AG87="","",'Model inputs'!AG87),IF('RC Customers by plan'!O32="","",'RC Customers by plan'!O32)) -> 8.466264 | Q8: =IF(IF(IF(ISERROR('RC Customers by plan'!Q5=0),'RC Customers by plan'!Q5=0,IF('RC Customers by plan'!Q5="","",'RC Customers by plan'!Q5=0))="",FALSE,IF(ISERROR('RC Customers by plan'!Q5=0),'RC Customers by plan'!Q5=0,IF('RC Customers by plan'!Q5="","",'RC Customers by plan'!Q5=0))),IF('Model inputs'!AG87="","",'Model inputs'!AG87),IF('RC Customers by plan'!P32="","",'RC Customers by plan'!P32)) -> 9.1544595 | R8: =IF(IF(IF(ISERROR('RC Customers by plan'!R5=0),'RC Customers by plan'!R5=0,IF('RC Customers by plan'!R5="","",'RC Customers by plan'!R5=0))="",FALSE,IF(ISERROR('RC Customers by plan'!R5=0),'RC Customers by plan'!R5=0,IF('RC Customers by plan'!R5="","",'RC Customers by plan'!R5=0))),IF('Model inputs'!AG87="","",'Model inputs'!AG87),IF('RC Customers by plan'!Q32="","",'RC Customers by plan'!Q32)) -> 9.8631592 | S8: =IF(IF(IF(ISERROR('RC Customers by plan'!S5=0),'RC Customers by plan'!S5=0,IF('RC Customers by plan'!S5="","",'RC Customers by plan'!S5=0))="",FALSE,IF(ISERROR('RC Customers by plan'!S5=0),'RC Customers by plan'!S5=0,IF('RC Customers by plan'!S5="","",'RC Customers by plan'!S5=0))),IF('Model inputs'!AG87="","",'Model inputs'!AG87),IF('RC Customers by plan'!R32="","",'RC Customers by plan'!R32)) -> 10.593023
A9: Team | B9: =IF(IF(IF(ISERROR('RC Customers by plan'!B5=0),'RC Customers by plan'!B5=0,IF('RC Customers by plan'!B5="","",'RC Customers by plan'!B5=0))="",FALSE,IF(ISERROR('RC Customers by plan'!B5=0),'RC Customers by plan'!B5=0,IF('RC Customers by plan'!B5="","",'RC Customers by plan'!B5=0))),IF('Model inputs'!AG88="","",'Model inputs'!AG88),IF('Model inputs'!N40="","",'Model inputs'!N40)) -> 6 | C9: =IF(IF(IF(ISERROR('RC Customers by plan'!C5=0),'RC Customers by plan'!C5=0,IF('RC Customers by plan'!C5="","",'RC Customers by plan'!C5=0))="",FALSE,IF(ISERROR('RC Customers by plan'!C5=0),'RC Customers by plan'!C5=0,IF('RC Customers by plan'!C5="","",'RC Customers by plan'!C5=0))),IF('Model inputs'!AG88="","",'Model inputs'!AG88),IF('RC Customers by plan'!B33="","",'RC Customers by plan'!B33)) -> 6 | D9: =IF(IF(IF(ISERROR('RC Customers by plan'!D5=0),'RC Customers by plan'!D5=0,IF('RC Customers by plan'!D5="","",'RC Customers by plan'!D5=0))="",FALSE,IF(ISERROR('RC Customers by plan'!D5=0),'RC Customers by plan'!D5=0,IF('RC Customers by plan'!D5="","",'RC Customers by plan'!D5=0))),IF('Model inputs'!AG88="","",'Model inputs'!AG88),IF('RC Customers by plan'!C33="","",'RC Customers by plan'!C33)) -> 9.0616667 | E9: =IF(IF(IF(ISERROR('RC Customers by plan'!E5=0),'RC Customers by plan'!E5=0,IF('RC Customers by plan'!E5="","",'RC Customers by plan'!E5=0))="",FALSE,IF(ISERROR('RC Customers by plan'!E5=0),'RC Customers by plan'!E5=0,IF('RC Customers by plan'!E5="","",'RC Customers by plan'!E5=0))),IF('Model inputs'!AG88="","",'Model inputs'!AG88),IF('RC Customers by plan'!D33="","",'RC Customers by plan'!D33)) -> 12.547615 | F9: =IF(IF(IF(ISERROR('RC Customers by plan'!F5=0),'RC Customers by plan'!F5=0,IF('RC Customers by plan'!F5="","",'RC Customers by plan'!F5=0))="",FALSE,IF(ISERROR('RC Customers by plan'!F5=0),'RC Customers by plan'!F5=0,IF('RC Customers by plan'!F5="","",'RC Customers by plan'!F5=0))),IF('Model inputs'!AG88="","",'Model inputs'!AG88),IF('RC Customers by plan'!E33="","",'RC Customers by plan'!E33)) -> 16.391424 | G9: =IF(IF(IF(ISERROR('RC Customers by plan'!G5=0),'RC Customers by plan'!G5=0,IF('RC Customers by plan'!G5="","",'RC Customers by plan'!G5=0))="",FALSE,IF(ISERROR('RC Customers by plan'!G5=0),'RC Customers by plan'!G5=0,IF('RC Customers by plan'!G5="","",'RC Customers by plan'!G5=0))),IF('Model inputs'!AG88="","",'Model inputs'!AG88),IF('RC Customers by plan'!F33="","",'RC Customers by plan'!F33)) -> 20.618467 | H9: =IF(IF(IF(ISERROR('RC Customers by plan'!H5=0),'RC Customers by plan'!H5=0,IF('RC Customers by plan'!H5="","",'RC Customers by plan'!H5=0))="",FALSE,IF(ISERROR('RC Customers by plan'!H5=0),'RC Customers by plan'!H5=0,IF('RC Customers by plan'!H5="","",'RC Customers by plan'!H5=0))),IF('Model inputs'!AG88="","",'Model inputs'!AG88),IF('RC Customers by plan'!G33="","",'RC Customers by plan'!G33)) -> 25.2574 | I9: =IF(IF(IF(ISERROR('RC Customers by plan'!I5=0),'RC Customers by plan'!I5=0,IF('RC Customers by plan'!I5="","",'RC Customers by plan'!I5=0))="",FALSE,IF(ISERROR('RC Customers by plan'!I5=0),'RC Customers by plan'!I5=0,IF('RC Customers by plan'!I5="","",'RC Customers by plan'!I5=0))),IF('Model inputs'!AG88="","",'Model inputs'!AG88),IF('RC Customers by plan'!H33="","",'RC Customers by plan'!H33)) -> 30.340408 | J9: =IF(IF(IF(ISERROR('RC Customers by plan'!J5=0),'RC Customers by plan'!J5=0,IF('RC Customers by plan'!J5="","",'RC Customers by plan'!J5=0))="",FALSE,IF(ISERROR('RC Customers by plan'!J5=0),'RC Customers by plan'!J5=0,IF('RC Customers by plan'!J5="","",'RC Customers by plan'!J5=0))),IF('Model inputs'!AG88="","",'Model inputs'!AG88),IF('RC Customers by plan'!I33="","",'RC Customers by plan'!I33)) -> 35.903491 | K9: =IF(IF(IF(ISERROR('RC Customers by plan'!K5=0),'RC Customers by plan'!K5=0,IF('RC Customers by plan'!K5="","",'RC Customers by plan'!K5=0))="",FALSE,IF(ISERROR('RC Customers by plan'!K5=0),'RC Customers by plan'!K5=0,IF('RC Customers by plan'!K5="","",'RC Customers by plan'!K5=0))),IF('Model inputs'!AG88="","",'Model inputs'!AG88),IF('RC Customers by plan'!J33="","",'RC Customers by plan'!J33)) -> 41.986781 | L9: =IF(IF(IF(ISERROR('RC Customers by plan'!L5=0),'RC Customers by plan'!L5=0,IF('RC Customers by plan'!L5="","",'RC Customers by plan'!L5=0))="",FALSE,IF(ISERROR('RC Customers by plan'!L5=0),'RC Customers by plan'!L5=0,IF('RC Customers by plan'!L5="","",'RC Customers by plan'!L5=0))),IF('Model inputs'!AG88="","",'Model inputs'!AG88),IF('RC Customers by plan'!K33="","",'RC Customers by plan'!K33)) -> 48.284119 | M9: =IF(IF(IF(ISERROR('RC Customers by plan'!M5=0),'RC Customers by plan'!M5=0,IF('RC Customers by plan'!M5="","",'RC Customers by plan'!M5=0))="",FALSE,IF(ISERROR('RC Customers by plan'!M5=0),'RC Customers by plan'!M5=0,IF('RC Customers by plan'!M5="","",'RC Customers by plan'!M5=0))),IF('Model inputs'!AG88="","",'Model inputs'!AG88),IF('RC Customers by plan'!L33="","",'RC Customers by plan'!L33)) -> 54.796435 | N9: =IF(IF(IF(ISERROR('RC Customers by plan'!N5=0),'RC Customers by plan'!N5=0,IF('RC Customers by plan'!N5="","",'RC Customers by plan'!N5=0))="",FALSE,IF(ISERROR('RC Customers by plan'!N5=0),'RC Customers by plan'!N5=0,IF('RC Customers by plan'!N5="","",'RC Customers by plan'!N5=0))),IF('Model inputs'!AG88="","",'Model inputs'!AG88),IF('RC Customers by plan'!M33="","",'RC Customers by plan'!M33)) -> 61.525531 | O9: =IF(IF(IF(ISERROR('RC Customers by plan'!O5=0),'RC Customers by plan'!O5=0,IF('RC Customers by plan'!O5="","",'RC Customers by plan'!O5=0))="",FALSE,IF(ISERROR('RC Customers by plan'!O5=0),'RC Customers by plan'!O5=0,IF('RC Customers by plan'!O5="","",'RC Customers by plan'!O5=0))),IF('Model inputs'!AG88="","",'Model inputs'!AG88),IF('RC Customers by plan'!N33="","",'RC Customers by plan'!N33)) -> 68.474053 | P9: =IF(IF(IF(ISERROR('RC Customers by plan'!P5=0),'RC Customers by plan'!P5=0,IF('RC Customers by plan'!P5="","",'RC Customers by plan'!P5=0))="",FALSE,IF(ISERROR('RC Customers by plan'!P5=0),'RC Customers by plan'!P5=0,IF('RC Customers by plan'!P5="","",'RC Customers by plan'!P5=0))),IF('Model inputs'!AG88="","",'Model inputs'!AG88),IF('RC Customers by plan'!O33="","",'RC Customers by plan'!O33)) -> 75.645458 | Q9: =IF(IF(IF(ISERROR('RC Customers by plan'!Q5=0),'RC Customers by plan'!Q5=0,IF('RC Customers by plan'!Q5="","",'RC Customers by plan'!Q5=0))="",FALSE,IF(ISERROR('RC Customers by plan'!Q5=0),'RC Customers by plan'!Q5=0,IF('RC Customers by plan'!Q5="","",'RC Customers by plan'!Q5=0))),IF('Model inputs'!AG88="","",'Model inputs'!AG88),IF('RC Customers by plan'!P33="","",'RC Customers by plan'!P33)) -> 83.04399 | R9: =IF(IF(IF(ISERROR('RC Customers by plan'!R5=0),'RC Customers by plan'!R5=0,IF('RC Customers by plan'!R5="","",'RC Customers by plan'!R5=0))="",FALSE,IF(ISERROR('RC Customers by plan'!R5=0),'RC Customers by plan'!R5=0,IF('RC Customers by plan'!R5="","",'RC Customers by plan'!R5=0))),IF('Model inputs'!AG88="","",'Model inputs'!AG88),IF('RC Customers by plan'!Q33="","",'RC Customers by plan'!Q33)) -> 90.674663 | S9: =IF(IF(IF(ISERROR('RC Customers by plan'!S5=0),'RC Customers by plan'!S5=0,IF('RC Customers by plan'!S5="","",'RC Customers by plan'!S5=0))="",FALSE,IF(ISERROR('RC Customers by plan'!S5=0),'RC Customers by plan'!S5=0,IF('RC Customers by plan'!S5="","",'RC Customers by plan'!S5=0))),IF('Model inputs'!AG88="","",'Model inputs'!AG88),IF('RC Customers by plan'!R33="","",'RC Customers by plan'!R33)) -> 98.543234
A10: Organic new logos | B10: =SUM('RC Customers by plan'!B11,'RC Customers by plan'!B12,'RC Customers by plan'!B13) -> 0 | C10: =SUM('RC Customers by plan'!C11,'RC Customers by plan'!C12,'RC Customers by plan'!C13) -> 28.5 | D10: =SUM('RC Customers by plan'!D11,'RC Customers by plan'!D12,'RC Customers by plan'!D13) -> 30.8 | E10: =SUM('RC Customers by plan'!E11,'RC Customers by plan'!E12,'RC Customers by plan'!E13) -> 33.29 | F10: =SUM('RC Customers by plan'!F11,'RC Customers by plan'!F12,'RC Customers by plan'!F13) -> 35.9858 | G10: =SUM('RC Customers by plan'!G11,'RC Customers by plan'!G12,'RC Customers by plan'!G13) -> 38.904524 | H10: =SUM('RC Customers by plan'!H11,'RC Customers by plan'!H12,'RC Customers by plan'!H13) -> 42.064732 | I10: =SUM('RC Customers by plan'!I11,'RC Customers by plan'!I12,'RC Customers by plan'!I13) -> 45.486541 | ... S10: =SUM('RC Customers by plan'!S11,'RC Customers by plan'!S12,'RC Customers by plan'!S13) -> 69.803554
A11: Indie | B11: =IF(IF(IF(ISERROR('RC Customers by plan'!B5<1),'RC Customers by plan'!B5<1,IF('RC Customers by plan'!B5="","",'RC Customers by plan'!B5<1))="",FALSE,IF(ISERROR('RC Customers by plan'!B5<1),'RC Customers by plan'!B5<1,IF('RC Customers by plan'!B5="","",'RC Customers by plan'!B5<1))),0,IF(IF(IF(ISERROR('RC Customers by plan'!B5=1),'RC Customers by plan'!B5=1,IF('RC Customers by plan'!B5="","",'RC Customers by plan'!B5=1))="",FALSE,IF(ISERROR('RC Customers by plan'!B5=1),'RC Customers by plan'!B5=1,IF('RC Customers by plan'!B5="","",'RC Customers by plan'!B5=1))),IF('Model inputs'!AG69="","",'Model inputs'!AG69),'Model inputs'!N77*(1+IF(IF(IF(IF(ISERROR('RC Customers by plan'!B5<=8),'RC Customers by plan'!B5<=8,IF('RC Customers by plan'!B5="","",'RC Customers by plan'!B5<=8))="",FALSE,IF(ISERROR('RC Customers by plan'!B5<=8),'RC Customers by plan'!B5<=8,IF('RC Customers by plan'!B5="","",'RC Customers by plan'!B5<=8))),IF('Model inputs'!AG50="","",'Model inputs'!AG50),IF('Model inputs'!AG46="","",'Model inputs'!AG46))="",0,IF(IF(IF(ISERROR('RC Customers by plan'!B5<=8),'RC Customers by plan'!B5<=8,IF('RC Customers by plan'!B5="","",'RC Customers by plan'!B5<=8))="",FALSE,IF(ISERROR('RC Customers by plan'!B5<=8),'RC Customers by plan'!B5<=8,IF('RC Customers by plan'!B5="","",'RC Customers by plan'!B5<=8))),IF('Model inputs'!AG50="","",'Model inputs'!AG50),IF('Model inputs'!AG46="","",'Model inputs'!AG46)))))) -> 0 | C11: =IF(IF(IF(ISERROR('RC Customers by plan'!C5<1),'RC Customers by plan'!C5<1,IF('RC Customers by plan'!C5="","",'RC Customers by plan'!C5<1))="",FALSE,IF(ISERROR('RC Customers by plan'!C5<1),'RC Customers by plan'!C5<1,IF('RC Customers by plan'!C5="","",'RC Customers by plan'!C5<1))),0,IF(IF(IF(ISERROR('RC Customers by plan'!C5=1),'RC Customers by plan'!C5=1,IF('RC Customers by plan'!C5="","",'RC Customers by plan'!C5=1))="",FALSE,IF(ISERROR('RC Customers by plan'!C5=1),'RC Customers by plan'!C5=1,IF('RC Customers by plan'!C5="","",'RC Customers by plan'!C5=1))),IF('Model inputs'!AG69="","",'Model inputs'!AG69),'RC Customers by plan'!B11*(1+IF(IF(IF(IF(ISERROR('RC Customers by plan'!C5<=8),'RC Customers by plan'!C5<=8,IF('RC Customers by plan'!C5="","",'RC Customers by plan'!C5<=8))="",FALSE,IF(ISERROR('RC Customers by plan'!C5<=8),'RC Customers by plan'!C5<=8,IF('RC Customers by plan'!C5="","",'RC Customers by plan'!C5<=8))),IF('Model inputs'!AG50="","",'Model inputs'!AG50),IF('Model inputs'!AG46="","",'Model inputs'!AG46))="",0,IF(IF(IF(ISERROR('RC Customers by plan'!C5<=8),'RC Customers by plan'!C5<=8,IF('RC Customers by plan'!C5="","",'RC Customers by plan'!C5<=8))="",FALSE,IF(ISERROR('RC Customers by plan'!C5<=8),'RC Customers by plan'!C5<=8,IF('RC Customers by plan'!C5="","",'RC Customers by plan'!C5<=8))),IF('Model inputs'!AG50="","",'Model inputs'!AG50),IF('Model inputs'!AG46="","",'Model inputs'!AG46)))))) -> 25 | D11: =IF(IF(IF(ISERROR('RC Customers by plan'!D5<1),'RC Customers by plan'!D5<1,IF('RC Customers by plan'!D5="","",'RC Customers by plan'!D5<1))="",FALSE,IF(ISERROR('RC Customers by plan'!D5<1),'RC Customers by plan'!D5<1,IF('RC Customers by plan'!D5="","",'RC Customers by plan'!D5<1))),0,IF(IF(IF(ISERROR('RC Customers by plan'!D5=1),'RC Customers by plan'!D5=1,IF('RC Customers by plan'!D5="","",'RC Customers by plan'!D5=1))="",FALSE,IF(ISERROR('RC Customers by plan'!D5=1),'RC Customers by plan'!D5=1,IF('RC Customers by plan'!D5="","",'RC Customers by plan'!D5=1))),IF('Model inputs'!AG69="","",'Model inputs'!AG69),'RC Customers by plan'!C11*(1+IF(IF(IF(IF(ISERROR('RC Customers by plan'!D5<=8),'RC Customers by plan'!D5<=8,IF('RC Customers by plan'!D5="","",'RC Customers by plan'!D5<=8))="",FALSE,IF(ISERROR('RC Customers by plan'!D5<=8),'RC Customers by plan'!D5<=8,IF('RC Customers by plan'!D5="","",'RC Customers by plan'!D5<=8))),IF('Model inputs'!AG50="","",'Model inputs'!AG50),IF('Model inputs'!AG46="","",'Model inputs'!AG46))="",0,IF(IF(IF(ISERROR('RC Customers by plan'!D5<=8),'RC Customers by plan'!D5<=8,IF('RC Customers by plan'!D5="","",'RC Customers by plan'!D5<=8))="",FALSE,IF(ISERROR('RC Customers by plan'!D5<=8),'RC Customers by plan'!D5<=8,IF('RC Customers by plan'!D5="","",'RC Customers by plan'!D5<=8))),IF('Model inputs'!AG50="","",'Model inputs'!AG50),IF('Model inputs'!AG46="","",'Model inputs'!AG46)))))) -> 27 | E11: =IF(IF(IF(ISERROR('RC Customers by plan'!E5<1),'RC Customers by plan'!E5<1,IF('RC Customers by plan'!E5="","",'RC Customers by plan'!E5<1))="",FALSE,IF(ISERROR('RC Customers by plan'!E5<1),'RC Customers by plan'!E5<1,IF('RC Customers by plan'!E5="","",'RC Customers by plan'!E5<1))),0,IF(IF(IF(ISERROR('RC Customers by plan'!E5=1),'RC Customers by plan'!E5=1,IF('RC Customers by plan'!E5="","",'RC Customers by plan'!E5=1))="",FALSE,IF(ISERROR('RC Customers by plan'!E5=1),'RC Customers by plan'!E5=1,IF('RC Customers by plan'!E5="","",'RC Customers by plan'!E5=1))),IF('Model inputs'!AG69="","",'Model inputs'!AG69),'RC Customers by plan'!D11*(1+IF(IF(IF(IF(ISERROR('RC Customers by plan'!E5<=8),'RC Customers by plan'!E5<=8,IF('RC Customers by plan'!E5="","",'RC Customers by plan'!E5<=8))="",FALSE,IF(ISERROR('RC Customers by plan'!E5<=8),'RC Customers by plan'!E5<=8,IF('RC Customers by plan'!E5="","",'RC Customers by plan'!E5<=8))),IF('Model inputs'!AG50="","",'Model inputs'!AG50),IF('Model inputs'!AG46="","",'Model inputs'!AG46))="",0,IF(IF(IF(ISERROR('RC Customers by plan'!E5<=8),'RC Customers by plan'!E5<=8,IF('RC Customers by plan'!E5="","",'RC Customers by plan'!E5<=8))="",FALSE,IF(ISERROR('RC Customers by plan'!E5<=8),'RC Customers by plan'!E5<=8,IF('RC Customers by plan'!E5="","",'RC Customers by plan'!E5<=8))),IF('Model inputs'!AG50="","",'Model inputs'!AG50),IF('Model inputs'!AG46="","",'Model inputs'!AG46)))))) -> 29.16 | F11: =IF(IF(IF(ISERROR('RC Customers by plan'!F5<1),'RC Customers by plan'!F5<1,IF('RC Customers by plan'!F5="","",'RC Customers by plan'!F5<1))="",FALSE,IF(ISERROR('RC Customers by plan'!F5<1),'RC Customers by plan'!F5<1,IF('RC Customers by plan'!F5="","",'RC Customers by plan'!F5<1))),0,IF(IF(IF(ISERROR('RC Customers by plan'!F5=1),'RC Customers by plan'!F5=1,IF('RC Customers by plan'!F5="","",'RC Customers by plan'!F5=1))="",FALSE,IF(ISERROR('RC Customers by plan'!F5=1),'RC Customers by plan'!F5=1,IF('RC Customers by plan'!F5="","",'RC Customers by plan'!F5=1))),IF('Model inputs'!AG69="","",'Model inputs'!AG69),'RC Customers by plan'!E11*(1+IF(IF(IF(IF(ISERROR('RC Customers by plan'!F5<=8),'RC Customers by plan'!F5<=8,IF('RC Customers by plan'!F5="","",'RC Customers by plan'!F5<=8))="",FALSE,IF(ISERROR('RC Customers by plan'!F5<=8),'RC Customers by plan'!F5<=8,IF('RC Customers by plan'!F5="","",'RC Customers by plan'!F5<=8))),IF('Model inputs'!AG50="","",'Model inputs'!AG50),IF('Model inputs'!AG46="","",'Model inputs'!AG46))="",0,IF(IF(IF(ISERROR('RC Customers by plan'!F5<=8),'RC Customers by plan'!F5<=8,IF('RC Customers by plan'!F5="","",'RC Customers by plan'!F5<=8))="",FALSE,IF(ISERROR('RC Customers by plan'!F5<=8),'RC Customers by plan'!F5<=8,IF('RC Customers by plan'!F5="","",'RC Customers by plan'!F5<=8))),IF('Model inputs'!AG50="","",'Model inputs'!AG50),IF('Model inputs'!AG46="","",'Model inputs'!AG46)))))) -> 31.4928 | G11: =IF(IF(IF(ISERROR('RC Customers by plan'!G5<1),'RC Customers by plan'!G5<1,IF('RC Customers by plan'!G5="","",'RC Customers by plan'!G5<1))="",FALSE,IF(ISERROR('RC Customers by plan'!G5<1),'RC Customers by plan'!G5<1,IF('RC Customers by plan'!G5="","",'RC Customers by plan'!G5<1))),0,IF(IF(IF(ISERROR('RC Customers by plan'!G5=1),'RC Customers by plan'!G5=1,IF('RC Customers by plan'!G5="","",'RC Customers by plan'!G5=1))="",FALSE,IF(ISERROR('RC Customers by plan'!G5=1),'RC Customers by plan'!G5=1,IF('RC Customers by plan'!G5="","",'RC Customers by plan'!G5=1))),IF('Model inputs'!AG69="","",'Model inputs'!AG69),'RC Customers by plan'!F11*(1+IF(IF(IF(IF(ISERROR('RC Customers by plan'!G5<=8),'RC Customers by plan'!G5<=8,IF('RC Customers by plan'!G5="","",'RC Customers by plan'!G5<=8))="",FALSE,IF(ISERROR('RC Customers by plan'!G5<=8),'RC Customers by plan'!G5<=8,IF('RC Customers by plan'!G5="","",'RC Customers by plan'!G5<=8))),IF('Model inputs'!AG50="","",'Model inputs'!AG50),IF('Model inputs'!AG46="","",'Model inputs'!AG46))="",0,IF(IF(IF(ISERROR('RC Customers by plan'!G5<=8),'RC Customers by plan'!G5<=8,IF('RC Customers by plan'!G5="","",'RC Customers by plan'!G5<=8))="",FALSE,IF(ISERROR('RC Customers by plan'!G5<=8),'RC Customers by plan'!G5<=8,IF('RC Customers by plan'!G5="","",'RC Customers by plan'!G5<=8))),IF('Model inputs'!AG50="","",'Model inputs'!AG50),IF('Model inputs'!AG46="","",'Model inputs'!AG46)))))) -> 34.012224 | H11: =IF(IF(IF(ISERROR('RC Customers by plan'!H5<1),'RC Customers by plan'!H5<1,IF('RC Customers by plan'!H5="","",'RC Customers by plan'!H5<1))="",FALSE,IF(ISERROR('RC Customers by plan'!H5<1),'RC Customers by plan'!H5<1,IF('RC Customers by plan'!H5="","",'RC Customers by plan'!H5<1))),0,IF(IF(IF(ISERROR('RC Customers by plan'!H5=1),'RC Customers by plan'!H5=1,IF('RC Customers by plan'!H5="","",'RC Customers by plan'!H5=1))="",FALSE,IF(ISERROR('RC Customers by plan'!H5=1),'RC Customers by plan'!H5=1,IF('RC Customers by plan'!H5="","",'RC Customers by plan'!H5=1))),IF('Model inputs'!AG69="","",'Model inputs'!AG69),'RC Customers by plan'!G11*(1+IF(IF(IF(IF(ISERROR('RC Customers by plan'!H5<=8),'RC Customers by plan'!H5<=8,IF('RC Customers by plan'!H5="","",'RC Customers by plan'!H5<=8))="",FALSE,IF(ISERROR('RC Customers by plan'!H5<=8),'RC Customers by plan'!H5<=8,IF('RC Customers by plan'!H5="","",'RC Customers by plan'!H5<=8))),IF('Model inputs'!AG50="","",'Model inputs'!AG50),IF('Model inputs'!AG46="","",'Model inputs'!AG46))="",0,IF(IF(IF(ISERROR('RC Customers by plan'!H5<=8),'RC Customers by plan'!H5<=8,IF('RC Customers by plan'!H5="","",'RC Customers by plan'!H5<=8))="",FALSE,IF(ISERROR('RC Customers by plan'!H5<=8),'RC Customers by plan'!H5<=8,IF('RC Customers by plan'!H5="","",'RC Customers by plan'!H5<=8))),IF('Model inputs'!AG50="","",'Model inputs'!AG50),IF('Model inputs'!AG46="","",'Model inputs'!AG46)))))) -> 36.733202 | I11: =IF(IF(IF(ISERROR('RC Customers by plan'!I5<1),'RC Customers by plan'!I5<1,IF('RC Customers by plan'!I5="","",'RC Customers by plan'!I5<1))="",FALSE,IF(ISERROR('RC Customers by plan'!I5<1),'RC Customers by plan'!I5<1,IF('RC Customers by plan'!I5="","",'RC Customers by plan'!I5<1))),0,IF(IF(IF(ISERROR('RC Customers by plan'!I5=1),'RC Customers by plan'!I5=1,IF('RC Customers by plan'!I5="","",'RC Customers by plan'!I5=1))="",FALSE,IF(ISERROR('RC Customers by plan'!I5=1),'RC Customers by plan'!I5=1,IF('RC Customers by plan'!I5="","",'RC Customers by plan'!I5=1))),IF('Model inputs'!AG69="","",'Model inputs'!AG69),'RC Customers by plan'!H11*(1+IF(IF(IF(IF(ISERROR('RC Customers by plan'!I5<=8),'RC Customers by plan'!I5<=8,IF('RC Customers by plan'!I5="","",'RC Customers by plan'!I5<=8))="",FALSE,IF(ISERROR('RC Customers by plan'!I5<=8),'RC Customers by plan'!I5<=8,IF('RC Customers by plan'!I5="","",'RC Customers by plan'!I5<=8))),IF('Model inputs'!AG50="","",'Model inputs'!AG50),IF('Model inputs'!AG46="","",'Model inputs'!AG46))="",0,IF(IF(IF(ISERROR('RC Customers by plan'!I5<=8),'RC Customers by plan'!I5<=8,IF('RC Customers by plan'!I5="","",'RC Customers by plan'!I5<=8))="",FALSE,IF(ISERROR('RC Customers by plan'!I5<=8),'RC Customers by plan'!I5<=8,IF('RC Customers by plan'!I5="","",'RC Customers by plan'!I5<=8))),IF('Model inputs'!AG50="","",'Model inputs'!AG50),IF('Model inputs'!AG46="","",'Model inputs'!AG46)))))) -> 39.671858 | J11: =IF(IF(IF(ISERROR('RC Customers by plan'!J5<1),'RC Customers by plan'!J5<1,IF('RC Customers by plan'!J5="","",'RC Customers by plan'!J5<1))="",FALSE,IF(ISERROR('RC Customers by plan'!J5<1),'RC Customers by plan'!J5<1,IF('RC Customers by plan'!J5="","",'RC Customers by plan'!J5<1))),0,IF(IF(IF(ISERROR('RC Customers by plan'!J5=1),'RC Customers by plan'!J5=1,IF('RC Customers by plan'!J5="","",'RC Customers by plan'!J5=1))="",FALSE,IF(ISERROR('RC Customers by plan'!J5=1),'RC Customers by plan'!J5=1,IF('RC Customers by plan'!J5="","",'RC Customers by plan'!J5=1))),IF('Model inputs'!AG69="","",'Model inputs'!AG69),'RC Customers by plan'!I11*(1+IF(IF(IF(IF(ISERROR('RC Customers by plan'!J5<=8),'RC Customers by plan'!J5<=8,IF('RC Customers by plan'!J5="","",'RC Customers by plan'!J5<=8))="",FALSE,IF(ISERROR('RC Customers by plan'!J5<=8),'RC Customers by plan'!J5<=8,IF('RC Customers by plan'!J5="","",'RC Customers by plan'!J5<=8))),IF('Model inputs'!AG50="","",'Model inputs'!AG50),IF('Model inputs'!AG46="","",'Model inputs'!AG46))="",0,IF(IF(IF(ISERROR('RC Customers by plan'!J5<=8),'RC Customers by plan'!J5<=8,IF('RC Customers by plan'!J5="","",'RC Customers by plan'!J5<=8))="",FALSE,IF(ISERROR('RC Customers by plan'!J5<=8),'RC Customers by plan'!J5<=8,IF('RC Customers by plan'!J5="","",'RC Customers by plan'!J5<=8))),IF('Model inputs'!AG50="","",'Model inputs'!AG50),IF('Model inputs'!AG46="","",'Model inputs'!AG46)))))) -> 42.845607 | K11: =IF(IF(IF(ISERROR('RC Customers by plan'!K5<1),'RC Customers by plan'!K5<1,IF('RC Customers by plan'!K5="","",'RC Customers by plan'!K5<1))="",FALSE,IF(ISERROR('RC Customers by plan'!K5<1),'RC Customers by plan'!K5<1,IF('RC Customers by plan'!K5="","",'RC Customers by plan'!K5<1))),0,IF(IF(IF(ISERROR('RC Customers by plan'!K5=1),'RC Customers by plan'!K5=1,IF('RC Customers by plan'!K5="","",'RC Customers by plan'!K5=1))="",FALSE,IF(ISERROR('RC Customers by plan'!K5=1),'RC Customers by plan'!K5=1,IF('RC Customers by plan'!K5="","",'RC Customers by plan'!K5=1))),IF('Model inputs'!AG69="","",'Model inputs'!AG69),'RC Customers by plan'!J11*(1+IF(IF(IF(IF(ISERROR('RC Customers by plan'!K5<=8),'RC Customers by plan'!K5<=8,IF('RC Customers by plan'!K5="","",'RC Customers by plan'!K5<=8))="",FALSE,IF(ISERROR('RC Customers by plan'!K5<=8),'RC Customers by plan'!K5<=8,IF('RC Customers by plan'!K5="","",'RC Customers by plan'!K5<=8))),IF('Model inputs'!AG50="","",'Model inputs'!AG50),IF('Model inputs'!AG46="","",'Model inputs'!AG46))="",0,IF(IF(IF(ISERROR('RC Customers by plan'!K5<=8),'RC Customers by plan'!K5<=8,IF('RC Customers by plan'!K5="","",'RC Customers by plan'!K5<=8))="",FALSE,IF(ISERROR('RC Customers by plan'!K5<=8),'RC Customers by plan'!K5<=8,IF('RC Customers by plan'!K5="","",'RC Customers by plan'!K5<=8))),IF('Model inputs'!AG50="","",'Model inputs'!AG50),IF('Model inputs'!AG46="","",'Model inputs'!AG46)))))) -> 44.559431 | L11: =IF(IF(IF(ISERROR('RC Customers by plan'!L5<1),'RC Customers by plan'!L5<1,IF('RC Customers by plan'!L5="","",'RC Customers by plan'!L5<1))="",FALSE,IF(ISERROR('RC Customers by plan'!L5<1),'RC Customers by plan'!L5<1,IF('RC Customers by plan'!L5="","",'RC Customers by plan'!L5<1))),0,IF(IF(IF(ISERROR('RC Customers by plan'!L5=1),'RC Customers by plan'!L5=1,IF('RC Customers by plan'!L5="","",'RC Customers by plan'!L5=1))="",FALSE,IF(ISERROR('RC Customers by plan'!L5=1),'RC Customers by plan'!L5=1,IF('RC Customers by plan'!L5="","",'RC Customers by plan'!L5=1))),IF('Model inputs'!AG69="","",'Model inputs'!AG69),'RC Customers by plan'!K11*(1+IF(IF(IF(IF(ISERROR('RC Customers by plan'!L5<=8),'RC Customers by plan'!L5<=8,IF('RC Customers by plan'!L5="","",'RC Customers by plan'!L5<=8))="",FALSE,IF(ISERROR('RC Customers by plan'!L5<=8),'RC Customers by plan'!L5<=8,IF('RC Customers by plan'!L5="","",'RC Customers by plan'!L5<=8))),IF('Model inputs'!AG50="","",'Model inputs'!AG50),IF('Model inputs'!AG46="","",'Model inputs'!AG46))="",0,IF(IF(IF(ISERROR('RC Customers by plan'!L5<=8),'RC Customers by plan'!L5<=8,IF('RC Customers by plan'!L5="","",'RC Customers by plan'!L5<=8))="",FALSE,IF(ISERROR('RC Customers by plan'!L5<=8),'RC Customers by plan'!L5<=8,IF('RC Customers by plan'!L5="","",'RC Customers by plan'!L5<=8))),IF('Model inputs'!AG50="","",'Model inputs'!AG50),IF('Model inputs'!AG46="","",'Model inputs'!AG46)))))) -> 46.341808 | M11: =IF(IF(IF(ISERROR('RC Customers by plan'!M5<1),'RC Customers by plan'!M5<1,IF('RC Customers by plan'!M5="","",'RC Customers by plan'!M5<1))="",FALSE,IF(ISERROR('RC Customers by plan'!M5<1),'RC Customers by plan'!M5<1,IF('RC Customers by plan'!M5="","",'RC Customers by plan'!M5<1))),0,IF(IF(IF(ISERROR('RC Customers by plan'!M5=1),'RC Customers by plan'!M5=1,IF('RC Customers by plan'!M5="","",'RC Customers by plan'!M5=1))="",FALSE,IF(ISERROR('RC Customers by plan'!M5=1),'RC Customers by plan'!M5=1,IF('RC Customers by plan'!M5="","",'RC Customers by plan'!M5=1))),IF('Model inputs'!AG69="","",'Model inputs'!AG69),'RC Customers by plan'!L11*(1+IF(IF(IF(IF(ISERROR('RC Customers by plan'!M5<=8),'RC Customers by plan'!M5<=8,IF('RC Customers by plan'!M5="","",'RC Customers by plan'!M5<=8))="",FALSE,IF(ISERROR('RC Customers by plan'!M5<=8),'RC Customers by plan'!M5<=8,IF('RC Customers by plan'!M5="","",'RC Customers by plan'!M5<=8))),IF('Model inputs'!AG50="","",'Model inputs'!AG50),IF('Model inputs'!AG46="","",'Model inputs'!AG46))="",0,IF(IF(IF(ISERROR('RC Customers by plan'!M5<=8),'RC Customers by plan'!M5<=8,IF('RC Customers by plan'!M5="","",'RC Customers by plan'!M5<=8))="",FALSE,IF(ISERROR('RC Customers by plan'!M5<=8),'RC Customers by plan'!M5<=8,IF('RC Customers by plan'!M5="","",'RC Customers by plan'!M5<=8))),IF('Model inputs'!AG50="","",'Model inputs'!AG50),IF('Model inputs'!AG46="","",'Model inputs'!AG46)))))) -> 48.195481 | N11: =IF(IF(IF(ISERROR('RC Customers by plan'!N5<1),'RC Customers by plan'!N5<1,IF('RC Customers by plan'!N5="","",'RC Customers by plan'!N5<1))="",FALSE,IF(ISERROR('RC Customers by plan'!N5<1),'RC Customers by plan'!N5<1,IF('RC Customers by plan'!N5="","",'RC Customers by plan'!N5<1))),0,IF(IF(IF(ISERROR('RC Customers by plan'!N5=1),'RC Customers by plan'!N5=1,IF('RC Customers by plan'!N5="","",'RC Customers by plan'!N5=1))="",FALSE,IF(ISERROR('RC Customers by plan'!N5=1),'RC Customers by plan'!N5=1,IF('RC Customers by plan'!N5="","",'RC Customers by plan'!N5=1))),IF('Model inputs'!AG69="","",'Model inputs'!AG69),'RC Customers by plan'!M11*(1+IF(IF(IF(IF(ISERROR('RC Customers by plan'!N5<=8),'RC Customers by plan'!N5<=8,IF('RC Customers by plan'!N5="","",'RC Customers by plan'!N5<=8))="",FALSE,IF(ISERROR('RC Customers by plan'!N5<=8),'RC Customers by plan'!N5<=8,IF('RC Customers by plan'!N5="","",'RC Customers by plan'!N5<=8))),IF('Model inputs'!AG50="","",'Model inputs'!AG50),IF('Model inputs'!AG46="","",'Model inputs'!AG46))="",0,IF(IF(IF(ISERROR('RC Customers by plan'!N5<=8),'RC Customers by plan'!N5<=8,IF('RC Customers by plan'!N5="","",'RC Customers by plan'!N5<=8))="",FALSE,IF(ISERROR('RC Customers by plan'!N5<=8),'RC Customers by plan'!N5<=8,IF('RC Customers by plan'!N5="","",'RC Customers by plan'!N5<=8))),IF('Model inputs'!AG50="","",'Model inputs'!AG50),IF('Model inputs'!AG46="","",'Model inputs'!AG46)))))) -> 50.1233 | O11: =IF(IF(IF(ISERROR('RC Customers by plan'!O5<1),'RC Customers by plan'!O5<1,IF('RC Customers by plan'!O5="","",'RC Customers by plan'!O5<1))="",FALSE,IF(ISERROR('RC Customers by plan'!O5<1),'RC Customers by plan'!O5<1,IF('RC Customers by plan'!O5="","",'RC Customers by plan'!O5<1))),0,IF(IF(IF(ISERROR('RC Customers by plan'!O5=1),'RC Customers by plan'!O5=1,IF('RC Customers by plan'!O5="","",'RC Customers by plan'!O5=1))="",FALSE,IF(ISERROR('RC Customers by plan'!O5=1),'RC Customers by plan'!O5=1,IF('RC Customers by plan'!O5="","",'RC Customers by plan'!O5=1))),IF('Model inputs'!AG69="","",'Model inputs'!AG69),'RC Customers by plan'!N11*(1+IF(IF(IF(IF(ISERROR('RC Customers by plan'!O5<=8),'RC Customers by plan'!O5<=8,IF('RC Customers by plan'!O5="","",'RC Customers by plan'!O5<=8))="",FALSE,IF(ISERROR('RC Customers by plan'!O5<=8),'RC Customers by plan'!O5<=8,IF('RC Customers by plan'!O5="","",'RC Customers by plan'!O5<=8))),IF('Model inputs'!AG50="","",'Model inputs'!AG50),IF('Model inputs'!AG46="","",'Model inputs'!AG46))="",0,IF(IF(IF(ISERROR('RC Customers by plan'!O5<=8),'RC Customers by plan'!O5<=8,IF('RC Customers by plan'!O5="","",'RC Customers by plan'!O5<=8))="",FALSE,IF(ISERROR('RC Customers by plan'!O5<=8),'RC Customers by plan'!O5<=8,IF('RC Customers by plan'!O5="","",'RC Customers by plan'!O5<=8))),IF('Model inputs'!AG50="","",'Model inputs'!AG50),IF('Model inputs'!AG46="","",'Model inputs'!AG46)))))) -> 52.128232 | P11: =IF(IF(IF(ISERROR('RC Customers by plan'!P5<1),'RC Customers by plan'!P5<1,IF('RC Customers by plan'!P5="","",'RC Customers by plan'!P5<1))="",FALSE,IF(ISERROR('RC Customers by plan'!P5<1),'RC Customers by plan'!P5<1,IF('RC Customers by plan'!P5="","",'RC Customers by plan'!P5<1))),0,IF(IF(IF(ISERROR('RC Customers by plan'!P5=1),'RC Customers by plan'!P5=1,IF('RC Customers by plan'!P5="","",'RC Customers by plan'!P5=1))="",FALSE,IF(ISERROR('RC Customers by plan'!P5=1),'RC Customers by plan'!P5=1,IF('RC Customers by plan'!P5="","",'RC Customers by plan'!P5=1))),IF('Model inputs'!AG69="","",'Model inputs'!AG69),'RC Customers by plan'!O11*(1+IF(IF(IF(IF(ISERROR('RC Customers by plan'!P5<=8),'RC Customers by plan'!P5<=8,IF('RC Customers by plan'!P5="","",'RC Customers by plan'!P5<=8))="",FALSE,IF(ISERROR('RC Customers by plan'!P5<=8),'RC Customers by plan'!P5<=8,IF('RC Customers by plan'!P5="","",'RC Customers by plan'!P5<=8))),IF('Model inputs'!AG50="","",'Model inputs'!AG50),IF('Model inputs'!AG46="","",'Model inputs'!AG46))="",0,IF(IF(IF(ISERROR('RC Customers by plan'!P5<=8),'RC Customers by plan'!P5<=8,IF('RC Customers by plan'!P5="","",'RC Customers by plan'!P5<=8))="",FALSE,IF(ISERROR('RC Customers by plan'!P5<=8),'RC Customers by plan'!P5<=8,IF('RC Customers by plan'!P5="","",'RC Customers by plan'!P5<=8))),IF('Model inputs'!AG50="","",'Model inputs'!AG50),IF('Model inputs'!AG46="","",'Model inputs'!AG46)))))) -> 54.213361 | Q11: =IF(IF(IF(ISERROR('RC Customers by plan'!Q5<1),'RC Customers by plan'!Q5<1,IF('RC Customers by plan'!Q5="","",'RC Customers by plan'!Q5<1))="",FALSE,IF(ISERROR('RC Customers by plan'!Q5<1),'RC Customers by plan'!Q5<1,IF('RC Customers by plan'!Q5="","",'RC Customers by plan'!Q5<1))),0,IF(IF(IF(ISERROR('RC Customers by plan'!Q5=1),'RC Customers by plan'!Q5=1,IF('RC Customers by plan'!Q5="","",'RC Customers by plan'!Q5=1))="",FALSE,IF(ISERROR('RC Customers by plan'!Q5=1),'RC Customers by plan'!Q5=1,IF('RC Customers by plan'!Q5="","",'RC Customers by plan'!Q5=1))),IF('Model inputs'!AG69="","",'Model inputs'!AG69),'RC Customers by plan'!P11*(1+IF(IF(IF(IF(ISERROR('RC Customers by plan'!Q5<=8),'RC Customers by plan'!Q5<=8,IF('RC Customers by plan'!Q5="","",'RC Customers by plan'!Q5<=8))="",FALSE,IF(ISERROR('RC Customers by plan'!Q5<=8),'RC Customers by plan'!Q5<=8,IF('RC Customers by plan'!Q5="","",'RC Customers by plan'!Q5<=8))),IF('Model inputs'!AG50="","",'Model inputs'!AG50),IF('Model inputs'!AG46="","",'Model inputs'!AG46))="",0,IF(IF(IF(ISERROR('RC Customers by plan'!Q5<=8),'RC Customers by plan'!Q5<=8,IF('RC Customers by plan'!Q5="","",'RC Customers by plan'!Q5<=8))="",FALSE,IF(ISERROR('RC Customers by plan'!Q5<=8),'RC Customers by plan'!Q5<=8,IF('RC Customers by plan'!Q5="","",'RC Customers by plan'!Q5<=8))),IF('Model inputs'!AG50="","",'Model inputs'!AG50),IF('Model inputs'!AG46="","",'Model inputs'!AG46)))))) -> 56.381895 | R11: =IF(IF(IF(ISERROR('RC Customers by plan'!R5<1),'RC Customers by plan'!R5<1,IF('RC Customers by plan'!R5="","",'RC Customers by plan'!R5<1))="",FALSE,IF(ISERROR('RC Customers by plan'!R5<1),'RC Customers by plan'!R5<1,IF('RC Customers by plan'!R5="","",'RC Customers by plan'!R5<1))),0,IF(IF(IF(ISERROR('RC Customers by plan'!R5=1),'RC Customers by plan'!R5=1,IF('RC Customers by plan'!R5="","",'RC Customers by plan'!R5=1))="",FALSE,IF(ISERROR('RC Customers by plan'!R5=1),'RC Customers by plan'!R5=1,IF('RC Customers by plan'!R5="","",'RC Customers by plan'!R5=1))),IF('Model inputs'!AG69="","",'Model inputs'!AG69),'RC Customers by plan'!Q11*(1+IF(IF(IF(IF(ISERROR('RC Customers by plan'!R5<=8),'RC Customers by plan'!R5<=8,IF('RC Customers by plan'!R5="","",'RC Customers by plan'!R5<=8))="",FALSE,IF(ISERROR('RC Customers by plan'!R5<=8),'RC Customers by plan'!R5<=8,IF('RC Customers by plan'!R5="","",'RC Customers by plan'!R5<=8))),IF('Model inputs'!AG50="","",'Model inputs'!AG50),IF('Model inputs'!AG46="","",'Model inputs'!AG46))="",0,IF(IF(IF(ISERROR('RC Customers by plan'!R5<=8),'RC Customers by plan'!R5<=8,IF('RC Customers by plan'!R5="","",'RC Customers by plan'!R5<=8))="",FALSE,IF(ISERROR('RC Customers by plan'!R5<=8),'RC Customers by plan'!R5<=8,IF('RC Customers by plan'!R5="","",'RC Customers by plan'!R5<=8))),IF('Model inputs'!AG50="","",'Model inputs'!AG50),IF('Model inputs'!AG46="","",'Model inputs'!AG46)))))) -> 58.637171 | S11: =IF(IF(IF(ISERROR('RC Customers by plan'!S5<1),'RC Customers by plan'!S5<1,IF('RC Customers by plan'!S5="","",'RC Customers by plan'!S5<1))="",FALSE,IF(ISERROR('RC Customers by plan'!S5<1),'RC Customers by plan'!S5<1,IF('RC Customers by plan'!S5="","",'RC Customers by plan'!S5<1))),0,IF(IF(IF(ISERROR('RC Customers by plan'!S5=1),'RC Customers by plan'!S5=1,IF('RC Customers by plan'!S5="","",'RC Customers by plan'!S5=1))="",FALSE,IF(ISERROR('RC Customers by plan'!S5=1),'RC Customers by plan'!S5=1,IF('RC Customers by plan'!S5="","",'RC Customers by plan'!S5=1))),IF('Model inputs'!AG69="","",'Model inputs'!AG69),'RC Customers by plan'!R11*(1+IF(IF(IF(IF(ISERROR('RC Customers by plan'!S5<=8),'RC Customers by plan'!S5<=8,IF('RC Customers by plan'!S5="","",'RC Customers by plan'!S5<=8))="",FALSE,IF(ISERROR('RC Customers by plan'!S5<=8),'RC Customers by plan'!S5<=8,IF('RC Customers by plan'!S5="","",'RC Customers by plan'!S5<=8))),IF('Model inputs'!AG50="","",'Model inputs'!AG50),IF('Model inputs'!AG46="","",'Model inputs'!AG46))="",0,IF(IF(IF(ISERROR('RC Customers by plan'!S5<=8),'RC Customers by plan'!S5<=8,IF('RC Customers by plan'!S5="","",'RC Customers by plan'!S5<=8))="",FALSE,IF(ISERROR('RC Customers by plan'!S5<=8),'RC Customers by plan'!S5<=8,IF('RC Customers by plan'!S5="","",'RC Customers by plan'!S5<=8))),IF('Model inputs'!AG50="","",'Model inputs'!AG50),IF('Model inputs'!AG46="","",'Model inputs'!AG46)))))) -> 60.982658
