Workbook

Sheet RC P&L, cash & runway
A1: RC P&L, cash & runway
A2: RC P&L, cash & runway · Main Scenario
A4: Variable / dimension | B4: 2026-11 | C4: 2026-12 | D4: 2027-01 | E4: 2027-02 | F4: 2027-03 | G4: 2027-04 | H4: 2027-05 | I4: 2027-06 | J4: 2027-07 | K4: 2027-08 | L4: 2027-09 | M4: 2027-10 | N4: 2027-11 | O4: 2027-12 | P4: 2028-01 | Q4: 2028-02 | R4: 2028-03 | S4: 2028-04
A5: Subscription revenue | B5: =SUM('Model inputs'!E69,'Model inputs'!E70,'Model inputs'!E71) -> 2553 | C5: =SUM('Model inputs'!F69,'Model inputs'!F70,'Model inputs'!F71) -> 4238.8926 | D5: =SUM('Model inputs'!G69,'Model inputs'!G70,'Model inputs'!G71) -> 5619.0762 | E5: =SUM('Model inputs'!H69,'Model inputs'!H70,'Model inputs'!H71) -> 7059.2423 | F5: =SUM('Model inputs'!I69,'Model inputs'!I70,'Model inputs'!I71) -> 8565.7133 | G5: =SUM('Model inputs'!J69,'Model inputs'!J70,'Model inputs'!J71) -> 10145.299 | H5: =SUM('Model inputs'!K69,'Model inputs'!K70,'Model inputs'!K71) -> 11805.331 | I5: =SUM('Model inputs'!L69,'Model inputs'!L70,'Model inputs'!L71) -> 13628.676 | ... S5: =SUM('Model inputs'!V69,'Model inputs'!V70,'Model inputs'!V71) -> 34889.409
A6: Overage revenue | B6: =SUM('Model inputs'!E59,'Model inputs'!E60,'Model inputs'!E61) -> 95 | C6: =SUM('Model inputs'!F59,'Model inputs'!F60,'Model inputs'!F61) -> 160.875 | D6: =SUM('Model inputs'!G59,'Model inputs'!G60,'Model inputs'!G61) -> 213.5869 | E6: =SUM('Model inputs'!H59,'Model inputs'!H60,'Model inputs'!H61) -> 269.05304 | F6: =SUM('Model inputs'!I59,'Model inputs'!I60,'Model inputs'!I61) -> 327.57959 | G6: =SUM('Model inputs'!J59,'Model inputs'!J60,'Model inputs'!J61) -> 389.49713 | H6: =SUM('Model inputs'!K59,'Model inputs'!K60,'Model inputs'!K61) -> 455.16298 | I6: =SUM('Model inputs'!L59,'Model inputs'!L60,'Model inputs'!L61) -> 524.96385 | ... S6: =SUM('Model inputs'!V59,'Model inputs'!V60,'Model inputs'!V61) -> 1332.4977
A7: Long-trailer revenue | B7: =SUM('Model inputs'!E29,'Model inputs'!E30,'Model inputs'!E31) -> 49.68 | C7: =SUM('Model inputs'!F29,'Model inputs'!F30,'Model inputs'!F31) -> 82.1275 | D7: =SUM('Model inputs'!G29,'Model inputs'!G30,'Model inputs'!G31) -> 109.56726 | E7: =SUM('Model inputs'!H29,'Model inputs'!H30,'Model inputs'!H31) -> 138.45231 | F7: =SUM('Model inputs'!I29,'Model inputs'!I30,'Model inputs'!I31) -> 168.93601 | G7: =SUM('Model inputs'!J29,'Model inputs'!J30,'Model inputs'!J31) -> 201.1848 | H7: =SUM('Model inputs'!K29,'Model inputs'!K30,'Model inputs'!K31) -> 235.37936 | I7: =SUM('Model inputs'!L29,'Model inputs'!L30,'Model inputs'!L31) -> 271.71606 | ... S7: =SUM('Model inputs'!V29,'Model inputs'!V30,'Model inputs'!V31) -> 697.64198
A8: Total revenue | B8: =SUM('Model inputs'!E73,'Model inputs'!E74,'Model inputs'!E75) -> 2697.68 | C8: =SUM('Model inputs'!F73,'Model inputs'!F74,'Model inputs'!F75) -> 4481.8951 | D8: =SUM('Model inputs'!G73,'Model inputs'!G74,'Model inputs'!G75) -> 5942.2304 | E8: =SUM('Model inputs'!H73,'Model inputs'!H74,'Model inputs'!H75) -> 7466.7476 | F8: =SUM('Model inputs'!I73,'Model inputs'!I74,'Model inputs'!I75) -> 9062.2289 | G8: =SUM('Model inputs'!J73,'Model inputs'!J74,'Model inputs'!J75) -> 10735.98 | H8: =SUM('Model inputs'!K73,'Model inputs'!K74,'Model inputs'!K75) -> 12495.874 | I8: =SUM('Model inputs'!L73,'Model inputs'!L74,'Model inputs'!L75) -> 14425.355 | ... S8: =SUM('Model inputs'!V73,'Model inputs'!V74,'Model inputs'!V75) -> 36919.548
A9: Kit COGS | B9: =SUM('Model inputs'!E25,'Model inputs'!E26,'Model inputs'!E27) -> 198.72 | C9: =SUM('Model inputs'!F25,'Model inputs'!F26,'Model inputs'!F27) -> 328.51 | D9: =SUM('Model inputs'!G25,'Model inputs'!G26,'Model inputs'!G27) -> 438.26905 | E9: =SUM('Model inputs'!H25,'Model inputs'!H26,'Model inputs'!H27) -> 553.80922 | F9: =SUM('Model inputs'!I25,'Model inputs'!I26,'Model inputs'!I27) -> 675.74404 | G9: =SUM('Model inputs'!J25,'Model inputs'!J26,'Model inputs'!J27) -> 804.73919 | H9: =SUM('Model inputs'!K25,'Model inputs'!K26,'Model inputs'!K27) -> 941.51746 | I9: =SUM('Model inputs'!L25,'Model inputs'!L26,'Model inputs'!L27) -> 1086.8642 | ... S9: =SUM('Model inputs'!V25,'Model inputs'!V26,'Model inputs'!V27) -> 2790.5679
A10: Kit gross profit | B10: ='RC P&L, cash & runway'!B8-'RC P&L, cash & runway'!B9 -> 2498.96 | C10: ='RC P&L, cash & runway'!C8-'RC P&L, cash & runway'!C9 -> 4153.3851 | D10: ='RC P&L, cash & runway'!D8-'RC P&L, cash & runway'!D9 -> 5503.9613 | E10: ='RC P&L, cash & runway'!E8-'RC P&L, cash & runway'!E9 -> 6912.9384 | F10: ='RC P&L, cash & runway'!F8-'RC P&L, cash & runway'!F9 -> 8386.4849 | G10: ='RC P&L, cash & runway'!G8-'RC P&L, cash & runway'!G9 -> 9931.2413 | H10: ='RC P&L, cash & runway'!H8-'RC P&L, cash & runway'!H9 -> 11554.356 | I10: ='RC P&L, cash & runway'!I8-'RC P&L, cash & runway'!I9 -> 13338.491 | ... S10: ='RC P&L, cash & runway'!S8-'RC P&L, cash & runway'!S9 -> 34128.98
A11: Gross margin % | B11: =IFERROR('RC P&L, cash & runway'!B10/'RC P&L, cash & runway'!B8,"") -> 0.9263367 | C11: =IFERROR('RC P&L, cash & runway'!C10/'RC P&L, cash & runway'!C8,"") -> 0.92670288 | D11: =IFERROR('RC P&L, cash & runway'!D10/'RC P&L, cash & runway'!D8,"") -> 0.92624502 | E11: =IFERROR('RC P&L, cash & runway'!E10/'RC P&L, cash & runway'!E8,"") -> 0.92582993 | F11: =IFERROR('RC P&L, cash & runway'!F10/'RC P&L, cash & runway'!F8,"") -> 0.92543291 | G11: =IFERROR('RC P&L, cash & runway'!G10/'RC P&L, cash & runway'!G8,"") -> 0.92504279 | H11: =IFERROR('RC P&L, cash & runway'!H10/'RC P&L, cash & runway'!H8,"") -> 0.92465373 | I11: =IFERROR('RC P&L, cash & runway'!I10/'RC P&L, cash & runway'!I8,"") -> 0.92465598 | ... S11: =IFERROR('RC P&L, cash & runway'!S10/'RC P&L, cash & runway'!S8,"") -> 0.9244149
A12: Payment fees | B12: =SUM('Model inputs'!E63,'Model inputs'!E64,'Model inputs'!E65) -> 92.33272 | C12: =SUM('Model inputs'!F63,'Model inputs'!F64,'Model inputs'!F65) -> 188.06808 | D12: =SUM('Model inputs'!G63,'Model inputs'!G64,'Model inputs'!G65) -> 260.04299 | E12: =SUM('Model inputs'!H63,'Model inputs'!H64,'Model inputs'!H65) -> 335.16643 | F12: =SUM('Model inputs'!I63,'Model inputs'!I64,'Model inputs'!I65) -> 413.78401 | G12: =SUM('Model inputs'!J63,'Model inputs'!J64,'Model inputs'!J65) -> 496.28164 | H12: =SUM('Model inputs'!K63,'Model inputs'!K64,'Model inputs'!K65) -> 583.08838 | I12: =SUM('Model inputs'!L63,'Model inputs'!L64,'Model inputs'!L65) -> 557.28335 | ... S12: =SUM('Model inputs'!V63,'Model inputs'!V64,'Model inputs'!V65) -> 1400.7014
A13: Contribution | B13: =SUM('Model inputs'!E16,'Model inputs'!E17,'Model inputs'!E18) -> 2406.6273 | C13: =SUM('Model inputs'!F16,'Model inputs'!F17,'Model inputs'!F18) -> 3965.317 | D13: =SUM('Model inputs'!G16,'Model inputs'!G17,'Model inputs'!G18) -> 5243.9183 | E13: =SUM('Model inputs'!H16,'Model inputs'!H17,'Model inputs'!H18) -> 6577.772 | F13: =SUM('Model inputs'!I16,'Model inputs'!I17,'Model inputs'!I18) -> 7972.7009 | G13: =SUM('Model inputs'!J16,'Model inputs'!J17,'Model inputs'!J18) -> 9434.9597 | H13: =SUM('Model inputs'!K16,'Model inputs'!K17,'Model inputs'!K18) -> 10971.268 | I13: =SUM('Model inputs'!L16,'Model inputs'!L17,'Model inputs'!L18) -> 12781.208 | ... S13: =SUM('Model inputs'!V16,'Model inputs'!V17,'Model inputs'!V18) -> 32728.279
A14: Contribution margin % | B14: =IFERROR('RC P&L, cash & runway'!B13/'RC P&L, cash & runway'!B8,"") -> 0.89210999 | C14: =IFERROR('RC P&L, cash & runway'!C13/'RC P&L, cash & runway'!C8,"") -> 0.88474115 | D14: =IFERROR('RC P&L, cash & runway'!D13/'RC P&L, cash & runway'!D8,"") -> 0.88248318 | E14: =IFERROR('RC P&L, cash & runway'!E13/'RC P&L, cash & runway'!E8,"") -> 0.88094205 | F14: =IFERROR('RC P&L, cash & runway'!F13/'RC P&L, cash & runway'!F8,"") -> 0.87977262 | G14: =IFERROR('RC P&L, cash & runway'!G13/'RC P&L, cash & runway'!G8,"") -> 0.87881677 | H14: =IFERROR('RC P&L, cash & runway'!H13/'RC P&L, cash & runway'!H8,"") -> 0.87799126 | I14: =IFERROR('RC P&L, cash & runway'!I13/'RC P&L, cash & runway'!I8,"") -> 0.88602377 | ... S14: =IFERROR('RC P&L, cash & runway'!S13/'RC P&L, cash & runway'!S8,"") -> 0.88647561
A15: Opex | B15: =SUM('Model inputs'!E35,'Model inputs'!E36,'Model inputs'!E37,'Model inputs'!E38,'Model inputs'!E39,'Model inputs'!E40,'Model inputs'!E41,'Model inputs'!E42,'Model inputs'!E43,'Model inputs'!E44,'Model inputs'!E45) -> 5245 | C15: =SUM('Model inputs'!F35,'Model inputs'!F36,'Model inputs'!F37,'Model inputs'!F38,'Model inputs'!F39,'Model inputs'!F40,'Model inputs'!F41,'Model inputs'!F42,'Model inputs'!F43,'Model inputs'!F44,'Model inputs'!F45) -> 5595 | D15: =SUM('Model inputs'!G35,'Model inputs'!G36,'Model inputs'!G37,'Model inputs'!G38,'Model inputs'!G39,'Model inputs'!G40,'Model inputs'!G41,'Model inputs'!G42,'Model inputs'!G43,'Model inputs'!G44,'Model inputs'!G45) -> 5595 | E15: =SUM('Model inputs'!H35,'Model inputs'!H36,'Model inputs'!H37,'Model inputs'!H38,'Model inputs'!H39,'Model inputs'!H40,'Model inputs'!H41,'Model inputs'!H42,'Model inputs'!H43,'Model inputs'!H44,'Model inputs'!H45) -> 7245 | F15: =SUM('Model inputs'!I35,'Model inputs'!I36,'Model inputs'!I37,'Model inputs'!I38,'Model inputs'!I39,'Model inputs'!I40,'Model inputs'!I41,'Model inputs'!I42,'Model inputs'!I43,'Model inputs'!I44,'Model inputs'!I45) -> 7445 | G15: =SUM('Model inputs'!J35,'Model inputs'!J36,'Model inputs'!J37,'Model inputs'!J38,'Model inputs'!J39,'Model inputs'!J40,'Model inputs'!J41,'Model inputs'!J42,'Model inputs'!J43,'Model inputs'!J44,'Model inputs'!J45) -> 7445 | H15: =SUM('Model inputs'!K35,'Model inputs'!K36,'Model inputs'!K37,'Model inputs'!K38,'Model inputs'!K39,'Model inputs'!K40,'Model inputs'!K41,'Model inputs'!K42,'Model inputs'!K43,'Model inputs'!K44,'Model inputs'!K45) -> 11445 | I15: =SUM('Model inputs'!L35,'Model inputs'!L36,'Model inputs'!L37,'Model inputs'!L38,'Model inputs'!L39,'Model inputs'!L40,'Model inputs'!L41,'Model inputs'!L42,'Model inputs'!L43,'Model inputs'!L44,'Model inputs'!L45) -> 11445 | ... S15: =SUM('Model inputs'!V35,'Model inputs'!V36,'Model inputs'!V37,'Model inputs'!V38,'Model inputs'!V39,'Model inputs'!V40,'Model inputs'!V41,'Model inputs'!V42,'Model inputs'!V43,'Model inputs'!V44,'Model inputs'!V45) -> 11445
A16: Net income | B16: ='RC P&L, cash & runway'!B13-'RC P&L, cash & runway'!B15 -> -2838.3727 | C16: ='RC P&L, cash & runway'!C13-'RC P&L, cash & runway'!C15 -> -1629.683 | D16: ='RC P&L, cash & runway'!D13-'RC P&L, cash & runway'!D15 -> -351.08167 | E16: ='RC P&L, cash & runway'!E13-'RC P&L, cash & runway'!E15 -> -667.22802 | F16: ='RC P&L, cash & runway'!F13-'RC P&L, cash & runway'!F15 -> 527.70086 | G16: ='RC P&L, cash & runway'!G13-'RC P&L, cash & runway'!G15 -> 1989.9597 | H16: ='RC P&L, cash & runway'!H13-'RC P&L, cash & runway'!H15 -> -473.73205 | I16: ='RC P&L, cash & runway'!I13-'RC P&L, cash & runway'!I15 -> 1336.2079 | ... S16: ='RC P&L, cash & runway'!S13-'RC P&L, cash & runway'!S15 -> 21283.279
A18: Cash collected | B18: =SUM('Model inputs'!E10,'Model inputs'!E11,'Model inputs'!E12) -> 2697.68 | C18: =SUM('Model inputs'!F10,'Model inputs'!F11,'Model inputs'!F12) -> 5606.7786 | D18: =SUM('Model inputs'!G10,'Model inputs'!G11,'Model inputs'!G12) -> 7825.4376 | E18: =SUM('Model inputs'!H10,'Model inputs'!H11,'Model inputs'!H12) -> 10146.446 | F18: =SUM('Model inputs'!I10,'Model inputs'!I11,'Model inputs'!I12) -> 12580.773 | G18: =SUM('Model inputs'!J10,'Model inputs'!J11,'Model inputs'!J12) -> 15140.751 | H18: =SUM('Model inputs'!K10,'Model inputs'!K11,'Model inputs'!K12) -> 17840.171 | I18: =SUM('Model inputs'!L10,'Model inputs'!L11,'Model inputs'!L12) -> 16646.247 | ... S18: =SUM('Model inputs'!V10,'Model inputs'!V11,'Model inputs'!V12) -> 42234.94
A19: Opex cash paid | B19: =SUM('Model inputs'!E47,'Model inputs'!E48,'Model inputs'!E49,'Model inputs'!E50,'Model inputs'!E51,'Model inputs'!E52,'Model inputs'!E53,'Model inputs'!E54,'Model inputs'!E55,'Model inputs'!E56,'Model inputs'!E57) -> 9370 | C19: =SUM('Model inputs'!F47,'Model inputs'!F48,'Model inputs'!F49,'Model inputs'!F50,'Model inputs'!F51,'Model inputs'!F52,'Model inputs'!F53,'Model inputs'!F54,'Model inputs'!F55,'Model inputs'!F56,'Model inputs'!F57) -> 5220 | D19: =SUM('Model inputs'!G47,'Model inputs'!G48,'Model inputs'!G49,'Model inputs'!G50,'Model inputs'!G51,'Model inputs'!G52,'Model inputs'!G53,'Model inputs'!G54,'Model inputs'!G55,'Model inputs'!G56,'Model inputs'!G57) -> 5220 | E19: =SUM('Model inputs'!H47,'Model inputs'!H48,'Model inputs'!H49,'Model inputs'!H50,'Model inputs'!H51,'Model inputs'!H52,'Model inputs'!H53,'Model inputs'!H54,'Model inputs'!H55,'Model inputs'!H56,'Model inputs'!H57) -> 6870 | F19: =SUM('Model inputs'!I47,'Model inputs'!I48,'Model inputs'!I49,'Model inputs'!I50,'Model inputs'!I51,'Model inputs'!I52,'Model inputs'!I53,'Model inputs'!I54,'Model inputs'!I55,'Model inputs'!I56,'Model inputs'!I57) -> 7070 | G19: =SUM('Model inputs'!J47,'Model inputs'!J48,'Model inputs'!J49,'Model inputs'!J50,'Model inputs'!J51,'Model inputs'!J52,'Model inputs'!J53,'Model inputs'!J54,'Model inputs'!J55,'Model inputs'!J56,'Model inputs'!J57) -> 7070 | H19: =SUM('Model inputs'!K47,'Model inputs'!K48,'Model inputs'!K49,'Model inputs'!K50,'Model inputs'!K51,'Model inputs'!K52,'Model inputs'!K53,'Model inputs'!K54,'Model inputs'!K55,'Model inputs'!K56,'Model inputs'!K57) -> 11070 | I19: =SUM('Model inputs'!L47,'Model inputs'!L48,'Model inputs'!L49,'Model inputs'!L50,'Model inputs'!L51,'Model inputs'!L52,'Model inputs'!L53,'Model inputs'!L54,'Model inputs'!L55,'Model inputs'!L56,'Model inputs'!L57) -> 11070 | ... S19: =SUM('Model inputs'!V47,'Model inputs'!V48,'Model inputs'!V49,'Model inputs'!V50,'Model inputs'!V51,'Model inputs'!V52,'Model inputs'!V53,'Model inputs'!V54,'Model inputs'!V55,'Model inputs'!V56,'Model inputs'!V57) -> 11070
A20: Equity raised | B20: =IF(IF(IF(IFERROR(IF(ISERROR('Model inputs'!B8=1),'Model inputs'!B8=1,IF('Model inputs'!B8="","",'Model inputs'!B8=1))=FALSE,FALSE),FALSE,IF(IFERROR('Model inputs'!B358=FALSE,FALSE),FALSE,IF(IFERROR('Model inputs'!B359=FALSE,FALSE),FALSE,IF(OR(IF(ISERROR('Model inputs'!B8=1),'Model inputs'!B8=1,IF('Model inputs'!B8="","",'Model inputs'!B8=1))="",'Model inputs'!B358="",'Model inputs'!B359=""),"",AND(IF(ISERROR('Model inputs'!B8=1),'Model inputs'!B8=1,IF('Model inputs'!B8="","",'Model inputs'!B8=1)),'Model inputs'!B358,'Model inputs'!B359)))))="",FALSE,IF(IFERROR(IF(ISERROR('Model inputs'!B8=1),'Model inputs'!B8=1,IF('Model inputs'!B8="","",'Model inputs'!B8=1))=FALSE,FALSE),FALSE,IF(IFERROR('Model inputs'!B358=FALSE,FALSE),FALSE,IF(IFERROR('Model inputs'!B359=FALSE,FALSE),FALSE,IF(OR(IF(ISERROR('Model inputs'!B8=1),'Model inputs'!B8=1,IF('Model inputs'!B8="","",'Model inputs'!B8=1))="",'Model inputs'!B358="",'Model inputs'!B359=""),"",AND(IF(ISERROR('Model inputs'!B8=1),'Model inputs'!B8=1,IF('Model inputs'!B8="","",'Model inputs'!B8=1)),'Model inputs'!B358,'Model inputs'!B359)))))),IF('Model inputs'!B6="","",'Model inputs'!B6),0) -> 0 | C20: =IF(IF(IF(IFERROR(IF(ISERROR('Model inputs'!B8=1),'Model inputs'!B8=1,IF('Model inputs'!B8="","",'Model inputs'!B8=1))=FALSE,FALSE),FALSE,IF(IFERROR('Model inputs'!B360=FALSE,FALSE),FALSE,IF(IFERROR('Model inputs'!B361=FALSE,FALSE),FALSE,IF(OR(IF(ISERROR('Model inputs'!B8=1),'Model inputs'!B8=1,IF('Model inputs'!B8="","",'Model inputs'!B8=1))="",'Model inputs'!B360="",'Model inputs'!B361=""),"",AND(IF(ISERROR('Model inputs'!B8=1),'Model inputs'!B8=1,IF('Model inputs'!B8="","",'Model inputs'!B8=1)),'Model inputs'!B360,'Model inputs'!B361)))))="",FALSE,IF(IFERROR(IF(ISERROR('Model inputs'!B8=1),'Model inputs'!B8=1,IF('Model inputs'!B8="","",'Model inputs'!B8=1))=FALSE,FALSE),FALSE,IF(IFERROR('Model inputs'!B360=FALSE,FALSE),FALSE,IF(IFERROR('Model inputs'!B361=FALSE,FALSE),FALSE,IF(OR(IF(ISERROR('Model inputs'!B8=1),'Model inputs'!B8=1,IF('Model inputs'!B8="","",'Model inputs'!B8=1))="",'Model inputs'!B360="",'Model inputs'!B361=""),"",AND(IF(ISERROR('Model inputs'!B8=1),'Model inputs'!B8=1,IF('Model inputs'!B8="","",'Model inputs'!B8=1)),'Model inputs'!B360,'Model inputs'!B361)))))),IF('Model inputs'!B6="","",'Model inputs'!B6),0) -> 0 | D20: =IF(IF(IF(IFERROR(IF(ISERROR('Model inputs'!B8=1),'Model inputs'!B8=1,IF('Model inputs'!B8="","",'Model inputs'!B8=1))=FALSE,FALSE),FALSE,IF(IFERROR('Model inputs'!B362=FALSE,FALSE),FALSE,IF(IFERROR('Model inputs'!B363=FALSE,FALSE),FALSE,IF(OR(IF(ISERROR('Model inputs'!B8=1),'Model inputs'!B8=1,IF('Model inputs'!B8="","",'Model inputs'!B8=1))="",'Model inputs'!B362="",'Model inputs'!B363=""),"",AND(IF(ISERROR('Model inputs'!B8=1),'Model inputs'!B8=1,IF('Model inputs'!B8="","",'Model inputs'!B8=1)),'Model inputs'!B362,'Model inputs'!B363)))))="",FALSE,IF(IFERROR(IF(ISERROR('Model inputs'!B8=1),'Model inputs'!B8=1,IF('Model inputs'!B8="","",'Model inputs'!B8=1))=FALSE,FALSE),FALSE,IF(IFERROR('Model inputs'!B362=FALSE,FALSE),FALSE,IF(IFERROR('Model inputs'!B363=FALSE,FALSE),FALSE,IF(OR(IF(ISERROR('Model inputs'!B8=1),'Model inputs'!B8=1,IF('Model inputs'!B8="","",'Model inputs'!B8=1))="",'Model inputs'!B362="",'Model inputs'!B363=""),"",AND(IF(ISERROR('Model inputs'!B8=1),'Model inputs'!B8=1,IF('Model inputs'!B8="","",'Model inputs'!B8=1)),'Model inputs'!B362,'Model inputs'!B363)))))),IF('Model inputs'!B6="","",'Model inputs'!B6),0) -> 0 | E20: =IF(IF(IF(IFERROR(IF(ISERROR('Model inputs'!B8=1),'Model inputs'!B8=1,IF('Model inputs'!B8="","",'Model inputs'!B8=1))=FALSE,FALSE),FALSE,IF(IFERROR('Model inputs'!B364=FALSE,FALSE),FALSE,IF(IFERROR('Model inputs'!B365=FALSE,FALSE),FALSE,IF(OR(IF(ISERROR('Model inputs'!B8=1),'Model inputs'!B8=1,IF('Model inputs'!B8="","",'Model inputs'!B8=1))="",'Model inputs'!B364="",'Model inputs'!B365=""),"",AND(IF(ISERROR('Model inputs'!B8=1),'Model inputs'!B8=1,IF('Model inputs'!B8="","",'Model inputs'!B8=1)),'Model inputs'!B364,'Model inputs'!B365)))))="",FALSE,IF(IFERROR(IF(ISERROR('Model inputs'!B8=1),'Model inputs'!B8=1,IF('Model inputs'!B8="","",'Model inputs'!B8=1))=FALSE,FALSE),FALSE,IF(IFERROR('Model inputs'!B364=FALSE,FALSE),FALSE,IF(IFERROR('Model inputs'!B365=FALSE,FALSE),FALSE,IF(OR(IF(ISERROR('Model inputs'!B8=1),'Model inputs'!B8=1,IF('Model inputs'!B8="","",'Model inputs'!B8=1))="",'Model inputs'!B364="",'Model inputs'!B365=""),"",AND(IF(ISERROR('Model inputs'!B8=1),'Model inputs'!B8=1,IF('Model inputs'!B8="","",'Model inputs'!B8=1)),'Model inputs'!B364,'Model inputs'!B365)))))),IF('Model inputs'!B6="","",'Model inputs'!B6),0) -> 0 | F20: =IF(IF(IF(IFERROR(IF(ISERROR('Model inputs'!B8=1),'Model inputs'!B8=1,IF('Model inputs'!B8="","",'Model inputs'!B8=1))=FALSE,FALSE),FALSE,IF(IFERROR('Model inputs'!B366=FALSE,FALSE),FALSE,IF(IFERROR('Model inputs'!B367=FALSE,FALSE),FALSE,IF(OR(IF(ISERROR('Model inputs'!B8=1),'Model inputs'!B8=1,IF('Model inputs'!B8="","",'Model inputs'!B8=1))="",'Model inputs'!B366="",'Model inputs'!B367=""),"",AND(IF(ISERROR('Model inputs'!B8=1),'Model inputs'!B8=1,IF('Model inputs'!B8="","",'Model inputs'!B8=1)),'Model inputs'!B366,'Model inputs'!B367)))))="",FALSE,IF(IFERROR(IF(ISERROR('Model inputs'!B8=1),'Model inputs'!B8=1,IF('Model inputs'!B8="","",'Model inputs'!B8=1))=FALSE,FALSE),FALSE,IF(IFERROR('Model inputs'!B366=FALSE,FALSE),FALSE,IF(IFERROR('Model inputs'!B367=FALSE,FALSE),FALSE,IF(OR(IF(ISERROR('Model inputs'!B8=1),'Model inputs'!B8=1,IF('Model inputs'!B8="","",'Model inputs'!B8=1))="",'Model inputs'!B366="",'Model inputs'!B367=""),"",AND(IF(ISERROR('Model inputs'!B8=1),'Model inputs'!B8=1,IF('Model inputs'!B8="","",'Model inputs'!B8=1)),'Model inputs'!B366,'Model inputs'!B367)))))),IF('Model inputs'!B6="","",'Model inputs'!B6),0) -> 0 | G20: =IF(IF(IF(IFERROR(IF(ISERROR('Model inputs'!B8=1),'Model inputs'!B8=1,IF('Model inputs'!B8="","",'Model inputs'!B8=1))=FALSE,FALSE),FALSE,IF(IFERROR('Model inputs'!B368=FALSE,FALSE),FALSE,IF(IFERROR('Model inputs'!B369=FALSE,FALSE),FALSE,IF(OR(IF(ISERROR('Model inputs'!B8=1),'Model inputs'!B8=1,IF('Model inputs'!B8="","",'Model inputs'!B8=1))="",'Model inputs'!B368="",'Model inputs'!B369=""),"",AND(IF(ISERROR('Model inputs'!B8=1),'Model inputs'!B8=1,IF('Model inputs'!B8="","",'Model inputs'!B8=1)),'Model inputs'!B368,'Model inputs'!B369)))))="",FALSE,IF(IFERROR(IF(ISERROR('Model inputs'!B8=1),'Model inputs'!B8=1,IF('Model inputs'!B8="","",'Model inputs'!B8=1))=FALSE,FALSE),FALSE,IF(IFERROR('Model inputs'!B368=FALSE,FALSE),FALSE,IF(IFERROR('Model inputs'!B369=FALSE,FALSE),FALSE,IF(OR(IF(ISERROR('Model inputs'!B8=1),'Model inputs'!B8=1,IF('Model inputs'!B8="","",'Model inputs'!B8=1))="",'Model inputs'!B368="",'Model inputs'!B369=""),"",AND(IF(ISERROR('Model inputs'!B8=1),'Model inputs'!B8=1,IF('Model inputs'!B8="","",'Model inputs'!B8=1)),'Model inputs'!B368,'Model inputs'!B369)))))),IF('Model inputs'!B6="","",'Model inputs'!B6),0) -> 0 | H20: =IF(IF(IF(IFERROR(IF(ISERROR('Model inputs'!B8=1),'Model inputs'!B8=1,IF('Model inputs'!B8="","",'Model inputs'!B8=1))=FALSE,FALSE),FALSE,IF(IFERROR('Model inputs'!B370=FALSE,FALSE),FALSE,IF(IFERROR('Model inputs'!B371=FALSE,FALSE),FALSE,IF(OR(IF(ISERROR('Model inputs'!B8=1),'Model inputs'!B8=1,IF('Model inputs'!B8="","",'Model inputs'!B8=1))="",'Model inputs'!B370="",'Model inputs'!B371=""),"",AND(IF(ISERROR('Model inputs'!B8=1),'Model inputs'!B8=1,IF('Model inputs'!B8="","",'Model inputs'!B8=1)),'Model inputs'!B370,'Model inputs'!B371)))))="",FALSE,IF(IFERROR(IF(ISERROR('Model inputs'!B8=1),'Model inputs'!B8=1,IF('Model inputs'!B8="","",'Model inputs'!B8=1))=FALSE,FALSE),FALSE,IF(IFERROR('Model inputs'!B370=FALSE,FALSE),FALSE,IF(IFERROR('Model inputs'!B371=FALSE,FALSE),FALSE,IF(OR(IF(ISERROR('Model inputs'!B8=1),'Model inputs'!B8=1,IF('Model inputs'!B8="","",'Model inputs'!B8=1))="",'Model inputs'!B370="",'Model inputs'!B371=""),"",AND(IF(ISERROR('Model inputs'!B8=1),'Model inputs'!B8=1,IF('Model inputs'!B8="","",'Model inputs'!B8=1)),'Model inputs'!B370,'Model inputs'!B371)))))),IF('Model inputs'!B6="","",'Model inputs'!B6),0) -> 0 | I20: =IF(IF(IF(IFERROR(IF(ISERROR('Model inputs'!B8=1),'Model inputs'!B8=1,IF('Model inputs'!B8="","",'Model inputs'!B8=1))=FALSE,FALSE),FALSE,IF(IFERROR('Model inputs'!B372=FALSE,FALSE),FALSE,IF(IFERROR('Model inputs'!B373=FALSE,FALSE),FALSE,IF(OR(IF(ISERROR('Model inputs'!B8=1),'Model inputs'!B8=1,IF('Model inputs'!B8="","",'Model inputs'!B8=1))="",'Model inputs'!B372="",'Model inputs'!B373=""),"",AND(IF(ISERROR('Model inputs'!B8=1),'Model inputs'!B8=1,IF('Model inputs'!B8="","",'Model inputs'!B8=1)),'Model inputs'!B372,'Model inputs'!B373)))))="",FALSE,IF(IFERROR(IF(ISERROR('Model inputs'!B8=1),'Model inputs'!B8=1,IF('Model inputs'!B8="","",'Model inputs'!B8=1))=FALSE,FALSE),FALSE,IF(IFERROR('Model inputs'!B372=FALSE,FALSE),FALSE,IF(IFERROR('Model inputs'!B373=FALSE,FALSE),FALSE,IF(OR(IF(ISERROR('Model inputs'!B8=1),'Model inputs'!B8=1,IF('Model inputs'!B8="","",'Model inputs'!B8=1))="",'Model inputs'!B372="",'Model inputs'!B373=""),"",AND(IF(ISERROR('Model inputs'!B8=1),'Model inputs'!B8=1,IF('Model inputs'!B8="","",'Model inputs'!B8=1)),'Model inputs'!B372,'Model inputs'!B373)))))),IF('Model inputs'!B6="","",'Model inputs'!B6),0) -> 0 | J20: =IF(IF(IF(IFERROR(IF(ISERROR('Model inputs'!B8=1),'Model inputs'!B8=1,IF('Model inputs'!B8="","",'Model inputs'!B8=1))=FALSE,FALSE),FALSE,IF(IFERROR('Model inputs'!B374=FALSE,FALSE),FALSE,IF(IFERROR('Model inputs'!B375=FALSE,FALSE),FALSE,IF(OR(IF(ISERROR('Model inputs'!B8=1),'Model inputs'!B8=1,IF('Model inputs'!B8="","",'Model inputs'!B8=1))="",'Model inputs'!B374="",'Model inputs'!B375=""),"",AND(IF(ISERROR('Model inputs'!B8=1),'Model inputs'!B8=1,IF('Model inputs'!B8="","",'Model inputs'!B8=1)),'Model inputs'!B374,'Model inputs'!B375)))))="",FALSE,IF(IFERROR(IF(ISERROR('Model inputs'!B8=1),'Model inputs'!B8=1,IF('Model inputs'!B8="","",'Model inputs'!B8=1))=FALSE,FALSE),FALSE,IF(IFERROR('Model inputs'!B374=FALSE,FALSE),FALSE,IF(IFERROR('Model inputs'!B375=FALSE,FALSE),FALSE,IF(OR(IF(ISERROR('Model inputs'!B8=1),'Model inputs'!B8=1,IF('Model inputs'!B8="","",'Model inputs'!B8=1))="",'Model inputs'!B374="",'Model inputs'!B375=""),"",AND(IF(ISERROR('Model inputs'!B8=1),'Model inputs'!B8=1,IF('Model inputs'!B8="","",'Model inputs'!B8=1)),'Model inputs'!B374,'Model inputs'!B375)))))),IF('Model inputs'!B6="","",'Model inputs'!B6),0) -> 0 | K20: =IF(IF(IF(IFERROR(IF(ISERROR('Model inputs'!B8=1),'Model inputs'!B8=1,IF('Model inputs'!B8="","",'Model inputs'!B8=1))=FALSE,FALSE),FALSE,IF(IFERROR('Model inputs'!B376=FALSE,FALSE),FALSE,IF(IFERROR('Model inputs'!B377=FALSE,FALSE),FALSE,IF(OR(IF(ISERROR('Model inputs'!B8=1),'Model inputs'!B8=1,IF('Model inputs'!B8="","",'Model inputs'!B8=1))="",'Model inputs'!B376="",'Model inputs'!B377=""),"",AND(IF(ISERROR('Model inputs'!B8=1),'Model inputs'!B8=1,IF('Model inputs'!B8="","",'Model inputs'!B8=1)),'Model inputs'!B376,'Model inputs'!B377)))))="",FALSE,IF(IFERROR(IF(ISERROR('Model inputs'!B8=1),'Model inputs'!B8=1,IF('Model inputs'!B8="","",'Model inputs'!B8=1))=FALSE,FALSE),FALSE,IF(IFERROR('Model inputs'!B376=FALSE,FALSE),FALSE,IF(IFERROR('Model inputs'!B377=FALSE,FALSE),FALSE,IF(OR(IF(ISERROR('Model inputs'!B8=1),'Model inputs'!B8=1,IF('Model inputs'!B8="","",'Model inputs'!B8=1))="",'Model inputs'!B376="",'Model inputs'!B377=""),"",AND(IF(ISERROR('Model inputs'!B8=1),'Model inputs'!B8=1,IF('Model inputs'!B8="","",'Model inputs'!B8=1)),'Model inputs'!B376,'Model inputs'!B377)))))),IF('Model inputs'!B6="","",'Model inputs'!B6),0) -> 0 | L20: =IF(IF(IF(IFERROR(IF(ISERROR('Model inputs'!B8=1),'Model inputs'!B8=1,IF('Model inputs'!B8="","",'Model inputs'!B8=1))=FALSE,FALSE),FALSE,IF(IFERROR('Model inputs'!B378=FALSE,FALSE),FALSE,IF(IFERROR('Model inputs'!B379=FALSE,FALSE),FALSE,IF(OR(IF(ISERROR('Model inputs'!B8=1),'Model inputs'!B8=1,IF('Model inputs'!B8="","",'Model inputs'!B8=1))="",'Model inputs'!B378="",'Model inputs'!B379=""),"",AND(IF(ISERROR('Model inputs'!B8=1),'Model inputs'!B8=1,IF('Model inputs'!B8="","",'Model inputs'!B8=1)),'Model inputs'!B378,'Model inputs'!B379)))))="",FALSE,IF(IFERROR(IF(ISERROR('Model inputs'!B8=1),'Model inputs'!B8=1,IF('Model inputs'!B8="","",'Model inputs'!B8=1))=FALSE,FALSE),FALSE,IF(IFERROR('Model inputs'!B378=FALSE,FALSE),FALSE,IF(IFERROR('Model inputs'!B379=FALSE,FALSE),FALSE,IF(OR(IF(ISERROR('Model inputs'!B8=1),'Model inputs'!B8=1,IF('Model inputs'!B8="","",'Model inputs'!B8=1))="",'Model inputs'!B378="",'Model inputs'!B379=""),"",AND(IF(ISERROR('Model inputs'!B8=1),'Model inputs'!B8=1,IF('Model inputs'!B8="","",'Model inputs'!B8=1)),'Model inputs'!B378,'Model inputs'!B379)))))),IF('Model inputs'!B6="","",'Model inputs'!B6),0) -> 0 | M20: =IF(IF(IF(IFERROR(IF(ISERROR('Model inputs'!B8=1),'Model inputs'!B8=1,IF('Model inputs'!B8="","",'Model inputs'!B8=1))=FALSE,FALSE),FALSE,IF(IFERROR('Model inputs'!B380=FALSE,FALSE),FALSE,IF(IFERROR('Model inputs'!B381=FALSE,FALSE),FALSE,IF(OR(IF(ISERROR('Model inputs'!B8=1),'Model inputs'!B8=1,IF('Model inputs'!B8="","",'Model inputs'!B8=1))="",'Model inputs'!B380="",'Model inputs'!B381=""),"",AND(IF(ISERROR('Model inputs'!B8=1),'Model inputs'!B8=1,IF('Model inputs'!B8="","",'Model inputs'!B8=1)),'Model inputs'!B380,'Model inputs'!B381)))))="",FALSE,IF(IFERROR(IF(ISERROR('Model inputs'!B8=1),'Model inputs'!B8=1,IF('Model inputs'!B8="","",'Model inputs'!B8=1))=FALSE,FALSE),FALSE,IF(IFERROR('Model inputs'!B380=FALSE,FALSE),FALSE,IF(IFERROR('Model inputs'!B381=FALSE,FALSE),FALSE,IF(OR(IF(ISERROR('Model inputs'!B8=1),'Model inputs'!B8=1,IF('Model inputs'!B8="","",'Model inputs'!B8=1))="",'Model inputs'!B380="",'Model inputs'!B381=""),"",AND(IF(ISERROR('Model inputs'!B8=1),'Model inputs'!B8=1,IF('Model inputs'!B8="","",'Model inputs'!B8=1)),'Model inputs'!B380,'Model inputs'!B381)))))),IF('Model inputs'!B6="","",'Model inputs'!B6),0) -> 0 | N20: =IF(IF(IF(IFERROR(IF(ISERROR('Model inputs'!B8=1),'Model inputs'!B8=1,IF('Model inputs'!B8="","",'Model inputs'!B8=1))=FALSE,FALSE),FALSE,IF(IFERROR('Model inputs'!B382=FALSE,FALSE),FALSE,IF(IFERROR('Model inputs'!B383=FALSE,FALSE),FALSE,IF(OR(IF(ISERROR('Model inputs'!B8=1),'Model inputs'!B8=1,IF('Model inputs'!B8="","",'Model inputs'!B8=1))="",'Model inputs'!B382="",'Model inputs'!B383=""),"",AND(IF(ISERROR('Model inputs'!B8=1),'Model inputs'!B8=1,IF('Model inputs'!B8="","",'Model inputs'!B8=1)),'Model inputs'!B382,'Model inputs'!B383)))))="",FALSE,IF(IFERROR(IF(ISERROR('Model inputs'!B8=1),'Model inputs'!B8=1,IF('Model inputs'!B8="","",'Model inputs'!B8=1))=FALSE,FALSE),FALSE,IF(IFERROR('Model inputs'!B382=FALSE,FALSE),FALSE,IF(IFERROR('Model inputs'!B383=FALSE,FALSE),FALSE,IF(OR(IF(ISERROR('Model inputs'!B8=1),'Model inputs'!B8=1,IF('Model inputs'!B8="","",'Model inputs'!B8=1))="",'Model inputs'!B382="",'Model inputs'!B383=""),"",AND(IF(ISERROR('Model inputs'!B8=1),'Model inputs'!B8=1,IF('Model inputs'!B8="","",'Model inputs'!B8=1)),'Model inputs'!B382,'Model inputs'!B383)))))),IF('Model inputs'!B6="","",'Model inputs'!B6),0) -> 0 | O20: =IF(IF(IF(IFERROR(IF(ISERROR('Model inputs'!B8=1),'Model inputs'!B8=1,IF('Model inputs'!B8="","",'Model inputs'!B8=1))=FALSE,FALSE),FALSE,IF(IFERROR('Model inputs'!B384=FALSE,FALSE),FALSE,IF(IFERROR('Model inputs'!B385=FALSE,FALSE),FALSE,IF(OR(IF(ISERROR('Model inputs'!B8=1),'Model inputs'!B8=1,IF('Model inputs'!B8="","",'Model inputs'!B8=1))="",'Model inputs'!B384="",'Model inputs'!B385=""),"",AND(IF(ISERROR('Model inputs'!B8=1),'Model inputs'!B8=1,IF('Model inputs'!B8="","",'Model inputs'!B8=1)),'Model inputs'!B384,'Model inputs'!B385)))))="",FALSE,IF(IFERROR(IF(ISERROR('Model inputs'!B8=1),'Model inputs'!B8=1,IF('Model inputs'!B8="","",'Model inputs'!B8=1))=FALSE,FALSE),FALSE,IF(IFERROR('Model inputs'!B384=FALSE,FALSE),FALSE,IF(IFERROR('Model inputs'!B385=FALSE,FALSE),FALSE,IF(OR(IF(ISERROR('Model inputs'!B8=1),'Model inputs'!B8=1,IF('Model inputs'!B8="","",'Model inputs'!B8=1))="",'Model inputs'!B384="",'Model inputs'!B385=""),"",AND(IF(ISERROR('Model inputs'!B8=1),'Model inputs'!B8=1,IF('Model inputs'!B8="","",'Model inputs'!B8=1)),'Model inputs'!B384,'Model inputs'!B385)))))),IF('Model inputs'!B6="","",'Model inputs'!B6),0) -> 0 | P20: =IF(IF(IF(IFERROR(IF(ISERROR('Model inputs'!B8=1),'Model inputs'!B8=1,IF('Model inputs'!B8="","",'Model inputs'!B8=1))=FALSE,FALSE),FALSE,IF(IFERROR('Model inputs'!B386=FALSE,FALSE),FALSE,IF(IFERROR('Model inputs'!B387=FALSE,FALSE),FALSE,IF(OR(IF(ISERROR('Model inputs'!B8=1),'Model inputs'!B8=1,IF('Model inputs'!B8="","",'Model inputs'!B8=1))="",'Model inputs'!B386="",'Model inputs'!B387=""),"",AND(IF(ISERROR('Model inputs'!B8=1),'Model inputs'!B8=1,IF('Model inputs'!B8="","",'Model inputs'!B8=1)),'Model inputs'!B386,'Model inputs'!B387)))))="",FALSE,IF(IFERROR(IF(ISERROR('Model inputs'!B8=1),'Model inputs'!B8=1,IF('Model inputs'!B8="","",'Model inputs'!B8=1))=FALSE,FALSE),FALSE,IF(IFERROR('Model inputs'!B386=FALSE,FALSE),FALSE,IF(IFERROR('Model inputs'!B387=FALSE,FALSE),FALSE,IF(OR(IF(ISERROR('Model inputs'!B8=1),'Model inputs'!B8=1,IF('Model inputs'!B8="","",'Model inputs'!B8=1))="",'Model inputs'!B386="",'Model inputs'!B387=""),"",AND(IF(ISERROR('Model inputs'!B8=1),'Model inputs'!B8=1,IF('Model inputs'!B8="","",'Model inputs'!B8=1)),'Model inputs'!B386,'Model inputs'!B387)))))),IF('Model inputs'!B6="","",'Model inputs'!B6),0) -> 0 | Q20: =IF(IF(IF(IFERROR(IF(ISERROR('Model inputs'!B8=1),'Model inputs'!B8=1,IF('Model inputs'!B8="","",'Model inputs'!B8=1))=FALSE,FALSE),FALSE,IF(IFERROR('Model inputs'!B388=FALSE,FALSE),FALSE,IF(IFERROR('Model inputs'!B389=FALSE,FALSE),FALSE,IF(OR(IF(ISERROR('Model inputs'!B8=1),'Model inputs'!B8=1,IF('Model inputs'!B8="","",'Model inputs'!B8=1))="",'Model inputs'!B388="",'Model inputs'!B389=""),"",AND(IF(ISERROR('Model inputs'!B8=1),'Model inputs'!B8=1,IF('Model inputs'!B8="","",'Model inputs'!B8=1)),'Model inputs'!B388,'Model inputs'!B389)))))="",FALSE,IF(IFERROR(IF(ISERROR('Model inputs'!B8=1),'Model inputs'!B8=1,IF('Model inputs'!B8="","",'Model inputs'!B8=1))=FALSE,FALSE),FALSE,IF(IFERROR('Model inputs'!B388=FALSE,FALSE),FALSE,IF(IFERROR('Model inputs'!B389=FALSE,FALSE),FALSE,IF(OR(IF(ISERROR('Model inputs'!B8=1),'Model inputs'!B8=1,IF('Model inputs'!B8="","",'Model inputs'!B8=1))="",'Model inputs'!B388="",'Model inputs'!B389=""),"",AND(IF(ISERROR('Model inputs'!B8=1),'Model inputs'!B8=1,IF('Model inputs'!B8="","",'Model inputs'!B8=1)),'Model inputs'!B388,'Model inputs'!B389)))))),IF('Model inputs'!B6="","",'Model inputs'!B6),0) -> 0 | R20: =IF(IF(IF(IFERROR(IF(ISERROR('Model inputs'!B8=1),'Model inputs'!B8=1,IF('Model inputs'!B8="","",'Model inputs'!B8=1))=FALSE,FALSE),FALSE,IF(IFERROR('Model inputs'!B390=FALSE,FALSE),FALSE,IF(IFERROR('Model inputs'!B391=FALSE,FALSE),FALSE,IF(OR(IF(ISERROR('Model inputs'!B8=1),'Model inputs'!B8=1,IF('Model inputs'!B8="","",'Model inputs'!B8=1))="",'Model inputs'!B390="",'Model inputs'!B391=""),"",AND(IF(ISERROR('Model inputs'!B8=1),'Model inputs'!B8=1,IF('Model inputs'!B8="","",'Model inputs'!B8=1)),'Model inputs'!B390,'Model inputs'!B391)))))="",FALSE,IF(IFERROR(IF(ISERROR('Model inputs'!B8=1),'Model inputs'!B8=1,IF('Model inputs'!B8="","",'Model inputs'!B8=1))=FALSE,FALSE),FALSE,IF(IFERROR('Model inputs'!B390=FALSE,FALSE),FALSE,IF(IFERROR('Model inputs'!B391=FALSE,FALSE),FALSE,IF(OR(IF(ISERROR('Model inputs'!B8=1),'Model inputs'!B8=1,IF('Model inputs'!B8="","",'Model inputs'!B8=1))="",'Model inputs'!B390="",'Model inputs'!B391=""),"",AND(IF(ISERROR('Model inputs'!B8=1),'Model inputs'!B8=1,IF('Model inputs'!B8="","",'Model inputs'!B8=1)),'Model inputs'!B390,'Model inputs'!B391)))))),IF('Model inputs'!B6="","",'Model inputs'!B6),0) -> 0 | S20: =IF(IF(IF(IFERROR(IF(ISERROR('Model inputs'!B8=1),'Model inputs'!B8=1,IF('Model inputs'!B8="","",'Model inputs'!B8=1))=FALSE,FALSE),FALSE,IF(IFERROR('Model inputs'!B392=FALSE,FALSE),FALSE,IF(IFERROR('Model inputs'!B393=FALSE,FALSE),FALSE,IF(OR(IF(ISERROR('Model inputs'!B8=1),'Model inputs'!B8=1,IF('Model inputs'!B8="","",'Model inputs'!B8=1))="",'Model inputs'!B392="",'Model inputs'!B393=""),"",AND(IF(ISERROR('Model inputs'!B8=1),'Model inputs'!B8=1,IF('Model inputs'!B8="","",'Model inputs'!B8=1)),'Model inputs'!B392,'Model inputs'!B393)))))="",FALSE,IF(IFERROR(IF(ISERROR('Model inputs'!B8=1),'Model inputs'!B8=1,IF('Model inputs'!B8="","",'Model inputs'!B8=1))=FALSE,FALSE),FALSE,IF(IFERROR('Model inputs'!B392=FALSE,FALSE),FALSE,IF(IFERROR('Model inputs'!B393=FALSE,FALSE),FALSE,IF(OR(IF(ISERROR('Model inputs'!B8=1),'Model inputs'!B8=1,IF('Model inputs'!B8="","",'Model inputs'!B8=1))="",'Model inputs'!B392="",'Model inputs'!B393=""),"",AND(IF(ISERROR('Model inputs'!B8=1),'Model inputs'!B8=1,IF('Model inputs'!B8="","",'Model inputs'!B8=1)),'Model inputs'!B392,'Model inputs'!B393)))))),IF('Model inputs'!B6="","",'Model inputs'!B6),0) -> 0
A21: Net cash change | B21: ='RC P&L, cash & runway'!B18-'RC P&L, cash & runway'!B9-'RC P&L, cash & runway'!B12-'RC P&L, cash & runway'!B19+'RC P&L, cash & runway'!B20 -> -6963.3727 | C21: ='RC P&L, cash & runway'!C18-'RC P&L, cash & runway'!C9-'RC P&L, cash & runway'!C12-'RC P&L, cash & runway'!C19+'RC P&L, cash & runway'!C20 -> -129.79946 | D21: ='RC P&L, cash & runway'!D18-'RC P&L, cash & runway'!D9-'RC P&L, cash & runway'!D12-'RC P&L, cash & runway'!D19+'RC P&L, cash & runway'!D20 -> 1907.1256 | E21: ='RC P&L, cash & runway'!E18-'RC P&L, cash & runway'!E9-'RC P&L, cash & runway'!E12-'RC P&L, cash & runway'!E19+'RC P&L, cash & runway'!E20 -> 2387.4703 | F21: ='RC P&L, cash & runway'!F18-'RC P&L, cash & runway'!F9-'RC P&L, cash & runway'!F12-'RC P&L, cash & runway'!F19+'RC P&L, cash & runway'!F20 -> 4421.2451 | G21: ='RC P&L, cash & runway'!G18-'RC P&L, cash & runway'!G9-'RC P&L, cash & runway'!G12-'RC P&L, cash & runway'!G19+'RC P&L, cash & runway'!G20 -> 6769.7302 | H21: ='RC P&L, cash & runway'!H18-'RC P&L, cash & runway'!H9-'RC P&L, cash & runway'!H12-'RC P&L, cash & runway'!H19+'RC P&L, cash & runway'!H20 -> 5245.5654 | I21: ='RC P&L, cash & runway'!I18-'RC P&L, cash & runway'!I9-'RC P&L, cash & runway'!I12-'RC P&L, cash & runway'!I19+'RC P&L, cash & runway'!I20 -> 3932.0992 | ... S21: ='RC P&L, cash & runway'!S18-'RC P&L, cash & runway'!S9-'RC P&L, cash & runway'!S12-'RC P&L, cash & runway'!S19+'RC P&L, cash & runway'!S20 -> 26973.67
A22: Cash on hand | B22: =IF(IF(IF(ISERROR('Model inputs'!E32=0),'Model inputs'!E32=0,IF('Model inputs'!E32="","",'Model inputs'!E32=0))="",FALSE,IF(ISERROR('Model inputs'!E32=0),'Model inputs'!E32=0,IF('Model inputs'!E32="","",'Model inputs'!E32=0))),'Model inputs'!B67+'RC P&L, cash & runway'!B21,'Model inputs'!D14+'RC P&L, cash & runway'!B21) -> 5036.6273 | C22: =IF(IF(IF(ISERROR('Model inputs'!F32=0),'Model inputs'!F32=0,IF('Model inputs'!F32="","",'Model inputs'!F32=0))="",FALSE,IF(ISERROR('Model inputs'!F32=0),'Model inputs'!F32=0,IF('Model inputs'!F32="","",'Model inputs'!F32=0))),'Model inputs'!B67+'RC P&L, cash & runway'!C21,'RC P&L, cash & runway'!B22+'RC P&L, cash & runway'!C21) -> 4906.8278 | D22: =IF(IF(IF(ISERROR('Model inputs'!G32=0),'Model inputs'!G32=0,IF('Model inputs'!G32="","",'Model inputs'!G32=0))="",FALSE,IF(ISERROR('Model inputs'!G32=0),'Model inputs'!G32=0,IF('Model inputs'!G32="","",'Model inputs'!G32=0))),'Model inputs'!B67+'RC P&L, cash & runway'!D21,'RC P&L, cash & runway'!C22+'RC P&L, cash & runway'!D21) -> 6813.9534 | E22: =IF(IF(IF(ISERROR('Model inputs'!H32=0),'Model inputs'!H32=0,IF('Model inputs'!H32="","",'Model inputs'!H32=0))="",FALSE,IF(ISERROR('Model inputs'!H32=0),'Model inputs'!H32=0,IF('Model inputs'!H32="","",'Model inputs'!H32=0))),'Model inputs'!B67+'RC P&L, cash & runway'!E21,'RC P&L, cash & runway'!D22+'RC P&L, cash & runway'!E21) -> 9201.4237 | F22: =IF(IF(IF(ISERROR('Model inputs'!I32=0),'Model inputs'!I32=0,IF('Model inputs'!I32="","",'Model inputs'!I32=0))="",FALSE,IF(ISERROR('Model inputs'!I32=0),'Model inputs'!I32=0,IF('Model inputs'!I32="","",'Model inputs'!I32=0))),'Model inputs'!B67+'RC P&L, cash & runway'!F21,'RC P&L, cash & runway'!E22+'RC P&L, cash & runway'!F21) -> 13622.669 | G22: =IF(IF(IF(ISERROR('Model inputs'!J32=0),'Model inputs'!J32=0,IF('Model inputs'!J32="","",'Model inputs'!J32=0))="",FALSE,IF(ISERROR('Model inputs'!J32=0),'Model inputs'!J32=0,IF('Model inputs'!J32="","",'Model inputs'!J32=0))),'Model inputs'!B67+'RC P&L, cash & runway'!G21,'RC P&L, cash & runway'!F22+'RC P&L, cash & runway'!G21) -> 20392.399 | H22: =IF(IF(IF(ISERROR('Model inputs'!K32=0),'Model inputs'!K32=0,IF('Model inputs'!K32="","",'Model inputs'!K32=0))="",FALSE,IF(ISERROR('Model inputs'!K32=0),'Model inputs'!K32=0,IF('Model inputs'!K32="","",'Model inputs'!K32=0))),'Model inputs'!B67+'RC P&L, cash & runway'!H21,'RC P&L, cash & runway'!G22+'RC P&L, cash & runway'!H21) -> 25637.964 | I22: =IF(IF(IF(ISERROR('Model inputs'!L32=0),'Model inputs'!L32=0,IF('Model inputs'!L32="","",'Model inputs'!L32=0))="",FALSE,IF(ISERROR('Model inputs'!L32=0),'Model inputs'!L32=0,IF('Model inputs'!L32="","",'Model inputs'!L32=0))),'Model inputs'!B67+'RC P&L, cash & runway'!I21,'RC P&L, cash & runway'!H22+'RC P&L, cash & runway'!I21) -> 29570.064 | J22: =IF(IF(IF(ISERROR('Model inputs'!M32=0),'Model inputs'!M32=0,IF('Model inputs'!M32="","",'Model inputs'!M32=0))="",FALSE,IF(ISERROR('Model inputs'!M32=0),'Model inputs'!M32=0,IF('Model inputs'!M32="","",'Model inputs'!M32=0))),'Model inputs'!B67+'RC P&L, cash & runway'!J21,'RC P&L, cash & runway'!I22+'RC P&L, cash & runway'!J21) -> 35383.167 | K22: =IF(IF(IF(ISERROR('Model inputs'!N32=0),'Model inputs'!N32=0,IF('Model inputs'!N32="","",'Model inputs'!N32=0))="",FALSE,IF(ISERROR('Model inputs'!N32=0),'Model inputs'!N32=0,IF('Model inputs'!N32="","",'Model inputs'!N32=0))),'Model inputs'!B67+'RC P&L, cash & runway'!K21,'RC P&L, cash & runway'!J22+'RC P&L, cash & runway'!K21) -> 42953.427 | L22: =IF(IF(IF(ISERROR('Model inputs'!O32=0),'Model inputs'!O32=0,IF('Model inputs'!O32="","",'Model inputs'!O32=0))="",FALSE,IF(ISERROR('Model inputs'!O32=0),'Model inputs'!O32=0,IF('Model inputs'!O32="","",'Model inputs'!O32=0))),'Model inputs'!B67+'RC P&L, cash & runway'!L21,'RC P&L, cash & runway'!K22+'RC P&L, cash & runway'!L21) -> 52308.118 | M22: =IF(IF(IF(ISERROR('Model inputs'!P32=0),'Model inputs'!P32=0,IF('Model inputs'!P32="","",'Model inputs'!P32=0))="",FALSE,IF(ISERROR('Model inputs'!P32=0),'Model inputs'!P32=0,IF('Model inputs'!P32="","",'Model inputs'!P32=0))),'Model inputs'!B67+'RC P&L, cash & runway'!M21,'RC P&L, cash & runway'!L22+'RC P&L, cash & runway'!M21) -> 63477.448 | N22: =IF(IF(IF(ISERROR('Model inputs'!Q32=0),'Model inputs'!Q32=0,IF('Model inputs'!Q32="","",'Model inputs'!Q32=0))="",FALSE,IF(ISERROR('Model inputs'!Q32=0),'Model inputs'!Q32=0,IF('Model inputs'!Q32="","",'Model inputs'!Q32=0))),'Model inputs'!B67+'RC P&L, cash & runway'!N21,'RC P&L, cash & runway'!M22+'RC P&L, cash & runway'!N21) -> 71994.571 | O22: =IF(IF(IF(ISERROR('Model inputs'!R32=0),'Model inputs'!R32=0,IF('Model inputs'!R32="","",'Model inputs'!R32=0))="",FALSE,IF(ISERROR('Model inputs'!R32=0),'Model inputs'!R32=0,IF('Model inputs'!R32="","",'Model inputs'!R32=0))),'Model inputs'!B67+'RC P&L, cash & runway'!O21,'RC P&L, cash & runway'!N22+'RC P&L, cash & runway'!O21) -> 87782.111 | P22: =IF(IF(IF(ISERROR('Model inputs'!S32=0),'Model inputs'!S32=0,IF('Model inputs'!S32="","",'Model inputs'!S32=0))="",FALSE,IF(ISERROR('Model inputs'!S32=0),'Model inputs'!S32=0,IF('Model inputs'!S32="","",'Model inputs'!S32=0))),'Model inputs'!B67+'RC P&L, cash & runway'!P21,'RC P&L, cash & runway'!O22+'RC P&L, cash & runway'!P21) -> 106165 | Q22: =IF(IF(IF(ISERROR('Model inputs'!T32=0),'Model inputs'!T32=0,IF('Model inputs'!T32="","",'Model inputs'!T32=0))="",FALSE,IF(ISERROR('Model inputs'!T32=0),'Model inputs'!T32=0,IF('Model inputs'!T32="","",'Model inputs'!T32=0))),'Model inputs'!B67+'RC P&L, cash & runway'!Q21,'RC P&L, cash & runway'!P22+'RC P&L, cash & runway'!Q21) -> 127268.95 | R22: =IF(IF(IF(ISERROR('Model inputs'!U32=0),'Model inputs'!U32=0,IF('Model inputs'!U32="","",'Model inputs'!U32=0))="",FALSE,IF(ISERROR('Model inputs'!U32=0),'Model inputs'!U32=0,IF('Model inputs'!U32="","",'Model inputs'!U32=0))),'Model inputs'!B67+'RC P&L, cash & runway'!R21,'RC P&L, cash & runway'!Q22+'RC P&L, cash & runway'!R21) -> 151231.95 | S22: =IF(IF(IF(ISERROR('Model inputs'!V32=0),'Model inputs'!V32=0,IF('Model inputs'!V32="","",'Model inputs'!V32=0))="",FALSE,IF(ISERROR('Model inputs'!V32=0),'Model inputs'!V32=0,IF('Model inputs'!V32="","",'Model inputs'!V32=0))),'Model inputs'!B67+'RC P&L, cash & runway'!S21,'RC P&L, cash & runway'!R22+'RC P&L, cash & runway'!S21) -> 178205.62
A23: Net burn | B23: =MAX('RC P&L, cash & runway'!B20-'RC P&L, cash & runway'!B21,0) -> 6963.3727 | C23: =MAX('RC P&L, cash & runway'!C20-'RC P&L, cash & runway'!C21,0) -> 129.79946 | D23: =MAX('RC P&L, cash & runway'!D20-'RC P&L, cash & runway'!D21,0) -> 0 | E23: =MAX('RC P&L, cash & runway'!E20-'RC P&L, cash & runway'!E21,0) -> 0 | F23: =MAX('RC P&L, cash & runway'!F20-'RC P&L, cash & runway'!F21,0) -> 0 | G23: =MAX('RC P&L, cash & runway'!G20-'RC P&L, cash & runway'!G21,0) -> 0 | H23: =MAX('RC P&L, cash & runway'!H20-'RC P&L, cash & runway'!H21,0) -> 0 | I23: =MAX('RC P&L, cash & runway'!I20-'RC P&L, cash & runway'!I21,0) -> 0 | ... S23: =MAX('RC P&L, cash & runway'!S20-'RC P&L, cash & runway'!S21,0) -> 0
A24: Runway (months) | B24: =IFERROR(IF(IF(IF(ISERROR('RC P&L, cash & runway'!B22<=0),'RC P&L, cash & runway'!B22<=0,IF('RC P&L, cash & runway'!B22="","",'RC P&L, cash & runway'!B22<=0))="",FALSE,IF(ISERROR('RC P&L, cash & runway'!B22<=0),'RC P&L, cash & runway'!B22<=0,IF('RC P&L, cash & runway'!B22="","",'RC P&L, cash & runway'!B22<=0))),0,IF(IF(IF(ISERROR('RC P&L, cash & runway'!B23>0),'RC P&L, cash & runway'!B23>0,IF('RC P&L, cash & runway'!B23="","",'RC P&L, cash & runway'!B23>0))="",FALSE,IF(ISERROR('RC P&L, cash & runway'!B23>0),'RC P&L, cash & runway'!B23>0,IF('RC P&L, cash & runway'!B23="","",'RC P&L, cash & runway'!B23>0))),'RC P&L, cash & runway'!B22/'RC P&L, cash & runway'!B23,"")),"") -> 0.72330284 | C24: =IFERROR(IF(IF(IF(ISERROR('RC P&L, cash & runway'!C22<=0),'RC P&L, cash & runway'!C22<=0,IF('RC P&L, cash & runway'!C22="","",'RC P&L, cash & runway'!C22<=0))="",FALSE,IF(ISERROR('RC P&L, cash & runway'!C22<=0),'RC P&L, cash & runway'!C22<=0,IF('RC P&L, cash & runway'!C22="","",'RC P&L, cash & runway'!C22<=0))),0,IF(IF(IF(ISERROR('RC P&L, cash & runway'!C23>0),'RC P&L, cash & runway'!C23>0,IF('RC P&L, cash & runway'!C23="","",'RC P&L, cash & runway'!C23>0))="",FALSE,IF(ISERROR('RC P&L, cash & runway'!C23>0),'RC P&L, cash & runway'!C23>0,IF('RC P&L, cash & runway'!C23="","",'RC P&L, cash & runway'!C23>0))),'RC P&L, cash & runway'!C22/'RC P&L, cash & runway'!C23,"")),"") -> 37.803147 | D24: =IFERROR(IF(IF(IF(ISERROR('RC P&L, cash & runway'!D22<=0),'RC P&L, cash & runway'!D22<=0,IF('RC P&L, cash & runway'!D22="","",'RC P&L, cash & runway'!D22<=0))="",FALSE,IF(ISERROR('RC P&L, cash & runway'!D22<=0),'RC P&L, cash & runway'!D22<=0,IF('RC P&L, cash & runway'!D22="","",'RC P&L, cash & runway'!D22<=0))),0,IF(IF(IF(ISERROR('RC P&L, cash & runway'!D23>0),'RC P&L, cash & runway'!D23>0,IF('RC P&L, cash & runway'!D23="","",'RC P&L, cash & runway'!D23>0))="",FALSE,IF(ISERROR('RC P&L, cash & runway'!D23>0),'RC P&L, cash & runway'!D23>0,IF('RC P&L, cash & runway'!D23="","",'RC P&L, cash & runway'!D23>0))),'RC P&L, cash & runway'!D22/'RC P&L, cash & runway'!D23,"")),"") | E24: =IFERROR(IF(IF(IF(ISERROR('RC P&L, cash & runway'!E22<=0),'RC P&L, cash & runway'!E22<=0,IF('RC P&L, cash & runway'!E22="","",'RC P&L, cash & runway'!E22<=0))="",FALSE,IF(ISERROR('RC P&L, cash & runway'!E22<=0),'RC P&L, cash & runway'!E22<=0,IF('RC P&L, cash & runway'!E22="","",'RC P&L, cash & runway'!E22<=0))),0,IF(IF(IF(ISERROR('RC P&L, cash & runway'!E23>0),'RC P&L, cash & runway'!E23>0,IF('RC P&L, cash & runway'!E23="","",'RC P&L, cash & runway'!E23>0))="",FALSE,IF(ISERROR('RC P&L, cash & runway'!E23>0),'RC P&L, cash & runway'!E23>0,IF('RC P&L, cash & runway'!E23="","",'RC P&L, cash & runway'!E23>0))),'RC P&L, cash & runway'!E22/'RC P&L, cash & runway'!E23,"")),"") | F24: =IFERROR(IF(IF(IF(ISERROR('RC P&L, cash & runway'!F22<=0),'RC P&L, cash & runway'!F22<=0,IF('RC P&L, cash & runway'!F22="","",'RC P&L, cash & runway'!F22<=0))="",FALSE,IF(ISERROR('RC P&L, cash & runway'!F22<=0),'RC P&L, cash & runway'!F22<=0,IF('RC P&L, cash & runway'!F22="","",'RC P&L, cash & runway'!F22<=0))),0,IF(IF(IF(ISERROR('RC P&L, cash & runway'!F23>0),'RC P&L, cash & runway'!F23>0,IF('RC P&L, cash & runway'!F23="","",'RC P&L, cash & runway'!F23>0))="",FALSE,IF(ISERROR('RC P&L, cash & runway'!F23>0),'RC P&L, cash & runway'!F23>0,IF('RC P&L, cash & runway'!F23="","",'RC P&L, cash & runway'!F23>0))),'RC P&L, cash & runway'!F22/'RC P&L, cash & runway'!F23,"")),"") | G24: =IFERROR(IF(IF(IF(ISERROR('RC P&L, cash & runway'!G22<=0),'RC P&L, cash & runway'!G22<=0,IF('RC P&L, cash & runway'!G22="","",'RC P&L, cash & runway'!G22<=0))="",FALSE,IF(ISERROR('RC P&L, cash & runway'!G22<=0),'RC P&L, cash & runway'!G22<=0,IF('RC P&L, cash & runway'!G22="","",'RC P&L, cash & runway'!G22<=0))),0,IF(IF(IF(ISERROR('RC P&L, cash & runway'!G23>0),'RC P&L, cash & runway'!G23>0,IF('RC P&L, cash & runway'!G23="","",'RC P&L, cash & runway'!G23>0))="",FALSE,IF(ISERROR('RC P&L, cash & runway'!G23>0),'RC P&L, cash & runway'!G23>0,IF('RC P&L, cash & runway'!G23="","",'RC P&L, cash & runway'!G23>0))),'RC P&L, cash & runway'!G22/'RC P&L, cash & runway'!G23,"")),"") | H24: =IFERROR(IF(IF(IF(ISERROR('RC P&L, cash & runway'!H22<=0),'RC P&L, cash & runway'!H22<=0,IF('RC P&L, cash & runway'!H22="","",'RC P&L, cash & runway'!H22<=0))="",FALSE,IF(ISERROR('RC P&L, cash & runway'!H22<=0),'RC P&L, cash & runway'!H22<=0,IF('RC P&L, cash & runway'!H22="","",'RC P&L, cash & runway'!H22<=0))),0,IF(IF(IF(ISERROR('RC P&L, cash & runway'!H23>0),'RC P&L, cash & runway'!H23>0,IF('RC P&L, cash & runway'!H23="","",'RC P&L, cash & runway'!H23>0))="",FALSE,IF(ISERROR('RC P&L, cash & runway'!H23>0),'RC P&L, cash & runway'!H23>0,IF('RC P&L, cash & runway'!H23="","",'RC P&L, cash & runway'!H23>0))),'RC P&L, cash & runway'!H22/'RC P&L, cash & runway'!H23,"")),"") | I24: =IFERROR(IF(IF(IF(ISERROR('RC P&L, cash & runway'!I22<=0),'RC P&L, cash & runway'!I22<=0,IF('RC P&L, cash & runway'!I22="","",'RC P&L, cash & runway'!I22<=0))="",FALSE,IF(ISERROR('RC P&L, cash & runway'!I22<=0),'RC P&L, cash & runway'!I22<=0,IF('RC P&L, cash & runway'!I22="","",'RC P&L, cash & runway'!I22<=0))),0,IF(IF(IF(ISERROR('RC P&L, cash & runway'!I23>0),'RC P&L, cash & runway'!I23>0,IF('RC P&L, cash & runway'!I23="","",'RC P&L, cash & runway'!I23>0))="",FALSE,IF(ISERROR('RC P&L, cash & runway'!I23>0),'RC P&L, cash & runway'!I23>0,IF('RC P&L, cash & runway'!I23="","",'RC P&L, cash & runway'!I23>0))),'RC P&L, cash & runway'!I22/'RC P&L, cash & runway'!I23,"")),"") | ... S24: =IFERROR(IF(IF(IF(ISERROR('RC P&L, cash & runway'!S22<=0),'RC P&L, cash & runway'!S22<=0,IF('RC P&L, cash & runway'!S22="","",'RC P&L, cash & runway'!S22<=0))="",FALSE,IF(ISERROR('RC P&L, cash & runway'!S22<=0),'RC P&L, cash & runway'!S22<=0,IF('RC P&L, cash & runway'!S22="","",'RC P&L, cash & runway'!S22<=0))),0,IF(IF(IF(ISERROR('RC P&L, cash & runway'!S23>0),'RC P&L, cash & runway'!S23>0,IF('RC P&L, cash & runway'!S23="","",'RC P&L, cash & runway'!S23>0))="",FALSE,IF(ISERROR('RC P&L, cash & runway'!S23>0),'RC P&L, cash & runway'!S23>0,IF('RC P&L, cash & runway'!S23="","",'RC P&L, cash & runway'!S23>0))),'RC P&L, cash & runway'!S22/'RC P&L, cash & runway'!S23,"")),"")
A25: Months of opex in cash | B25: =IFERROR('RC P&L, cash & runway'!B22/'RC P&L, cash & runway'!B15,"") -> 0.96027212 | C25: =IFERROR('RC P&L, cash & runway'!C22/'RC P&L, cash & runway'!C15,"") -> 0.87700229 | D25: =IFERROR('RC P&L, cash & runway'!D22/'RC P&L, cash & runway'!D15,"") -> 1.2178648 | E25: =IFERROR('RC P&L, cash & runway'!E22/'RC P&L, cash & runway'!E15,"") -> 1.2700378 | F25: =IFERROR('RC P&L, cash & runway'!F22/'RC P&L, cash & runway'!F15,"") -> 1.8297742 | G25: =IFERROR('RC P&L, cash & runway'!G22/'RC P&L, cash & runway'!G15,"") -> 2.7390731 | H25: =IFERROR('RC P&L, cash & runway'!H22/'RC P&L, cash & runway'!H15,"") -> 2.2401017 | I25: =IFERROR('RC P&L, cash & runway'!I22/'RC P&L, cash & runway'!I15,"") -> 2.5836665 | ... S25: =IFERROR('RC P&L, cash & runway'!S22/'RC P&L, cash & runway'!S15,"") -> 15.570609
