Workbook

Sheet RC Unit economics
A1: RC Unit economics
A2: RC Unit economics · Main Scenario
A4: Variable / dimension | B4: 2026-11 | C4: 2026-12 | D4: 2027-01 | E4: 2027-02 | F4: 2027-03 | G4: 2027-04 | H4: 2027-05 | I4: 2027-06 | J4: 2027-07 | K4: 2027-08 | L4: 2027-09 | M4: 2027-10 | N4: 2027-11 | O4: 2027-12 | P4: 2028-01 | Q4: 2028-02 | R4: 2028-03 | S4: 2028-04
A5: Ending customers | B5: =SUM('RC Unit economics'!B6,'RC Unit economics'!B7,'RC Unit economics'!B8) -> 47 | C5: =SUM('RC Unit economics'!C6,'RC Unit economics'!C7,'RC Unit economics'!C8) -> 84.905 | D5: =SUM('RC Unit economics'!D6,'RC Unit economics'!D7,'RC Unit economics'!D8) -> 110.9505 | E5: =SUM('RC Unit economics'!E6,'RC Unit economics'!E7,'RC Unit economics'!E8) -> 138.05103 | F5: =SUM('RC Unit economics'!F6,'RC Unit economics'!F7,'RC Unit economics'!F8) -> 166.36012 | G5: =SUM('RC Unit economics'!G6,'RC Unit economics'!G7,'RC Unit economics'!G8) -> 196.04007 | H5: =SUM('RC Unit economics'!H6,'RC Unit economics'!H7,'RC Unit economics'!H8) -> 227.26287 | I5: =SUM('RC Unit economics'!I6,'RC Unit economics'!I7,'RC Unit economics'!I8) -> 260.21141 | ... S5: =SUM('RC Unit economics'!S6,'RC Unit economics'!S7,'RC Unit economics'!S8) -> 621.23762
A6: Indie | B6: ='Model inputs'!C43+'Model inputs'!C48+'Model inputs'!C68+'Model inputs'!C60-'Model inputs'!C11-'Model inputs'!C64 -> 40 | C6: ='Model inputs'!D43+'Model inputs'!D48+'Model inputs'!D68+'Model inputs'!D60-'Model inputs'!D11-'Model inputs'!D64 -> 74.333333 | D6: ='Model inputs'!E43+'Model inputs'!E48+'Model inputs'!E68+'Model inputs'!E60-'Model inputs'!E11-'Model inputs'!E64 -> 96.377778 | E6: ='Model inputs'!F43+'Model inputs'!F48+'Model inputs'!F68+'Model inputs'!F60-'Model inputs'!F11-'Model inputs'!F64 -> 119.11259 | F6: ='Model inputs'!G43+'Model inputs'!G48+'Model inputs'!G68+'Model inputs'!G60-'Model inputs'!G11-'Model inputs'!G64 -> 142.66455 | G6: ='Model inputs'!H43+'Model inputs'!H48+'Model inputs'!H68+'Model inputs'!H60-'Model inputs'!H11-'Model inputs'!H64 -> 167.16581 | H6: ='Model inputs'!I43+'Model inputs'!I48+'Model inputs'!I68+'Model inputs'!I60-'Model inputs'!I11-'Model inputs'!I64 -> 192.75462 | I6: ='Model inputs'!J43+'Model inputs'!J48+'Model inputs'!J68+'Model inputs'!J60-'Model inputs'!J11-'Model inputs'!J64 -> 219.57617 | ... S6: ='Model inputs'!T43+'Model inputs'!T48+'Model inputs'!T68+'Model inputs'!T60-'Model inputs'!T11-'Model inputs'!T64 -> 503.23671
A7: Launch | B7: ='Model inputs'!C44+'Model inputs'!C49+'Model inputs'!C69+'Model inputs'!C61-'Model inputs'!C12-'Model inputs'!C65 -> 1 | C7: ='Model inputs'!D44+'Model inputs'!D49+'Model inputs'!D69+'Model inputs'!D61-'Model inputs'!D12-'Model inputs'!D65 -> 1.51 | D7: ='Model inputs'!E44+'Model inputs'!E49+'Model inputs'!E69+'Model inputs'!E61-'Model inputs'!E12-'Model inputs'!E65 -> 2.0251069 | E7: ='Model inputs'!F44+'Model inputs'!F49+'Model inputs'!F69+'Model inputs'!F61-'Model inputs'!F12-'Model inputs'!F65 -> 2.5470121 | F7: ='Model inputs'!G44+'Model inputs'!G49+'Model inputs'!G69+'Model inputs'!G61-'Model inputs'!G12-'Model inputs'!G65 -> 3.0771045 | G7: ='Model inputs'!H44+'Model inputs'!H49+'Model inputs'!H69+'Model inputs'!H61-'Model inputs'!H12-'Model inputs'!H65 -> 3.6168582 | H7: ='Model inputs'!I44+'Model inputs'!I49+'Model inputs'!I69+'Model inputs'!I61-'Model inputs'!I12-'Model inputs'!I65 -> 4.1678445 | I7: ='Model inputs'!J44+'Model inputs'!J49+'Model inputs'!J69+'Model inputs'!J61-'Model inputs'!J12-'Model inputs'!J65 -> 4.7317452 | ... S7: ='Model inputs'!T44+'Model inputs'!T49+'Model inputs'!T69+'Model inputs'!T61-'Model inputs'!T12-'Model inputs'!T65 -> 11.344724
A8: Team | B8: ='Model inputs'!C45+'Model inputs'!C50+'Model inputs'!C70+'Model inputs'!C62-'Model inputs'!C13-'Model inputs'!C66 -> 6 | C8: ='Model inputs'!D45+'Model inputs'!D50+'Model inputs'!D70+'Model inputs'!D62-'Model inputs'!D13-'Model inputs'!D66 -> 9.0616667 | D8: ='Model inputs'!E45+'Model inputs'!E50+'Model inputs'!E70+'Model inputs'!E62-'Model inputs'!E13-'Model inputs'!E66 -> 12.547615 | E8: ='Model inputs'!F45+'Model inputs'!F50+'Model inputs'!F70+'Model inputs'!F62-'Model inputs'!F13-'Model inputs'!F66 -> 16.391424 | F8: ='Model inputs'!G45+'Model inputs'!G50+'Model inputs'!G70+'Model inputs'!G62-'Model inputs'!G13-'Model inputs'!G66 -> 20.618467 | G8: ='Model inputs'!H45+'Model inputs'!H50+'Model inputs'!H70+'Model inputs'!H62-'Model inputs'!H13-'Model inputs'!H66 -> 25.2574 | H8: ='Model inputs'!I45+'Model inputs'!I50+'Model inputs'!I70+'Model inputs'!I62-'Model inputs'!I13-'Model inputs'!I66 -> 30.340408 | I8: ='Model inputs'!J45+'Model inputs'!J50+'Model inputs'!J70+'Model inputs'!J62-'Model inputs'!J13-'Model inputs'!J66 -> 35.903491 | ... S8: ='Model inputs'!T45+'Model inputs'!T50+'Model inputs'!T70+'Model inputs'!T62-'Model inputs'!T13-'Model inputs'!T66 -> 106.65619
A9: ARPU | B9: =IFERROR('Model inputs'!C55/'RC Unit economics'!B5,"") -> 57.397447 | C9: =IFERROR('Model inputs'!D55/'RC Unit economics'!C5,"") -> 52.787175 | D9: =IFERROR('Model inputs'!E55/'RC Unit economics'!D5,"") -> 53.557491 | E9: =IFERROR('Model inputs'!F55/'RC Unit economics'!E5,"") -> 54.086867 | F9: =IFERROR('Model inputs'!G55/'RC Unit economics'!F5,"") -> 54.473564 | G9: =IFERROR('Model inputs'!H55/'RC Unit economics'!G5,"") -> 54.764216 | H9: =IFERROR('Model inputs'!I55/'RC Unit economics'!H5,"") -> 54.984229 | I9: =IFERROR('Model inputs'!J55/'RC Unit economics'!I5,"") -> 55.43706 | ... S9: =IFERROR('Model inputs'!T55/'RC Unit economics'!S5,"") -> 59.429028
A10: Indie | B10: =IFERROR('Model inputs'!C56/'RC Unit economics'!B6,"") -> 30.76 | C10: =IFERROR('Model inputs'!D56/'RC Unit economics'!C6,"") -> 30.76 | D10: =IFERROR('Model inputs'!E56/'RC Unit economics'!D6,"") -> 30.76 | E10: =IFERROR('Model inputs'!F56/'RC Unit economics'!E6,"") -> 30.76 | F10: =IFERROR('Model inputs'!G56/'RC Unit economics'!F6,"") -> 30.76 | G10: =IFERROR('Model inputs'!H56/'RC Unit economics'!G6,"") -> 30.76 | H10: =IFERROR('Model inputs'!I56/'RC Unit economics'!H6,"") -> 30.76 | I10: =IFERROR('Model inputs'!J56/'RC Unit economics'!I6,"") -> 30.76 | ... S10: =IFERROR('Model inputs'!T56/'RC Unit economics'!S6,"") -> 30.76
A11: Launch | B11: =IFERROR('Model inputs'!C57/'RC Unit economics'!B7,"") -> 526.36 | C11: =IFERROR('Model inputs'!D57/'RC Unit economics'!C7,"") -> 521.50861 | D11: =IFERROR('Model inputs'!E57/'RC Unit economics'!D7,"") -> 516.65722 | E11: =IFERROR('Model inputs'!F57/'RC Unit economics'!E7,"") -> 511.80583 | F11: =IFERROR('Model inputs'!G57/'RC Unit economics'!F7,"") -> 506.95444 | G11: =IFERROR('Model inputs'!H57/'RC Unit economics'!G7,"") -> 502.10306 | H11: =IFERROR('Model inputs'!I57/'RC Unit economics'!H7,"") -> 497.25167 | I11: =IFERROR('Model inputs'!J57/'RC Unit economics'!I7,"") -> 497.25167 | ... S11: =IFERROR('Model inputs'!T57/'RC Unit economics'!S7,"") -> 497.25167
A12: Team | B12: =IFERROR('Model inputs'!C58/'RC Unit economics'!B8,"") -> 156.82 | C12: =IFERROR('Model inputs'!D58/'RC Unit economics'!C8,"") -> 155.37139 | D12: =IFERROR('Model inputs'!E58/'RC Unit economics'!D8,"") -> 153.92278 | E12: =IFERROR('Model inputs'!F58/'RC Unit economics'!E8,"") -> 152.47417 | F12: =IFERROR('Model inputs'!G58/'RC Unit economics'!F8,"") -> 151.02556 | G12: =IFERROR('Model inputs'!H58/'RC Unit economics'!G8,"") -> 149.57694 | H12: =IFERROR('Model inputs'!I58/'RC Unit economics'!H8,"") -> 148.12833 | I12: =IFERROR('Model inputs'!J58/'RC Unit economics'!I8,"") -> 148.12833 | ... S12: =IFERROR('Model inputs'!T58/'RC Unit economics'!S8,"") -> 148.12833
A13: Kits per customer | B13: =IFERROR('Model inputs'!C20/'RC Unit economics'!B5,"") -> 17.617021 | C13: =IFERROR('Model inputs'!D20/'RC Unit economics'!C5,"") -> 16.121449 | D13: =IFERROR('Model inputs'!E20/'RC Unit economics'!D5,"") -> 16.458881 | E13: =IFERROR('Model inputs'!F20/'RC Unit economics'!E5,"") -> 16.715112 | F13: =IFERROR('Model inputs'!G20/'RC Unit economics'!F5,"") -> 16.92473 | G13: =IFERROR('Model inputs'!H20/'RC Unit economics'!G5,"") -> 17.104054 | H13: =IFERROR('Model inputs'!I20/'RC Unit economics'!H5,"") -> 17.261902 | I13: =IFERROR('Model inputs'!J20/'RC Unit economics'!I5,"") -> 17.403545 | ... S13: =IFERROR('Model inputs'!T20/'RC Unit economics'!S5,"") -> 18.716455
A14: Indie | B14: =IFERROR('Model inputs'!C21/'RC Unit economics'!B6,"") -> 8.5 | C14: =IFERROR('Model inputs'!D21/'RC Unit economics'!C6,"") -> 8.5 | D14: =IFERROR('Model inputs'!E21/'RC Unit economics'!D6,"") -> 8.5 | E14: =IFERROR('Model inputs'!F21/'RC Unit economics'!E6,"") -> 8.5 | F14: =IFERROR('Model inputs'!G21/'RC Unit economics'!F6,"") -> 8.5 | G14: =IFERROR('Model inputs'!H21/'RC Unit economics'!G6,"") -> 8.5 | H14: =IFERROR('Model inputs'!I21/'RC Unit economics'!H6,"") -> 8.5 | I14: =IFERROR('Model inputs'!J21/'RC Unit economics'!I6,"") -> 8.5 | ... S14: =IFERROR('Model inputs'!T21/'RC Unit economics'!S6,"") -> 8.5
A15: Launch | B15: =IFERROR('Model inputs'!C22/'RC Unit economics'!B7,"") -> 206 | C15: =IFERROR('Model inputs'!D22/'RC Unit economics'!C7,"") -> 206 | D15: =IFERROR('Model inputs'!E22/'RC Unit economics'!D7,"") -> 206 | E15: =IFERROR('Model inputs'!F22/'RC Unit economics'!E7,"") -> 206 | F15: =IFERROR('Model inputs'!G22/'RC Unit economics'!F7,"") -> 206 | G15: =IFERROR('Model inputs'!H22/'RC Unit economics'!G7,"") -> 206 | H15: =IFERROR('Model inputs'!I22/'RC Unit economics'!H7,"") -> 206 | I15: =IFERROR('Model inputs'!J22/'RC Unit economics'!I7,"") -> 206 | ... S15: =IFERROR('Model inputs'!T22/'RC Unit economics'!S7,"") -> 206
A16: Team | B16: =IFERROR('Model inputs'!C23/'RC Unit economics'!B8,"") -> 47 | C16: =IFERROR('Model inputs'!D23/'RC Unit economics'!C8,"") -> 47 | D16: =IFERROR('Model inputs'!E23/'RC Unit economics'!D8,"") -> 47 | E16: =IFERROR('Model inputs'!F23/'RC Unit economics'!E8,"") -> 47 | F16: =IFERROR('Model inputs'!G23/'RC Unit economics'!F8,"") -> 47 | G16: =IFERROR('Model inputs'!H23/'RC Unit economics'!G8,"") -> 47 | H16: =IFERROR('Model inputs'!I23/'RC Unit economics'!H8,"") -> 47 | I16: =IFERROR('Model inputs'!J23/'RC Unit economics'!I8,"") -> 47 | ... S16: =IFERROR('Model inputs'!T23/'RC Unit economics'!S8,"") -> 47
A17: COGS per kit | B17: =IF(IF(IF(IFERROR(IF(ISERROR('Model inputs'!B19=1),'Model inputs'!B19=1,IF('Model inputs'!B19="","",'Model inputs'!B19=1))=FALSE,FALSE),FALSE,IF(IFERROR('Model inputs'!B214=FALSE,FALSE),FALSE,IF(OR(IF(ISERROR('Model inputs'!B19=1),'Model inputs'!B19=1,IF('Model inputs'!B19="","",'Model inputs'!B19=1))="",'Model inputs'!B214=""),"",AND(IF(ISERROR('Model inputs'!B19=1),'Model inputs'!B19=1,IF('Model inputs'!B19="","",'Model inputs'!B19=1)),'Model inputs'!B214))))="",FALSE,IF(IFERROR(IF(ISERROR('Model inputs'!B19=1),'Model inputs'!B19=1,IF('Model inputs'!B19="","",'Model inputs'!B19=1))=FALSE,FALSE),FALSE,IF(IFERROR('Model inputs'!B214=FALSE,FALSE),FALSE,IF(OR(IF(ISERROR('Model inputs'!B19=1),'Model inputs'!B19=1,IF('Model inputs'!B19="","",'Model inputs'!B19=1))="",'Model inputs'!B214=""),"",AND(IF(ISERROR('Model inputs'!B19=1),'Model inputs'!B19=1,IF('Model inputs'!B19="","",'Model inputs'!B19=1)),'Model inputs'!B214))))),IF('Model inputs'!B46="","",'Model inputs'!B46),IF('Model inputs'!B36="","",'Model inputs'!B36)) -> 0.24 | C17: =IF(IF(IF(IFERROR(IF(ISERROR('Model inputs'!B19=1),'Model inputs'!B19=1,IF('Model inputs'!B19="","",'Model inputs'!B19=1))=FALSE,FALSE),FALSE,IF(IFERROR('Model inputs'!B215=FALSE,FALSE),FALSE,IF(OR(IF(ISERROR('Model inputs'!B19=1),'Model inputs'!B19=1,IF('Model inputs'!B19="","",'Model inputs'!B19=1))="",'Model inputs'!B215=""),"",AND(IF(ISERROR('Model inputs'!B19=1),'Model inputs'!B19=1,IF('Model inputs'!B19="","",'Model inputs'!B19=1)),'Model inputs'!B215))))="",FALSE,IF(IFERROR(IF(ISERROR('Model inputs'!B19=1),'Model inputs'!B19=1,IF('Model inputs'!B19="","",'Model inputs'!B19=1))=FALSE,FALSE),FALSE,IF(IFERROR('Model inputs'!B215=FALSE,FALSE),FALSE,IF(OR(IF(ISERROR('Model inputs'!B19=1),'Model inputs'!B19=1,IF('Model inputs'!B19="","",'Model inputs'!B19=1))="",'Model inputs'!B215=""),"",AND(IF(ISERROR('Model inputs'!B19=1),'Model inputs'!B19=1,IF('Model inputs'!B19="","",'Model inputs'!B19=1)),'Model inputs'!B215))))),IF('Model inputs'!B46="","",'Model inputs'!B46),IF('Model inputs'!B36="","",'Model inputs'!B36)) -> 0.24 | D17: =IF(IF(IF(IFERROR(IF(ISERROR('Model inputs'!B19=1),'Model inputs'!B19=1,IF('Model inputs'!B19="","",'Model inputs'!B19=1))=FALSE,FALSE),FALSE,IF(IFERROR('Model inputs'!B216=FALSE,FALSE),FALSE,IF(OR(IF(ISERROR('Model inputs'!B19=1),'Model inputs'!B19=1,IF('Model inputs'!B19="","",'Model inputs'!B19=1))="",'Model inputs'!B216=""),"",AND(IF(ISERROR('Model inputs'!B19=1),'Model inputs'!B19=1,IF('Model inputs'!B19="","",'Model inputs'!B19=1)),'Model inputs'!B216))))="",FALSE,IF(IFERROR(IF(ISERROR('Model inputs'!B19=1),'Model inputs'!B19=1,IF('Model inputs'!B19="","",'Model inputs'!B19=1))=FALSE,FALSE),FALSE,IF(IFERROR('Model inputs'!B216=FALSE,FALSE),FALSE,IF(OR(IF(ISERROR('Model inputs'!B19=1),'Model inputs'!B19=1,IF('Model inputs'!B19="","",'Model inputs'!B19=1))="",'Model inputs'!B216=""),"",AND(IF(ISERROR('Model inputs'!B19=1),'Model inputs'!B19=1,IF('Model inputs'!B19="","",'Model inputs'!B19=1)),'Model inputs'!B216))))),IF('Model inputs'!B46="","",'Model inputs'!B46),IF('Model inputs'!B36="","",'Model inputs'!B36)) -> 0.24 | E17: =IF(IF(IF(IFERROR(IF(ISERROR('Model inputs'!B19=1),'Model inputs'!B19=1,IF('Model inputs'!B19="","",'Model inputs'!B19=1))=FALSE,FALSE),FALSE,IF(IFERROR('Model inputs'!B217=FALSE,FALSE),FALSE,IF(OR(IF(ISERROR('Model inputs'!B19=1),'Model inputs'!B19=1,IF('Model inputs'!B19="","",'Model inputs'!B19=1))="",'Model inputs'!B217=""),"",AND(IF(ISERROR('Model inputs'!B19=1),'Model inputs'!B19=1,IF('Model inputs'!B19="","",'Model inputs'!B19=1)),'Model inputs'!B217))))="",FALSE,IF(IFERROR(IF(ISERROR('Model inputs'!B19=1),'Model inputs'!B19=1,IF('Model inputs'!B19="","",'Model inputs'!B19=1))=FALSE,FALSE),FALSE,IF(IFERROR('Model inputs'!B217=FALSE,FALSE),FALSE,IF(OR(IF(ISERROR('Model inputs'!B19=1),'Model inputs'!B19=1,IF('Model inputs'!B19="","",'Model inputs'!B19=1))="",'Model inputs'!B217=""),"",AND(IF(ISERROR('Model inputs'!B19=1),'Model inputs'!B19=1,IF('Model inputs'!B19="","",'Model inputs'!B19=1)),'Model inputs'!B217))))),IF('Model inputs'!B46="","",'Model inputs'!B46),IF('Model inputs'!B36="","",'Model inputs'!B36)) -> 0.24 | F17: =IF(IF(IF(IFERROR(IF(ISERROR('Model inputs'!B19=1),'Model inputs'!B19=1,IF('Model inputs'!B19="","",'Model inputs'!B19=1))=FALSE,FALSE),FALSE,IF(IFERROR('Model inputs'!B218=FALSE,FALSE),FALSE,IF(OR(IF(ISERROR('Model inputs'!B19=1),'Model inputs'!B19=1,IF('Model inputs'!B19="","",'Model inputs'!B19=1))="",'Model inputs'!B218=""),"",AND(IF(ISERROR('Model inputs'!B19=1),'Model inputs'!B19=1,IF('Model inputs'!B19="","",'Model inputs'!B19=1)),'Model inputs'!B218))))="",FALSE,IF(IFERROR(IF(ISERROR('Model inputs'!B19=1),'Model inputs'!B19=1,IF('Model inputs'!B19="","",'Model inputs'!B19=1))=FALSE,FALSE),FALSE,IF(IFERROR('Model inputs'!B218=FALSE,FALSE),FALSE,IF(OR(IF(ISERROR('Model inputs'!B19=1),'Model inputs'!B19=1,IF('Model inputs'!B19="","",'Model inputs'!B19=1))="",'Model inputs'!B218=""),"",AND(IF(ISERROR('Model inputs'!B19=1),'Model inputs'!B19=1,IF('Model inputs'!B19="","",'Model inputs'!B19=1)),'Model inputs'!B218))))),IF('Model inputs'!B46="","",'Model inputs'!B46),IF('Model inputs'!B36="","",'Model inputs'!B36)) -> 0.24 | G17: =IF(IF(IF(IFERROR(IF(ISERROR('Model inputs'!B19=1),'Model inputs'!B19=1,IF('Model inputs'!B19="","",'Model inputs'!B19=1))=FALSE,FALSE),FALSE,IF(IFERROR('Model inputs'!B219=FALSE,FALSE),FALSE,IF(OR(IF(ISERROR('Model inputs'!B19=1),'Model inputs'!B19=1,IF('Model inputs'!B19="","",'Model inputs'!B19=1))="",'Model inputs'!B219=""),"",AND(IF(ISERROR('Model inputs'!B19=1),'Model inputs'!B19=1,IF('Model inputs'!B19="","",'Model inputs'!B19=1)),'Model inputs'!B219))))="",FALSE,IF(IFERROR(IF(ISERROR('Model inputs'!B19=1),'Model inputs'!B19=1,IF('Model inputs'!B19="","",'Model inputs'!B19=1))=FALSE,FALSE),FALSE,IF(IFERROR('Model inputs'!B219=FALSE,FALSE),FALSE,IF(OR(IF(ISERROR('Model inputs'!B19=1),'Model inputs'!B19=1,IF('Model inputs'!B19="","",'Model inputs'!B19=1))="",'Model inputs'!B219=""),"",AND(IF(ISERROR('Model inputs'!B19=1),'Model inputs'!B19=1,IF('Model inputs'!B19="","",'Model inputs'!B19=1)),'Model inputs'!B219))))),IF('Model inputs'!B46="","",'Model inputs'!B46),IF('Model inputs'!B36="","",'Model inputs'!B36)) -> 0.24 | H17: =IF(IF(IF(IFERROR(IF(ISERROR('Model inputs'!B19=1),'Model inputs'!B19=1,IF('Model inputs'!B19="","",'Model inputs'!B19=1))=FALSE,FALSE),FALSE,IF(IFERROR('Model inputs'!B220=FALSE,FALSE),FALSE,IF(OR(IF(ISERROR('Model inputs'!B19=1),'Model inputs'!B19=1,IF('Model inputs'!B19="","",'Model inputs'!B19=1))="",'Model inputs'!B220=""),"",AND(IF(ISERROR('Model inputs'!B19=1),'Model inputs'!B19=1,IF('Model inputs'!B19="","",'Model inputs'!B19=1)),'Model inputs'!B220))))="",FALSE,IF(IFERROR(IF(ISERROR('Model inputs'!B19=1),'Model inputs'!B19=1,IF('Model inputs'!B19="","",'Model inputs'!B19=1))=FALSE,FALSE),FALSE,IF(IFERROR('Model inputs'!B220=FALSE,FALSE),FALSE,IF(OR(IF(ISERROR('Model inputs'!B19=1),'Model inputs'!B19=1,IF('Model inputs'!B19="","",'Model inputs'!B19=1))="",'Model inputs'!B220=""),"",AND(IF(ISERROR('Model inputs'!B19=1),'Model inputs'!B19=1,IF('Model inputs'!B19="","",'Model inputs'!B19=1)),'Model inputs'!B220))))),IF('Model inputs'!B46="","",'Model inputs'!B46),IF('Model inputs'!B36="","",'Model inputs'!B36)) -> 0.24 | I17: =IF(IF(IF(IFERROR(IF(ISERROR('Model inputs'!B19=1),'Model inputs'!B19=1,IF('Model inputs'!B19="","",'Model inputs'!B19=1))=FALSE,FALSE),FALSE,IF(IFERROR('Model inputs'!B221=FALSE,FALSE),FALSE,IF(OR(IF(ISERROR('Model inputs'!B19=1),'Model inputs'!B19=1,IF('Model inputs'!B19="","",'Model inputs'!B19=1))="",'Model inputs'!B221=""),"",AND(IF(ISERROR('Model inputs'!B19=1),'Model inputs'!B19=1,IF('Model inputs'!B19="","",'Model inputs'!B19=1)),'Model inputs'!B221))))="",FALSE,IF(IFERROR(IF(ISERROR('Model inputs'!B19=1),'Model inputs'!B19=1,IF('Model inputs'!B19="","",'Model inputs'!B19=1))=FALSE,FALSE),FALSE,IF(IFERROR('Model inputs'!B221=FALSE,FALSE),FALSE,IF(OR(IF(ISERROR('Model inputs'!B19=1),'Model inputs'!B19=1,IF('Model inputs'!B19="","",'Model inputs'!B19=1))="",'Model inputs'!B221=""),"",AND(IF(ISERROR('Model inputs'!B19=1),'Model inputs'!B19=1,IF('Model inputs'!B19="","",'Model inputs'!B19=1)),'Model inputs'!B221))))),IF('Model inputs'!B46="","",'Model inputs'!B46),IF('Model inputs'!B36="","",'Model inputs'!B36)) -> 0.24 | J17: =IF(IF(IF(IFERROR(IF(ISERROR('Model inputs'!B19=1),'Model inputs'!B19=1,IF('Model inputs'!B19="","",'Model inputs'!B19=1))=FALSE,FALSE),FALSE,IF(IFERROR('Model inputs'!B222=FALSE,FALSE),FALSE,IF(OR(IF(ISERROR('Model inputs'!B19=1),'Model inputs'!B19=1,IF('Model inputs'!B19="","",'Model inputs'!B19=1))="",'Model inputs'!B222=""),"",AND(IF(ISERROR('Model inputs'!B19=1),'Model inputs'!B19=1,IF('Model inputs'!B19="","",'Model inputs'!B19=1)),'Model inputs'!B222))))="",FALSE,IF(IFERROR(IF(ISERROR('Model inputs'!B19=1),'Model inputs'!B19=1,IF('Model inputs'!B19="","",'Model inputs'!B19=1))=FALSE,FALSE),FALSE,IF(IFERROR('Model inputs'!B222=FALSE,FALSE),FALSE,IF(OR(IF(ISERROR('Model inputs'!B19=1),'Model inputs'!B19=1,IF('Model inputs'!B19="","",'Model inputs'!B19=1))="",'Model inputs'!B222=""),"",AND(IF(ISERROR('Model inputs'!B19=1),'Model inputs'!B19=1,IF('Model inputs'!B19="","",'Model inputs'!B19=1)),'Model inputs'!B222))))),IF('Model inputs'!B46="","",'Model inputs'!B46),IF('Model inputs'!B36="","",'Model inputs'!B36)) -> 0.24 | K17: =IF(IF(IF(IFERROR(IF(ISERROR('Model inputs'!B19=1),'Model inputs'!B19=1,IF('Model inputs'!B19="","",'Model inputs'!B19=1))=FALSE,FALSE),FALSE,IF(IFERROR('Model inputs'!B223=FALSE,FALSE),FALSE,IF(OR(IF(ISERROR('Model inputs'!B19=1),'Model inputs'!B19=1,IF('Model inputs'!B19="","",'Model inputs'!B19=1))="",'Model inputs'!B223=""),"",AND(IF(ISERROR('Model inputs'!B19=1),'Model inputs'!B19=1,IF('Model inputs'!B19="","",'Model inputs'!B19=1)),'Model inputs'!B223))))="",FALSE,IF(IFERROR(IF(ISERROR('Model inputs'!B19=1),'Model inputs'!B19=1,IF('Model inputs'!B19="","",'Model inputs'!B19=1))=FALSE,FALSE),FALSE,IF(IFERROR('Model inputs'!B223=FALSE,FALSE),FALSE,IF(OR(IF(ISERROR('Model inputs'!B19=1),'Model inputs'!B19=1,IF('Model inputs'!B19="","",'Model inputs'!B19=1))="",'Model inputs'!B223=""),"",AND(IF(ISERROR('Model inputs'!B19=1),'Model inputs'!B19=1,IF('Model inputs'!B19="","",'Model inputs'!B19=1)),'Model inputs'!B223))))),IF('Model inputs'!B46="","",'Model inputs'!B46),IF('Model inputs'!B36="","",'Model inputs'!B36)) -> 0.24 | L17: =IF(IF(IF(IFERROR(IF(ISERROR('Model inputs'!B19=1),'Model inputs'!B19=1,IF('Model inputs'!B19="","",'Model inputs'!B19=1))=FALSE,FALSE),FALSE,IF(IFERROR('Model inputs'!B224=FALSE,FALSE),FALSE,IF(OR(IF(ISERROR('Model inputs'!B19=1),'Model inputs'!B19=1,IF('Model inputs'!B19="","",'Model inputs'!B19=1))="",'Model inputs'!B224=""),"",AND(IF(ISERROR('Model inputs'!B19=1),'Model inputs'!B19=1,IF('Model inputs'!B19="","",'Model inputs'!B19=1)),'Model inputs'!B224))))="",FALSE,IF(IFERROR(IF(ISERROR('Model inputs'!B19=1),'Model inputs'!B19=1,IF('Model inputs'!B19="","",'Model inputs'!B19=1))=FALSE,FALSE),FALSE,IF(IFERROR('Model inputs'!B224=FALSE,FALSE),FALSE,IF(OR(IF(ISERROR('Model inputs'!B19=1),'Model inputs'!B19=1,IF('Model inputs'!B19="","",'Model inputs'!B19=1))="",'Model inputs'!B224=""),"",AND(IF(ISERROR('Model inputs'!B19=1),'Model inputs'!B19=1,IF('Model inputs'!B19="","",'Model inputs'!B19=1)),'Model inputs'!B224))))),IF('Model inputs'!B46="","",'Model inputs'!B46),IF('Model inputs'!B36="","",'Model inputs'!B36)) -> 0.24 | M17: =IF(IF(IF(IFERROR(IF(ISERROR('Model inputs'!B19=1),'Model inputs'!B19=1,IF('Model inputs'!B19="","",'Model inputs'!B19=1))=FALSE,FALSE),FALSE,IF(IFERROR('Model inputs'!B225=FALSE,FALSE),FALSE,IF(OR(IF(ISERROR('Model inputs'!B19=1),'Model inputs'!B19=1,IF('Model inputs'!B19="","",'Model inputs'!B19=1))="",'Model inputs'!B225=""),"",AND(IF(ISERROR('Model inputs'!B19=1),'Model inputs'!B19=1,IF('Model inputs'!B19="","",'Model inputs'!B19=1)),'Model inputs'!B225))))="",FALSE,IF(IFERROR(IF(ISERROR('Model inputs'!B19=1),'Model inputs'!B19=1,IF('Model inputs'!B19="","",'Model inputs'!B19=1))=FALSE,FALSE),FALSE,IF(IFERROR('Model inputs'!B225=FALSE,FALSE),FALSE,IF(OR(IF(ISERROR('Model inputs'!B19=1),'Model inputs'!B19=1,IF('Model inputs'!B19="","",'Model inputs'!B19=1))="",'Model inputs'!B225=""),"",AND(IF(ISERROR('Model inputs'!B19=1),'Model inputs'!B19=1,IF('Model inputs'!B19="","",'Model inputs'!B19=1)),'Model inputs'!B225))))),IF('Model inputs'!B46="","",'Model inputs'!B46),IF('Model inputs'!B36="","",'Model inputs'!B36)) -> 0.24 | N17: =IF(IF(IF(IFERROR(IF(ISERROR('Model inputs'!B19=1),'Model inputs'!B19=1,IF('Model inputs'!B19="","",'Model inputs'!B19=1))=FALSE,FALSE),FALSE,IF(IFERROR('Model inputs'!B226=FALSE,FALSE),FALSE,IF(OR(IF(ISERROR('Model inputs'!B19=1),'Model inputs'!B19=1,IF('Model inputs'!B19="","",'Model inputs'!B19=1))="",'Model inputs'!B226=""),"",AND(IF(ISERROR('Model inputs'!B19=1),'Model inputs'!B19=1,IF('Model inputs'!B19="","",'Model inputs'!B19=1)),'Model inputs'!B226))))="",FALSE,IF(IFERROR(IF(ISERROR('Model inputs'!B19=1),'Model inputs'!B19=1,IF('Model inputs'!B19="","",'Model inputs'!B19=1))=FALSE,FALSE),FALSE,IF(IFERROR('Model inputs'!B226=FALSE,FALSE),FALSE,IF(OR(IF(ISERROR('Model inputs'!B19=1),'Model inputs'!B19=1,IF('Model inputs'!B19="","",'Model inputs'!B19=1))="",'Model inputs'!B226=""),"",AND(IF(ISERROR('Model inputs'!B19=1),'Model inputs'!B19=1,IF('Model inputs'!B19="","",'Model inputs'!B19=1)),'Model inputs'!B226))))),IF('Model inputs'!B46="","",'Model inputs'!B46),IF('Model inputs'!B36="","",'Model inputs'!B36)) -> 0.24 | O17: =IF(IF(IF(IFERROR(IF(ISERROR('Model inputs'!B19=1),'Model inputs'!B19=1,IF('Model inputs'!B19="","",'Model inputs'!B19=1))=FALSE,FALSE),FALSE,IF(IFERROR('Model inputs'!B227=FALSE,FALSE),FALSE,IF(OR(IF(ISERROR('Model inputs'!B19=1),'Model inputs'!B19=1,IF('Model inputs'!B19="","",'Model inputs'!B19=1))="",'Model inputs'!B227=""),"",AND(IF(ISERROR('Model inputs'!B19=1),'Model inputs'!B19=1,IF('Model inputs'!B19="","",'Model inputs'!B19=1)),'Model inputs'!B227))))="",FALSE,IF(IFERROR(IF(ISERROR('Model inputs'!B19=1),'Model inputs'!B19=1,IF('Model inputs'!B19="","",'Model inputs'!B19=1))=FALSE,FALSE),FALSE,IF(IFERROR('Model inputs'!B227=FALSE,FALSE),FALSE,IF(OR(IF(ISERROR('Model inputs'!B19=1),'Model inputs'!B19=1,IF('Model inputs'!B19="","",'Model inputs'!B19=1))="",'Model inputs'!B227=""),"",AND(IF(ISERROR('Model inputs'!B19=1),'Model inputs'!B19=1,IF('Model inputs'!B19="","",'Model inputs'!B19=1)),'Model inputs'!B227))))),IF('Model inputs'!B46="","",'Model inputs'!B46),IF('Model inputs'!B36="","",'Model inputs'!B36)) -> 0.24 | P17: =IF(IF(IF(IFERROR(IF(ISERROR('Model inputs'!B19=1),'Model inputs'!B19=1,IF('Model inputs'!B19="","",'Model inputs'!B19=1))=FALSE,FALSE),FALSE,IF(IFERROR('Model inputs'!B228=FALSE,FALSE),FALSE,IF(OR(IF(ISERROR('Model inputs'!B19=1),'Model inputs'!B19=1,IF('Model inputs'!B19="","",'Model inputs'!B19=1))="",'Model inputs'!B228=""),"",AND(IF(ISERROR('Model inputs'!B19=1),'Model inputs'!B19=1,IF('Model inputs'!B19="","",'Model inputs'!B19=1)),'Model inputs'!B228))))="",FALSE,IF(IFERROR(IF(ISERROR('Model inputs'!B19=1),'Model inputs'!B19=1,IF('Model inputs'!B19="","",'Model inputs'!B19=1))=FALSE,FALSE),FALSE,IF(IFERROR('Model inputs'!B228=FALSE,FALSE),FALSE,IF(OR(IF(ISERROR('Model inputs'!B19=1),'Model inputs'!B19=1,IF('Model inputs'!B19="","",'Model inputs'!B19=1))="",'Model inputs'!B228=""),"",AND(IF(ISERROR('Model inputs'!B19=1),'Model inputs'!B19=1,IF('Model inputs'!B19="","",'Model inputs'!B19=1)),'Model inputs'!B228))))),IF('Model inputs'!B46="","",'Model inputs'!B46),IF('Model inputs'!B36="","",'Model inputs'!B36)) -> 0.24 | Q17: =IF(IF(IF(IFERROR(IF(ISERROR('Model inputs'!B19=1),'Model inputs'!B19=1,IF('Model inputs'!B19="","",'Model inputs'!B19=1))=FALSE,FALSE),FALSE,IF(IFERROR('Model inputs'!B229=FALSE,FALSE),FALSE,IF(OR(IF(ISERROR('Model inputs'!B19=1),'Model inputs'!B19=1,IF('Model inputs'!B19="","",'Model inputs'!B19=1))="",'Model inputs'!B229=""),"",AND(IF(ISERROR('Model inputs'!B19=1),'Model inputs'!B19=1,IF('Model inputs'!B19="","",'Model inputs'!B19=1)),'Model inputs'!B229))))="",FALSE,IF(IFERROR(IF(ISERROR('Model inputs'!B19=1),'Model inputs'!B19=1,IF('Model inputs'!B19="","",'Model inputs'!B19=1))=FALSE,FALSE),FALSE,IF(IFERROR('Model inputs'!B229=FALSE,FALSE),FALSE,IF(OR(IF(ISERROR('Model inputs'!B19=1),'Model inputs'!B19=1,IF('Model inputs'!B19="","",'Model inputs'!B19=1))="",'Model inputs'!B229=""),"",AND(IF(ISERROR('Model inputs'!B19=1),'Model inputs'!B19=1,IF('Model inputs'!B19="","",'Model inputs'!B19=1)),'Model inputs'!B229))))),IF('Model inputs'!B46="","",'Model inputs'!B46),IF('Model inputs'!B36="","",'Model inputs'!B36)) -> 0.24 | R17: =IF(IF(IF(IFERROR(IF(ISERROR('Model inputs'!B19=1),'Model inputs'!B19=1,IF('Model inputs'!B19="","",'Model inputs'!B19=1))=FALSE,FALSE),FALSE,IF(IFERROR('Model inputs'!B230=FALSE,FALSE),FALSE,IF(OR(IF(ISERROR('Model inputs'!B19=1),'Model inputs'!B19=1,IF('Model inputs'!B19="","",'Model inputs'!B19=1))="",'Model inputs'!B230=""),"",AND(IF(ISERROR('Model inputs'!B19=1),'Model inputs'!B19=1,IF('Model inputs'!B19="","",'Model inputs'!B19=1)),'Model inputs'!B230))))="",FALSE,IF(IFERROR(IF(ISERROR('Model inputs'!B19=1),'Model inputs'!B19=1,IF('Model inputs'!B19="","",'Model inputs'!B19=1))=FALSE,FALSE),FALSE,IF(IFERROR('Model inputs'!B230=FALSE,FALSE),FALSE,IF(OR(IF(ISERROR('Model inputs'!B19=1),'Model inputs'!B19=1,IF('Model inputs'!B19="","",'Model inputs'!B19=1))="",'Model inputs'!B230=""),"",AND(IF(ISERROR('Model inputs'!B19=1),'Model inputs'!B19=1,IF('Model inputs'!B19="","",'Model inputs'!B19=1)),'Model inputs'!B230))))),IF('Model inputs'!B46="","",'Model inputs'!B46),IF('Model inputs'!B36="","",'Model inputs'!B36)) -> 0.24 | S17: =IF(IF(IF(IFERROR(IF(ISERROR('Model inputs'!B19=1),'Model inputs'!B19=1,IF('Model inputs'!B19="","",'Model inputs'!B19=1))=FALSE,FALSE),FALSE,IF(IFERROR('Model inputs'!B231=FALSE,FALSE),FALSE,IF(OR(IF(ISERROR('Model inputs'!B19=1),'Model inputs'!B19=1,IF('Model inputs'!B19="","",'Model inputs'!B19=1))="",'Model inputs'!B231=""),"",AND(IF(ISERROR('Model inputs'!B19=1),'Model inputs'!B19=1,IF('Model inputs'!B19="","",'Model inputs'!B19=1)),'Model inputs'!B231))))="",FALSE,IF(IFERROR(IF(ISERROR('Model inputs'!B19=1),'Model inputs'!B19=1,IF('Model inputs'!B19="","",'Model inputs'!B19=1))=FALSE,FALSE),FALSE,IF(IFERROR('Model inputs'!B231=FALSE,FALSE),FALSE,IF(OR(IF(ISERROR('Model inputs'!B19=1),'Model inputs'!B19=1,IF('Model inputs'!B19="","",'Model inputs'!B19=1))="",'Model inputs'!B231=""),"",AND(IF(ISERROR('Model inputs'!B19=1),'Model inputs'!B19=1,IF('Model inputs'!B19="","",'Model inputs'!B19=1)),'Model inputs'!B231))))),IF('Model inputs'!B46="","",'Model inputs'!B46),IF('Model inputs'!B36="","",'Model inputs'!B36)) -> 0.24
A18: Payment fees per customer | B18: =IFERROR('Model inputs'!C51/'RC Unit economics'!B5,"") -> 1.964526 | C18: =IFERROR('Model inputs'!D51/'RC Unit economics'!C5,"") -> 2.2150413 | D18: =IFERROR('Model inputs'!E51/'RC Unit economics'!D5,"") -> 2.3437748 | E18: =IFERROR('Model inputs'!F51/'RC Unit economics'!E5,"") -> 2.4278445 | F18: =IFERROR('Model inputs'!G51/'RC Unit economics'!F5,"") -> 2.4872788 | G18: =IFERROR('Model inputs'!H51/'RC Unit economics'!G5,"") -> 2.5315317 | H18: =IFERROR('Model inputs'!I51/'RC Unit economics'!H5,"") -> 2.5657001 | I18: =IFERROR('Model inputs'!J51/'RC Unit economics'!I5,"") -> 2.1416561 | ... S18: =IFERROR('Model inputs'!T51/'RC Unit economics'!S5,"") -> 2.254695
A19: Indie | B19: =IFERROR('Model inputs'!C52/'RC Unit economics'!B6,"") -> 1.19204 | C19: =IFERROR('Model inputs'!D52/'RC Unit economics'!C6,"") -> 1.19204 | D19: =IFERROR('Model inputs'!E52/'RC Unit economics'!D6,"") -> 1.19204 | E19: =IFERROR('Model inputs'!F52/'RC Unit economics'!E6,"") -> 1.19204 | F19: =IFERROR('Model inputs'!G52/'RC Unit economics'!F6,"") -> 1.19204 | G19: =IFERROR('Model inputs'!H52/'RC Unit economics'!G6,"") -> 1.19204 | H19: =IFERROR('Model inputs'!I52/'RC Unit economics'!H6,"") -> 1.19204 | I19: =IFERROR('Model inputs'!J52/'RC Unit economics'!I6,"") -> 1.19204 | ... S19: =IFERROR('Model inputs'!T52/'RC Unit economics'!S6,"") -> 1.19204
A20: Launch | B20: =IFERROR('Model inputs'!C53/'RC Unit economics'!B7,"") -> 15.56444 | C20: =IFERROR('Model inputs'!D53/'RC Unit economics'!C7,"") -> 23.161715 | D20: =IFERROR('Model inputs'!E53/'RC Unit economics'!D7,"") -> 24.546296 | E20: =IFERROR('Model inputs'!F53/'RC Unit economics'!E7,"") -> 25.106813 | F20: =IFERROR('Model inputs'!G53/'RC Unit economics'!F7,"") -> 25.263516 | G20: =IFERROR('Model inputs'!H53/'RC Unit economics'!G7,"") -> 25.196332 | H20: =IFERROR('Model inputs'!I53/'RC Unit economics'!H7,"") -> 24.995372 | I20: =IFERROR('Model inputs'!J53/'RC Unit economics'!I7,"") -> 17.113659 | ... S20: =IFERROR('Model inputs'!T53/'RC Unit economics'!S7,"") -> 18.175509
A21: Team | B21: =IFERROR('Model inputs'!C54/'RC Unit economics'!B8,"") -> 4.84778 | C21: =IFERROR('Model inputs'!D54/'RC Unit economics'!C8,"") -> 7.116305 | D21: =IFERROR('Model inputs'!E54/'RC Unit economics'!D8,"") -> 7.6068597 | E21: =IFERROR('Model inputs'!F54/'RC Unit economics'!E8,"") -> 7.8841294 | F21: =IFERROR('Model inputs'!G54/'RC Unit economics'!F8,"") -> 8.0502435 | G21: =IFERROR('Model inputs'!H54/'RC Unit economics'!G8,"") -> 8.1513437 | H21: =IFERROR('Model inputs'!I54/'RC Unit economics'!H8,"") -> 8.2115027 | I21: =IFERROR('Model inputs'!J54/'RC Unit economics'!I8,"") -> 5.9760845 | ... S21: =IFERROR('Model inputs'!T54/'RC Unit economics'!S8,"") -> 5.575175
A22: Contribution per customer | B22: =IFERROR('Model inputs'!C14/'RC Unit economics'!B5,"") -> 51.204836 | C22: =IFERROR('Model inputs'!D14/'RC Unit economics'!C5,"") -> 46.702986 | D22: =IFERROR('Model inputs'!E14/'RC Unit economics'!D5,"") -> 47.263584 | E22: =IFERROR('Model inputs'!F14/'RC Unit economics'!E5,"") -> 47.647396 | F22: =IFERROR('Model inputs'!G14/'RC Unit economics'!F5,"") -> 47.92435 | G22: =IFERROR('Model inputs'!H14/'RC Unit economics'!G5,"") -> 48.127711 | H22: =IFERROR('Model inputs'!I14/'RC Unit economics'!H5,"") -> 48.275672 | I22: =IFERROR('Model inputs'!J14/'RC Unit economics'!I5,"") -> 49.118553 | ... S22: =IFERROR('Model inputs'!T14/'RC Unit economics'!S5,"") -> 52.682384
A23: Indie | B23: =IFERROR('Model inputs'!C15/'RC Unit economics'!B6,"") -> 27.52796 | C23: =IFERROR('Model inputs'!D15/'RC Unit economics'!C6,"") -> 27.52796 | D23: =IFERROR('Model inputs'!E15/'RC Unit economics'!D6,"") -> 27.52796 | E23: =IFERROR('Model inputs'!F15/'RC Unit economics'!E6,"") -> 27.52796 | F23: =IFERROR('Model inputs'!G15/'RC Unit economics'!F6,"") -> 27.52796 | G23: =IFERROR('Model inputs'!H15/'RC Unit economics'!G6,"") -> 27.52796 | H23: =IFERROR('Model inputs'!I15/'RC Unit economics'!H6,"") -> 27.52796 | I23: =IFERROR('Model inputs'!J15/'RC Unit economics'!I6,"") -> 27.52796 | ... S23: =IFERROR('Model inputs'!T15/'RC Unit economics'!S6,"") -> 27.52796
A24: Launch | B24: =IFERROR('Model inputs'!C16/'RC Unit economics'!B7,"") -> 461.35556 | C24: =IFERROR('Model inputs'!D16/'RC Unit economics'!C7,"") -> 448.9069 | D24: =IFERROR('Model inputs'!E16/'RC Unit economics'!D7,"") -> 442.67093 | E24: =IFERROR('Model inputs'!F16/'RC Unit economics'!E7,"") -> 437.25902 | F24: =IFERROR('Model inputs'!G16/'RC Unit economics'!F7,"") -> 432.25093 | G24: =IFERROR('Model inputs'!H16/'RC Unit economics'!G7,"") -> 427.46672 | H24: =IFERROR('Model inputs'!I16/'RC Unit economics'!H7,"") -> 422.81629 | I24: =IFERROR('Model inputs'!J16/'RC Unit economics'!I7,"") -> 430.69801 | ... S24: =IFERROR('Model inputs'!T16/'RC Unit economics'!S7,"") -> 429.63616
A25: Team | B25: =IFERROR('Model inputs'!C17/'RC Unit economics'!B8,"") -> 140.69222 | C25: =IFERROR('Model inputs'!D17/'RC Unit economics'!C8,"") -> 136.97508 | D25: =IFERROR('Model inputs'!E17/'RC Unit economics'!D8,"") -> 135.03592 | E25: =IFERROR('Model inputs'!F17/'RC Unit economics'!E8,"") -> 133.31004 | F25: =IFERROR('Model inputs'!G17/'RC Unit economics'!F8,"") -> 131.69531 | G25: =IFERROR('Model inputs'!H17/'RC Unit economics'!G8,"") -> 130.1456 | H25: =IFERROR('Model inputs'!I17/'RC Unit economics'!H8,"") -> 128.63683 | I25: =IFERROR('Model inputs'!J17/'RC Unit economics'!I8,"") -> 130.87225 | ... S25: =IFERROR('Model inputs'!T17/'RC Unit economics'!S8,"") -> 131.27316
A26: Contribution margin % | B26: =IFERROR('Model inputs'!C14/'Model inputs'!C55,"") -> 0.89210999 | C26: =IFERROR('Model inputs'!D14/'Model inputs'!D55,"") -> 0.88474115 | D26: =IFERROR('Model inputs'!E14/'Model inputs'!E55,"") -> 0.88248318 | E26: =IFERROR('Model inputs'!F14/'Model inputs'!F55,"") -> 0.88094205 | F26: =IFERROR('Model inputs'!G14/'Model inputs'!G55,"") -> 0.87977262 | G26: =IFERROR('Model inputs'!H14/'Model inputs'!H55,"") -> 0.87881677 | H26: =IFERROR('Model inputs'!I14/'Model inputs'!I55,"") -> 0.87799126 | I26: =IFERROR('Model inputs'!J14/'Model inputs'!J55,"") -> 0.88602377 | ... S26: =IFERROR('Model inputs'!T14/'Model inputs'!T55,"") -> 0.88647561
A27: Indie | B27: =IFERROR('Model inputs'!C15/'Model inputs'!C56,"") -> 0.89492718 | C27: =IFERROR('Model inputs'!D15/'Model inputs'!D56,"") -> 0.89492718 | D27: =IFERROR('Model inputs'!E15/'Model inputs'!E56,"") -> 0.89492718 | E27: =IFERROR('Model inputs'!F15/'Model inputs'!F56,"") -> 0.89492718 | F27: =IFERROR('Model inputs'!G15/'Model inputs'!G56,"") -> 0.89492718 | G27: =IFERROR('Model inputs'!H15/'Model inputs'!H56,"") -> 0.89492718 | H27: =IFERROR('Model inputs'!I15/'Model inputs'!I56,"") -> 0.89492718 | I27: =IFERROR('Model inputs'!J15/'Model inputs'!J56,"") -> 0.89492718 | ... S27: =IFERROR('Model inputs'!T15/'Model inputs'!T56,"") -> 0.89492718
A28: Launch | B28: =IFERROR('Model inputs'!C16/'Model inputs'!C57,"") -> 0.87650194 | C28: =IFERROR('Model inputs'!D16/'Model inputs'!D57,"") -> 0.8607852 | D28: =IFERROR('Model inputs'!E16/'Model inputs'!E57,"") -> 0.8567981 | E28: =IFERROR('Model inputs'!F16/'Model inputs'!F57,"") -> 0.85434552 | F28: =IFERROR('Model inputs'!G16/'Model inputs'!G57,"") -> 0.85264255 | G28: =IFERROR('Model inputs'!H16/'Model inputs'!H57,"") -> 0.85135256 | H28: =IFERROR('Model inputs'!I16/'Model inputs'!I57,"") -> 0.85030644 | I28: =IFERROR('Model inputs'!J16/'Model inputs'!J57,"") -> 0.86615699 | ... S28: =IFERROR('Model inputs'!T16/'Model inputs'!T57,"") -> 0.86402155
A29: Team | B29: =IFERROR('Model inputs'!C17/'Model inputs'!C58,"") -> 0.89715738 | C29: =IFERROR('Model inputs'!D17/'Model inputs'!D58,"") -> 0.88159786 | D29: =IFERROR('Model inputs'!E17/'Model inputs'!E58,"") -> 0.87729653 | E29: =IFERROR('Model inputs'!F17/'Model inputs'!F58,"") -> 0.87431229 | F29: =IFERROR('Model inputs'!G17/'Model inputs'!G58,"") -> 0.8720068 | G29: =IFERROR('Model inputs'!H17/'Model inputs'!H58,"") -> 0.87009132 | H29: =IFERROR('Model inputs'!I17/'Model inputs'!I58,"") -> 0.86841476 | I29: =IFERROR('Model inputs'!J17/'Model inputs'!J58,"") -> 0.88350585 | ... S29: =IFERROR('Model inputs'!T17/'Model inputs'!T58,"") -> 0.88621235
A30: LTV (24-month) | B30: =IFERROR('RC Unit economics'!B22*(1-(1-IF(IF(SUM(IF(IF('Model inputs'!B232="",0,1)="",0,IF('Model inputs'!B232="",0,1)),IF(IF('Model inputs'!B233="",0,1)="",0,IF('Model inputs'!B233="",0,1)),IF(IF('Model inputs'!B234="",0,1)="",0,IF('Model inputs'!B234="",0,1)))=0,"",SUM('Model inputs'!B232,'Model inputs'!B233,'Model inputs'!B234))="",0,IF(SUM(IF(IF('Model inputs'!B232="",0,1)="",0,IF('Model inputs'!B232="",0,1)),IF(IF('Model inputs'!B233="",0,1)="",0,IF('Model inputs'!B233="",0,1)),IF(IF('Model inputs'!B234="",0,1)="",0,IF('Model inputs'!B234="",0,1)))=0,"",SUM('Model inputs'!B232,'Model inputs'!B233,'Model inputs'!B234))))^24)/IF(IF(SUM(IF(IF('Model inputs'!B232="",0,1)="",0,IF('Model inputs'!B232="",0,1)),IF(IF('Model inputs'!B233="",0,1)="",0,IF('Model inputs'!B233="",0,1)),IF(IF('Model inputs'!B234="",0,1)="",0,IF('Model inputs'!B234="",0,1)))=0,"",SUM('Model inputs'!B232,'Model inputs'!B233,'Model inputs'!B234))="",0,IF(SUM(IF(IF('Model inputs'!B232="",0,1)="",0,IF('Model inputs'!B232="",0,1)),IF(IF('Model inputs'!B233="",0,1)="",0,IF('Model inputs'!B233="",0,1)),IF(IF('Model inputs'!B234="",0,1)="",0,IF('Model inputs'!B234="",0,1)))=0,"",SUM('Model inputs'!B232,'Model inputs'!B233,'Model inputs'!B234))),"") | C30: =IFERROR('RC Unit economics'!C22*(1-(1-IF(IF(SUM(IF(IF('Model inputs'!B232="",0,1)="",0,IF('Model inputs'!B232="",0,1)),IF(IF('Model inputs'!B233="",0,1)="",0,IF('Model inputs'!B233="",0,1)),IF(IF('Model inputs'!B234="",0,1)="",0,IF('Model inputs'!B234="",0,1)))=0,"",SUM('Model inputs'!B232,'Model inputs'!B233,'Model inputs'!B234))="",0,IF(SUM(IF(IF('Model inputs'!B232="",0,1)="",0,IF('Model inputs'!B232="",0,1)),IF(IF('Model inputs'!B233="",0,1)="",0,IF('Model inputs'!B233="",0,1)),IF(IF('Model inputs'!B234="",0,1)="",0,IF('Model inputs'!B234="",0,1)))=0,"",SUM('Model inputs'!B232,'Model inputs'!B233,'Model inputs'!B234))))^24)/IF(IF(SUM(IF(IF('Model inputs'!B232="",0,1)="",0,IF('Model inputs'!B232="",0,1)),IF(IF('Model inputs'!B233="",0,1)="",0,IF('Model inputs'!B233="",0,1)),IF(IF('Model inputs'!B234="",0,1)="",0,IF('Model inputs'!B234="",0,1)))=0,"",SUM('Model inputs'!B232,'Model inputs'!B233,'Model inputs'!B234))="",0,IF(SUM(IF(IF('Model inputs'!B232="",0,1)="",0,IF('Model inputs'!B232="",0,1)),IF(IF('Model inputs'!B233="",0,1)="",0,IF('Model inputs'!B233="",0,1)),IF(IF('Model inputs'!B234="",0,1)="",0,IF('Model inputs'!B234="",0,1)))=0,"",SUM('Model inputs'!B232,'Model inputs'!B233,'Model inputs'!B234))),"") | D30: =IFERROR('RC Unit economics'!D22*(1-(1-IF(IF(SUM(IF(IF('Model inputs'!B232="",0,1)="",0,IF('Model inputs'!B232="",0,1)),IF(IF('Model inputs'!B233="",0,1)="",0,IF('Model inputs'!B233="",0,1)),IF(IF('Model inputs'!B234="",0,1)="",0,IF('Model inputs'!B234="",0,1)))=0,"",SUM('Model inputs'!B232,'Model inputs'!B233,'Model inputs'!B234))="",0,IF(SUM(IF(IF('Model inputs'!B232="",0,1)="",0,IF('Model inputs'!B232="",0,1)),IF(IF('Model inputs'!B233="",0,1)="",0,IF('Model inputs'!B233="",0,1)),IF(IF('Model inputs'!B234="",0,1)="",0,IF('Model inputs'!B234="",0,1)))=0,"",SUM('Model inputs'!B232,'Model inputs'!B233,'Model inputs'!B234))))^24)/IF(IF(SUM(IF(IF('Model inputs'!B232="",0,1)="",0,IF('Model inputs'!B232="",0,1)),IF(IF('Model inputs'!B233="",0,1)="",0,IF('Model inputs'!B233="",0,1)),IF(IF('Model inputs'!B234="",0,1)="",0,IF('Model inputs'!B234="",0,1)))=0,"",SUM('Model inputs'!B232,'Model inputs'!B233,'Model inputs'!B234))="",0,IF(SUM(IF(IF('Model inputs'!B232="",0,1)="",0,IF('Model inputs'!B232="",0,1)),IF(IF('Model inputs'!B233="",0,1)="",0,IF('Model inputs'!B233="",0,1)),IF(IF('Model inputs'!B234="",0,1)="",0,IF('Model inputs'!B234="",0,1)))=0,"",SUM('Model inputs'!B232,'Model inputs'!B233,'Model inputs'!B234))),"") | E30: =IFERROR('RC Unit economics'!E22*(1-(1-IF(IF(SUM(IF(IF('Model inputs'!B232="",0,1)="",0,IF('Model inputs'!B232="",0,1)),IF(IF('Model inputs'!B233="",0,1)="",0,IF('Model inputs'!B233="",0,1)),IF(IF('Model inputs'!B234="",0,1)="",0,IF('Model inputs'!B234="",0,1)))=0,"",SUM('Model inputs'!B232,'Model inputs'!B233,'Model inputs'!B234))="",0,IF(SUM(IF(IF('Model inputs'!B232="",0,1)="",0,IF('Model inputs'!B232="",0,1)),IF(IF('Model inputs'!B233="",0,1)="",0,IF('Model inputs'!B233="",0,1)),IF(IF('Model inputs'!B234="",0,1)="",0,IF('Model inputs'!B234="",0,1)))=0,"",SUM('Model inputs'!B232,'Model inputs'!B233,'Model inputs'!B234))))^24)/IF(IF(SUM(IF(IF('Model inputs'!B232="",0,1)="",0,IF('Model inputs'!B232="",0,1)),IF(IF('Model inputs'!B233="",0,1)="",0,IF('Model inputs'!B233="",0,1)),IF(IF('Model inputs'!B234="",0,1)="",0,IF('Model inputs'!B234="",0,1)))=0,"",SUM('Model inputs'!B232,'Model inputs'!B233,'Model inputs'!B234))="",0,IF(SUM(IF(IF('Model inputs'!B232="",0,1)="",0,IF('Model inputs'!B232="",0,1)),IF(IF('Model inputs'!B233="",0,1)="",0,IF('Model inputs'!B233="",0,1)),IF(IF('Model inputs'!B234="",0,1)="",0,IF('Model inputs'!B234="",0,1)))=0,"",SUM('Model inputs'!B232,'Model inputs'!B233,'Model inputs'!B234))),"") | F30: =IFERROR('RC Unit economics'!F22*(1-(1-IF(IF(SUM(IF(IF('Model inputs'!B232="",0,1)="",0,IF('Model inputs'!B232="",0,1)),IF(IF('Model inputs'!B233="",0,1)="",0,IF('Model inputs'!B233="",0,1)),IF(IF('Model inputs'!B234="",0,1)="",0,IF('Model inputs'!B234="",0,1)))=0,"",SUM('Model inputs'!B232,'Model inputs'!B233,'Model inputs'!B234))="",0,IF(SUM(IF(IF('Model inputs'!B232="",0,1)="",0,IF('Model inputs'!B232="",0,1)),IF(IF('Model inputs'!B233="",0,1)="",0,IF('Model inputs'!B233="",0,1)),IF(IF('Model inputs'!B234="",0,1)="",0,IF('Model inputs'!B234="",0,1)))=0,"",SUM('Model inputs'!B232,'Model inputs'!B233,'Model inputs'!B234))))^24)/IF(IF(SUM(IF(IF('Model inputs'!B232="",0,1)="",0,IF('Model inputs'!B232="",0,1)),IF(IF('Model inputs'!B233="",0,1)="",0,IF('Model inputs'!B233="",0,1)),IF(IF('Model inputs'!B234="",0,1)="",0,IF('Model inputs'!B234="",0,1)))=0,"",SUM('Model inputs'!B232,'Model inputs'!B233,'Model inputs'!B234))="",0,IF(SUM(IF(IF('Model inputs'!B232="",0,1)="",0,IF('Model inputs'!B232="",0,1)),IF(IF('Model inputs'!B233="",0,1)="",0,IF('Model inputs'!B233="",0,1)),IF(IF('Model inputs'!B234="",0,1)="",0,IF('Model inputs'!B234="",0,1)))=0,"",SUM('Model inputs'!B232,'Model inputs'!B233,'Model inputs'!B234))),"") | G30: =IFERROR('RC Unit economics'!G22*(1-(1-IF(IF(SUM(IF(IF('Model inputs'!B232="",0,1)="",0,IF('Model inputs'!B232="",0,1)),IF(IF('Model inputs'!B233="",0,1)="",0,IF('Model inputs'!B233="",0,1)),IF(IF('Model inputs'!B234="",0,1)="",0,IF('Model inputs'!B234="",0,1)))=0,"",SUM('Model inputs'!B232,'Model inputs'!B233,'Model inputs'!B234))="",0,IF(SUM(IF(IF('Model inputs'!B232="",0,1)="",0,IF('Model inputs'!B232="",0,1)),IF(IF('Model inputs'!B233="",0,1)="",0,IF('Model inputs'!B233="",0,1)),IF(IF('Model inputs'!B234="",0,1)="",0,IF('Model inputs'!B234="",0,1)))=0,"",SUM('Model inputs'!B232,'Model inputs'!B233,'Model inputs'!B234))))^24)/IF(IF(SUM(IF(IF('Model inputs'!B232="",0,1)="",0,IF('Model inputs'!B232="",0,1)),IF(IF('Model inputs'!B233="",0,1)="",0,IF('Model inputs'!B233="",0,1)),IF(IF('Model inputs'!B234="",0,1)="",0,IF('Model inputs'!B234="",0,1)))=0,"",SUM('Model inputs'!B232,'Model inputs'!B233,'Model inputs'!B234))="",0,IF(SUM(IF(IF('Model inputs'!B232="",0,1)="",0,IF('Model inputs'!B232="",0,1)),IF(IF('Model inputs'!B233="",0,1)="",0,IF('Model inputs'!B233="",0,1)),IF(IF('Model inputs'!B234="",0,1)="",0,IF('Model inputs'!B234="",0,1)))=0,"",SUM('Model inputs'!B232,'Model inputs'!B233,'Model inputs'!B234))),"") | H30: =IFERROR('RC Unit economics'!H22*(1-(1-IF(IF(SUM(IF(IF('Model inputs'!B232="",0,1)="",0,IF('Model inputs'!B232="",0,1)),IF(IF('Model inputs'!B233="",0,1)="",0,IF('Model inputs'!B233="",0,1)),IF(IF('Model inputs'!B234="",0,1)="",0,IF('Model inputs'!B234="",0,1)))=0,"",SUM('Model inputs'!B232,'Model inputs'!B233,'Model inputs'!B234))="",0,IF(SUM(IF(IF('Model inputs'!B232="",0,1)="",0,IF('Model inputs'!B232="",0,1)),IF(IF('Model inputs'!B233="",0,1)="",0,IF('Model inputs'!B233="",0,1)),IF(IF('Model inputs'!B234="",0,1)="",0,IF('Model inputs'!B234="",0,1)))=0,"",SUM('Model inputs'!B232,'Model inputs'!B233,'Model inputs'!B234))))^24)/IF(IF(SUM(IF(IF('Model inputs'!B232="",0,1)="",0,IF('Model inputs'!B232="",0,1)),IF(IF('Model inputs'!B233="",0,1)="",0,IF('Model inputs'!B233="",0,1)),IF(IF('Model inputs'!B234="",0,1)="",0,IF('Model inputs'!B234="",0,1)))=0,"",SUM('Model inputs'!B232,'Model inputs'!B233,'Model inputs'!B234))="",0,IF(SUM(IF(IF('Model inputs'!B232="",0,1)="",0,IF('Model inputs'!B232="",0,1)),IF(IF('Model inputs'!B233="",0,1)="",0,IF('Model inputs'!B233="",0,1)),IF(IF('Model inputs'!B234="",0,1)="",0,IF('Model inputs'!B234="",0,1)))=0,"",SUM('Model inputs'!B232,'Model inputs'!B233,'Model inputs'!B234))),"") | I30: =IFERROR('RC Unit economics'!I22*(1-(1-IF(IF(SUM(IF(IF('Model inputs'!B232="",0,1)="",0,IF('Model inputs'!B232="",0,1)),IF(IF('Model inputs'!B233="",0,1)="",0,IF('Model inputs'!B233="",0,1)),IF(IF('Model inputs'!B234="",0,1)="",0,IF('Model inputs'!B234="",0,1)))=0,"",SUM('Model inputs'!B232,'Model inputs'!B233,'Model inputs'!B234))="",0,IF(SUM(IF(IF('Model inputs'!B232="",0,1)="",0,IF('Model inputs'!B232="",0,1)),IF(IF('Model inputs'!B233="",0,1)="",0,IF('Model inputs'!B233="",0,1)),IF(IF('Model inputs'!B234="",0,1)="",0,IF('Model inputs'!B234="",0,1)))=0,"",SUM('Model inputs'!B232,'Model inputs'!B233,'Model inputs'!B234))))^24)/IF(IF(SUM(IF(IF('Model inputs'!B232="",0,1)="",0,IF('Model inputs'!B232="",0,1)),IF(IF('Model inputs'!B233="",0,1)="",0,IF('Model inputs'!B233="",0,1)),IF(IF('Model inputs'!B234="",0,1)="",0,IF('Model inputs'!B234="",0,1)))=0,"",SUM('Model inputs'!B232,'Model inputs'!B233,'Model inputs'!B234))="",0,IF(SUM(IF(IF('Model inputs'!B232="",0,1)="",0,IF('Model inputs'!B232="",0,1)),IF(IF('Model inputs'!B233="",0,1)="",0,IF('Model inputs'!B233="",0,1)),IF(IF('Model inputs'!B234="",0,1)="",0,IF('Model inputs'!B234="",0,1)))=0,"",SUM('Model inputs'!B232,'Model inputs'!B233,'Model inputs'!B234))),"") | J30: =IFERROR('RC Unit economics'!J22*(1-(1-IF(IF(SUM(IF(IF('Model inputs'!B232="",0,1)="",0,IF('Model inputs'!B232="",0,1)),IF(IF('Model inputs'!B233="",0,1)="",0,IF('Model inputs'!B233="",0,1)),IF(IF('Model inputs'!B234="",0,1)="",0,IF('Model inputs'!B234="",0,1)))=0,"",SUM('Model inputs'!B232,'Model inputs'!B233,'Model inputs'!B234))="",0,IF(SUM(IF(IF('Model inputs'!B232="",0,1)="",0,IF('Model inputs'!B232="",0,1)),IF(IF('Model inputs'!B233="",0,1)="",0,IF('Model inputs'!B233="",0,1)),IF(IF('Model inputs'!B234="",0,1)="",0,IF('Model inputs'!B234="",0,1)))=0,"",SUM('Model inputs'!B232,'Model inputs'!B233,'Model inputs'!B234))))^24)/IF(IF(SUM(IF(IF('Model inputs'!B232="",0,1)="",0,IF('Model inputs'!B232="",0,1)),IF(IF('Model inputs'!B233="",0,1)="",0,IF('Model inputs'!B233="",0,1)),IF(IF('Model inputs'!B234="",0,1)="",0,IF('Model inputs'!B234="",0,1)))=0,"",SUM('Model inputs'!B232,'Model inputs'!B233,'Model inputs'!B234))="",0,IF(SUM(IF(IF('Model inputs'!B232="",0,1)="",0,IF('Model inputs'!B232="",0,1)),IF(IF('Model inputs'!B233="",0,1)="",0,IF('Model inputs'!B233="",0,1)),IF(IF('Model inputs'!B234="",0,1)="",0,IF('Model inputs'!B234="",0,1)))=0,"",SUM('Model inputs'!B232,'Model inputs'!B233,'Model inputs'!B234))),"") | K30: =IFERROR('RC Unit economics'!K22*(1-(1-IF(IF(SUM(IF(IF('Model inputs'!B232="",0,1)="",0,IF('Model inputs'!B232="",0,1)),IF(IF('Model inputs'!B233="",0,1)="",0,IF('Model inputs'!B233="",0,1)),IF(IF('Model inputs'!B234="",0,1)="",0,IF('Model inputs'!B234="",0,1)))=0,"",SUM('Model inputs'!B232,'Model inputs'!B233,'Model inputs'!B234))="",0,IF(SUM(IF(IF('Model inputs'!B232="",0,1)="",0,IF('Model inputs'!B232="",0,1)),IF(IF('Model inputs'!B233="",0,1)="",0,IF('Model inputs'!B233="",0,1)),IF(IF('Model inputs'!B234="",0,1)="",0,IF('Model inputs'!B234="",0,1)))=0,"",SUM('Model inputs'!B232,'Model inputs'!B233,'Model inputs'!B234))))^24)/IF(IF(SUM(IF(IF('Model inputs'!B232="",0,1)="",0,IF('Model inputs'!B232="",0,1)),IF(IF('Model inputs'!B233="",0,1)="",0,IF('Model inputs'!B233="",0,1)),IF(IF('Model inputs'!B234="",0,1)="",0,IF('Model inputs'!B234="",0,1)))=0,"",SUM('Model inputs'!B232,'Model inputs'!B233,'Model inputs'!B234))="",0,IF(SUM(IF(IF('Model inputs'!B232="",0,1)="",0,IF('Model inputs'!B232="",0,1)),IF(IF('Model inputs'!B233="",0,1)="",0,IF('Model inputs'!B233="",0,1)),IF(IF('Model inputs'!B234="",0,1)="",0,IF('Model inputs'!B234="",0,1)))=0,"",SUM('Model inputs'!B232,'Model inputs'!B233,'Model inputs'!B234))),"") | L30: =IFERROR('RC Unit economics'!L22*(1-(1-IF(IF(SUM(IF(IF('Model inputs'!B232="",0,1)="",0,IF('Model inputs'!B232="",0,1)),IF(IF('Model inputs'!B233="",0,1)="",0,IF('Model inputs'!B233="",0,1)),IF(IF('Model inputs'!B234="",0,1)="",0,IF('Model inputs'!B234="",0,1)))=0,"",SUM('Model inputs'!B232,'Model inputs'!B233,'Model inputs'!B234))="",0,IF(SUM(IF(IF('Model inputs'!B232="",0,1)="",0,IF('Model inputs'!B232="",0,1)),IF(IF('Model inputs'!B233="",0,1)="",0,IF('Model inputs'!B233="",0,1)),IF(IF('Model inputs'!B234="",0,1)="",0,IF('Model inputs'!B234="",0,1)))=0,"",SUM('Model inputs'!B232,'Model inputs'!B233,'Model inputs'!B234))))^24)/IF(IF(SUM(IF(IF('Model inputs'!B232="",0,1)="",0,IF('Model inputs'!B232="",0,1)),IF(IF('Model inputs'!B233="",0,1)="",0,IF('Model inputs'!B233="",0,1)),IF(IF('Model inputs'!B234="",0,1)="",0,IF('Model inputs'!B234="",0,1)))=0,"",SUM('Model inputs'!B232,'Model inputs'!B233,'Model inputs'!B234))="",0,IF(SUM(IF(IF('Model inputs'!B232="",0,1)="",0,IF('Model inputs'!B232="",0,1)),IF(IF('Model inputs'!B233="",0,1)="",0,IF('Model inputs'!B233="",0,1)),IF(IF('Model inputs'!B234="",0,1)="",0,IF('Model inputs'!B234="",0,1)))=0,"",SUM('Model inputs'!B232,'Model inputs'!B233,'Model inputs'!B234))),"") | M30: =IFERROR('RC Unit economics'!M22*(1-(1-IF(IF(SUM(IF(IF('Model inputs'!B232="",0,1)="",0,IF('Model inputs'!B232="",0,1)),IF(IF('Model inputs'!B233="",0,1)="",0,IF('Model inputs'!B233="",0,1)),IF(IF('Model inputs'!B234="",0,1)="",0,IF('Model inputs'!B234="",0,1)))=0,"",SUM('Model inputs'!B232,'Model inputs'!B233,'Model inputs'!B234))="",0,IF(SUM(IF(IF('Model inputs'!B232="",0,1)="",0,IF('Model inputs'!B232="",0,1)),IF(IF('Model inputs'!B233="",0,1)="",0,IF('Model inputs'!B233="",0,1)),IF(IF('Model inputs'!B234="",0,1)="",0,IF('Model inputs'!B234="",0,1)))=0,"",SUM('Model inputs'!B232,'Model inputs'!B233,'Model inputs'!B234))))^24)/IF(IF(SUM(IF(IF('Model inputs'!B232="",0,1)="",0,IF('Model inputs'!B232="",0,1)),IF(IF('Model inputs'!B233="",0,1)="",0,IF('Model inputs'!B233="",0,1)),IF(IF('Model inputs'!B234="",0,1)="",0,IF('Model inputs'!B234="",0,1)))=0,"",SUM('Model inputs'!B232,'Model inputs'!B233,'Model inputs'!B234))="",0,IF(SUM(IF(IF('Model inputs'!B232="",0,1)="",0,IF('Model inputs'!B232="",0,1)),IF(IF('Model inputs'!B233="",0,1)="",0,IF('Model inputs'!B233="",0,1)),IF(IF('Model inputs'!B234="",0,1)="",0,IF('Model inputs'!B234="",0,1)))=0,"",SUM('Model inputs'!B232,'Model inputs'!B233,'Model inputs'!B234))),"") | N30: =IFERROR('RC Unit economics'!N22*(1-(1-IF(IF(SUM(IF(IF('Model inputs'!B232="",0,1)="",0,IF('Model inputs'!B232="",0,1)),IF(IF('Model inputs'!B233="",0,1)="",0,IF('Model inputs'!B233="",0,1)),IF(IF('Model inputs'!B234="",0,1)="",0,IF('Model inputs'!B234="",0,1)))=0,"",SUM('Model inputs'!B232,'Model inputs'!B233,'Model inputs'!B234))="",0,IF(SUM(IF(IF('Model inputs'!B232="",0,1)="",0,IF('Model inputs'!B232="",0,1)),IF(IF('Model inputs'!B233="",0,1)="",0,IF('Model inputs'!B233="",0,1)),IF(IF('Model inputs'!B234="",0,1)="",0,IF('Model inputs'!B234="",0,1)))=0,"",SUM('Model inputs'!B232,'Model inputs'!B233,'Model inputs'!B234))))^24)/IF(IF(SUM(IF(IF('Model inputs'!B232="",0,1)="",0,IF('Model inputs'!B232="",0,1)),IF(IF('Model inputs'!B233="",0,1)="",0,IF('Model inputs'!B233="",0,1)),IF(IF('Model inputs'!B234="",0,1)="",0,IF('Model inputs'!B234="",0,1)))=0,"",SUM('Model inputs'!B232,'Model inputs'!B233,'Model inputs'!B234))="",0,IF(SUM(IF(IF('Model inputs'!B232="",0,1)="",0,IF('Model inputs'!B232="",0,1)),IF(IF('Model inputs'!B233="",0,1)="",0,IF('Model inputs'!B233="",0,1)),IF(IF('Model inputs'!B234="",0,1)="",0,IF('Model inputs'!B234="",0,1)))=0,"",SUM('Model inputs'!B232,'Model inputs'!B233,'Model inputs'!B234))),"") | O30: =IFERROR('RC Unit economics'!O22*(1-(1-IF(IF(SUM(IF(IF('Model inputs'!B232="",0,1)="",0,IF('Model inputs'!B232="",0,1)),IF(IF('Model inputs'!B233="",0,1)="",0,IF('Model inputs'!B233="",0,1)),IF(IF('Model inputs'!B234="",0,1)="",0,IF('Model inputs'!B234="",0,1)))=0,"",SUM('Model inputs'!B232,'Model inputs'!B233,'Model inputs'!B234))="",0,IF(SUM(IF(IF('Model inputs'!B232="",0,1)="",0,IF('Model inputs'!B232="",0,1)),IF(IF('Model inputs'!B233="",0,1)="",0,IF('Model inputs'!B233="",0,1)),IF(IF('Model inputs'!B234="",0,1)="",0,IF('Model inputs'!B234="",0,1)))=0,"",SUM('Model inputs'!B232,'Model inputs'!B233,'Model inputs'!B234))))^24)/IF(IF(SUM(IF(IF('Model inputs'!B232="",0,1)="",0,IF('Model inputs'!B232="",0,1)),IF(IF('Model inputs'!B233="",0,1)="",0,IF('Model inputs'!B233="",0,1)),IF(IF('Model inputs'!B234="",0,1)="",0,IF('Model inputs'!B234="",0,1)))=0,"",SUM('Model inputs'!B232,'Model inputs'!B233,'Model inputs'!B234))="",0,IF(SUM(IF(IF('Model inputs'!B232="",0,1)="",0,IF('Model inputs'!B232="",0,1)),IF(IF('Model inputs'!B233="",0,1)="",0,IF('Model inputs'!B233="",0,1)),IF(IF('Model inputs'!B234="",0,1)="",0,IF('Model inputs'!B234="",0,1)))=0,"",SUM('Model inputs'!B232,'Model inputs'!B233,'Model inputs'!B234))),"") | P30: =IFERROR('RC Unit economics'!P22*(1-(1-IF(IF(SUM(IF(IF('Model inputs'!B232="",0,1)="",0,IF('Model inputs'!B232="",0,1)),IF(IF('Model inputs'!B233="",0,1)="",0,IF('Model inputs'!B233="",0,1)),IF(IF('Model inputs'!B234="",0,1)="",0,IF('Model inputs'!B234="",0,1)))=0,"",SUM('Model inputs'!B232,'Model inputs'!B233,'Model inputs'!B234))="",0,IF(SUM(IF(IF('Model inputs'!B232="",0,1)="",0,IF('Model inputs'!B232="",0,1)),IF(IF('Model inputs'!B233="",0,1)="",0,IF('Model inputs'!B233="",0,1)),IF(IF('Model inputs'!B234="",0,1)="",0,IF('Model inputs'!B234="",0,1)))=0,"",SUM('Model inputs'!B232,'Model inputs'!B233,'Model inputs'!B234))))^24)/IF(IF(SUM(IF(IF('Model inputs'!B232="",0,1)="",0,IF('Model inputs'!B232="",0,1)),IF(IF('Model inputs'!B233="",0,1)="",0,IF('Model inputs'!B233="",0,1)),IF(IF('Model inputs'!B234="",0,1)="",0,IF('Model inputs'!B234="",0,1)))=0,"",SUM('Model inputs'!B232,'Model inputs'!B233,'Model inputs'!B234))="",0,IF(SUM(IF(IF('Model inputs'!B232="",0,1)="",0,IF('Model inputs'!B232="",0,1)),IF(IF('Model inputs'!B233="",0,1)="",0,IF('Model inputs'!B233="",0,1)),IF(IF('Model inputs'!B234="",0,1)="",0,IF('Model inputs'!B234="",0,1)))=0,"",SUM('Model inputs'!B232,'Model inputs'!B233,'Model inputs'!B234))),"") | Q30: =IFERROR('RC Unit economics'!Q22*(1-(1-IF(IF(SUM(IF(IF('Model inputs'!B232="",0,1)="",0,IF('Model inputs'!B232="",0,1)),IF(IF('Model inputs'!B233="",0,1)="",0,IF('Model inputs'!B233="",0,1)),IF(IF('Model inputs'!B234="",0,1)="",0,IF('Model inputs'!B234="",0,1)))=0,"",SUM('Model inputs'!B232,'Model inputs'!B233,'Model inputs'!B234))="",0,IF(SUM(IF(IF('Model inputs'!B232="",0,1)="",0,IF('Model inputs'!B232="",0,1)),IF(IF('Model inputs'!B233="",0,1)="",0,IF('Model inputs'!B233="",0,1)),IF(IF('Model inputs'!B234="",0,1)="",0,IF('Model inputs'!B234="",0,1)))=0,"",SUM('Model inputs'!B232,'Model inputs'!B233,'Model inputs'!B234))))^24)/IF(IF(SUM(IF(IF('Model inputs'!B232="",0,1)="",0,IF('Model inputs'!B232="",0,1)),IF(IF('Model inputs'!B233="",0,1)="",0,IF('Model inputs'!B233="",0,1)),IF(IF('Model inputs'!B234="",0,1)="",0,IF('Model inputs'!B234="",0,1)))=0,"",SUM('Model inputs'!B232,'Model inputs'!B233,'Model inputs'!B234))="",0,IF(SUM(IF(IF('Model inputs'!B232="",0,1)="",0,IF('Model inputs'!B232="",0,1)),IF(IF('Model inputs'!B233="",0,1)="",0,IF('Model inputs'!B233="",0,1)),IF(IF('Model inputs'!B234="",0,1)="",0,IF('Model inputs'!B234="",0,1)))=0,"",SUM('Model inputs'!B232,'Model inputs'!B233,'Model inputs'!B234))),"") | R30: =IFERROR('RC Unit economics'!R22*(1-(1-IF(IF(SUM(IF(IF('Model inputs'!B232="",0,1)="",0,IF('Model inputs'!B232="",0,1)),IF(IF('Model inputs'!B233="",0,1)="",0,IF('Model inputs'!B233="",0,1)),IF(IF('Model inputs'!B234="",0,1)="",0,IF('Model inputs'!B234="",0,1)))=0,"",SUM('Model inputs'!B232,'Model inputs'!B233,'Model inputs'!B234))="",0,IF(SUM(IF(IF('Model inputs'!B232="",0,1)="",0,IF('Model inputs'!B232="",0,1)),IF(IF('Model inputs'!B233="",0,1)="",0,IF('Model inputs'!B233="",0,1)),IF(IF('Model inputs'!B234="",0,1)="",0,IF('Model inputs'!B234="",0,1)))=0,"",SUM('Model inputs'!B232,'Model inputs'!B233,'Model inputs'!B234))))^24)/IF(IF(SUM(IF(IF('Model inputs'!B232="",0,1)="",0,IF('Model inputs'!B232="",0,1)),IF(IF('Model inputs'!B233="",0,1)="",0,IF('Model inputs'!B233="",0,1)),IF(IF('Model inputs'!B234="",0,1)="",0,IF('Model inputs'!B234="",0,1)))=0,"",SUM('Model inputs'!B232,'Model inputs'!B233,'Model inputs'!B234))="",0,IF(SUM(IF(IF('Model inputs'!B232="",0,1)="",0,IF('Model inputs'!B232="",0,1)),IF(IF('Model inputs'!B233="",0,1)="",0,IF('Model inputs'!B233="",0,1)),IF(IF('Model inputs'!B234="",0,1)="",0,IF('Model inputs'!B234="",0,1)))=0,"",SUM('Model inputs'!B232,'Model inputs'!B233,'Model inputs'!B234))),"") | S30: =IFERROR('RC Unit economics'!S22*(1-(1-IF(IF(SUM(IF(IF('Model inputs'!B232="",0,1)="",0,IF('Model inputs'!B232="",0,1)),IF(IF('Model inputs'!B233="",0,1)="",0,IF('Model inputs'!B233="",0,1)),IF(IF('Model inputs'!B234="",0,1)="",0,IF('Model inputs'!B234="",0,1)))=0,"",SUM('Model inputs'!B232,'Model inputs'!B233,'Model inputs'!B234))="",0,IF(SUM(IF(IF('Model inputs'!B232="",0,1)="",0,IF('Model inputs'!B232="",0,1)),IF(IF('Model inputs'!B233="",0,1)="",0,IF('Model inputs'!B233="",0,1)),IF(IF('Model inputs'!B234="",0,1)="",0,IF('Model inputs'!B234="",0,1)))=0,"",SUM('Model inputs'!B232,'Model inputs'!B233,'Model inputs'!B234))))^24)/IF(IF(SUM(IF(IF('Model inputs'!B232="",0,1)="",0,IF('Model inputs'!B232="",0,1)),IF(IF('Model inputs'!B233="",0,1)="",0,IF('Model inputs'!B233="",0,1)),IF(IF('Model inputs'!B234="",0,1)="",0,IF('Model inputs'!B234="",0,1)))=0,"",SUM('Model inputs'!B232,'Model inputs'!B233,'Model inputs'!B234))="",0,IF(SUM(IF(IF('Model inputs'!B232="",0,1)="",0,IF('Model inputs'!B232="",0,1)),IF(IF('Model inputs'!B233="",0,1)="",0,IF('Model inputs'!B233="",0,1)),IF(IF('Model inputs'!B234="",0,1)="",0,IF('Model inputs'!B234="",0,1)))=0,"",SUM('Model inputs'!B232,'Model inputs'!B233,'Model inputs'!B234))),"")
